Workbook
Name SlicerCache_Table_2_Col_15: #N/A
Name SlicerCache_Table_2_Col_4: #N/A
Name SlicerCache_Table_4_Col_15: #N/A
Name SlicerCache_Table_4_Col_4: #N/A
Name SlicerCache_Table_6_Col_26: #N/A
Name SlicerCache_Table_6_Col_4: #N/A
Name SlicerCache_Table_7_Col_15: #N/A
Name SlicerCache_Table_7_Col_4: #N/A
Name SlicerCache_Table_8_Col_15: #N/A
Name SlicerCache_Table_8_Col_23: #N/A
Name SlicerCache_Table_8_Col_4: #N/A
Name SlicerCache_Table_9_Col_15: #N/A
Name SlicerCache_Table_9_Col_23: #N/A
Name SlicerCache_Table_9_Col_4: #N/A

Sheet Sheet1
A1: 번호 | B1: 고유번호 | C1: 인원수 | D1: 지역 | E1: 팀 | F1: 지역총괄팀장 | G1: 담당팀장 | H1: 팀장 | I1: 구역장 | J1: 부구역장(1) | K1: 부구역장(2) | L1: 부구역장(3) | M1: 구역 | N1: 새신자 | O1: 직책 | P1: 겸직 | Q1: 부서 | R1: 이름(KR) | S1: 이름(RU) | T1: 성별 | U1: 생년월일 | V1: (만)나이 | W1: 전화번호 | X1: 직분 | Y1: 등록상태 | Z1: 국적 | AA1: 국가 | AB1: 도시명 | AC1: 출결 여부 | AD1: 사유/기간 | AE1: 센터기수 | AF1: 기타사항 | AG1: 변경전 지역 | AH1: десятина-1 | AI1: 금액 | AJ1: 메모
A2: 1 | B2: 00360527-00006 | C2: 42 | D2: 국내성도 | E2: 국내_장년 | F2: 00350330-00205 | G2: 김세진 | H2: 00360527-00006 | I2: 00360830-00345 | J2: x | K2: x | M2: 1구역 | O2: 국내총괄팀장 | P2: 구역장 | Q2: 2장년 | R2: 김세진 | S2: Ким Сергей | T2: 남 | U2: 32431 | V2: 37 | W2: 010.6640.3437 | X2: 집사 | Y2: 총회등록 | Z2: 우즈베키스탄/한국(국적취득) | AA2: 한국 | AB2: 서울특별시 | AG2: 국내성도
A3: 2 | B3: 00360830-00345 | C3: 39 | D3: 국내성도 | E3: 국내_장년 | F3: 00350330-00205 | G3: 김세진 | H3: 00360527-00006 | I3: 00360830-00345 | J3: x | K3: x | M3: 1구역 | O3: 구역장 | Q3: 2장년 | R3: 허드미트리 | S3: Хе Дмитрий | T3: 남 | U3: 32370 | V3: 37 | W3: 010-9575-8815 | X3: 집사 | Y3: 총회등록 | Z3: 우즈베키스탄 | AA3: 한국 | AB3: 서울특별시 | AG3: 국내성도
A4: 3 | B4: 00291129-00211 | C4: 36 | D4: 해외개척 | E4: 국내_장년 | F4: 00350330-00205 | G4: 김세진 | H4: 00360527-00006 | I4: 00360830-00345 | J4: x | K4: x | M4: 1구역 | Q4: 2장년 | R4: 김에두아르드 | S4: Ким Эдуард | T4: 남 | U4: 29900 | V4: 44 | W4: 010-2426-2496/(+1(506) 898-3709) | X4: 집사 | Y4: 총회등록 | Z4: 우크라이나 | AA4: 캐나다 | AB4: 프레더릭턴 | AG4: 해외개척
A5: 4 | B5: 00360830-00344 | C5: 33 | D5: 국내성도 | E5: 국내_장년 | F5: 00350330-00205 | G5: 김세진 | H5: 00360527-00006 | I5: 00360830-00345 | J5: x | K5: x | M5: 1구역 | Q5: 2장년 | R5: 이드미트리 | S5: Ли Дмитрий | T5: 남 | U5: 32279 | V5: 37 | W5: 010-2351-0933 | X5: 집사 | Y5: 총회등록 | Z5: 우즈베키스탄 | AA5: 한국 | AB5: 서울특별시 | AG5: 국내성도
A6: 5 | B6: 00320813-00008 | C6: 30 | D6: 국내성도 | E6: 국내_장년 | F6: 00350330-00205 | G6: 김세진 | H6: 00360527-00006 | I6: 00360830-00345 | J6: x | K6: x | M6: 1구역 | Q6: 2장년 | R6: 박뱌체슬라브 | S6: Пак Вячеслав | T6: 남 | U6: 31456 | V6: 39 | W6: 010-4374-0713 | X6: 집사 | Y6: 총회등록 | Z6: 우즈베키스탄 | AA6: 한국 | AB6: 서울특별시 | AG6: 국내성도
A7: 6 | B7: 00371218-00469 | C7: 27 | D7: 국내성도 | E7: 국내_장년 | F7: 00350330-00205 | G7: 김세진 | H7: 00360527-00006 | I7: 00360830-00345 | J7: x | K7: x | M7: 1구역 | Q7: 2장년 | R7: 한세묜세묘노비치 | S7: Хан Семён | T7: 남 | U7: 33599 | V7: 34 | W7: 010-8433-2802 | X7: 집사 | Y7: 총회등록 | Z7: 우즈베키스탄 | AA7: 한국 | AB7: 서울특별시 | AG7: 국내성도
A8: 7 | B8: 00360810-00494 | C8: 24 | D8: 국내성도 | E8: 국내_장년 | F8: 00350330-00205 | G8: 김세진 | H8: 00360527-00006 | I8: 00360830-00345 | J8: x | K8: x | M8: 1구역 | Q8: 2장년 | R8: 오가이디미트리 | S8: Огай Дмитрий | T8: 남 | U8: 31780 | V8: 39 | W8: 010-4333-4896 | X8: 집사 | Y8: 총회등록 | Z8: 우즈베키스탄 | AA8: 한국 | AB8: 전라남도 | AG8: 국내성도
A9: 8 | B9: 00371217-01048 | C9: 21 | D9: 국내성도 | E9: 국내_장년 | F9: 00350330-00205 | G9: 김세진 | H9: 00360527-00006 | I9: 00360830-00345 | J9: x | K9: x | M9: 1구역 | O9: 새신자팀장 | P9: 구역장 | Q9: 2장년 | R9: 강블라디미르파블로비치 | S9: Кан Владимир | T9: 남 | U9: 33031 | V9: 35 | W9: 010-5820-6557 | X9: 집사 | Y9: 총회등록 | Z9: 러시아 | AA9: 한국 | AB9: 서울특별시 | AG9: 국내성도
A10: 9 | B10: 00390826-00075 | C10: 18 | D10: 국내성도 | E10: 국내_청년 | F10: 00350330-00205 | G10: 김세진 | H10: 00360527-00006 | I10: 00390826-00075 | J10: x | K10: x | M10: 2구역 | O10: 구역장 | Q10: 4청년 | R10: 김세르게이발레리예비치 | S10: Ким Сергей Валерьевич | T10: 남 | U10: 32305 | V10: 37 | W10: 010-8441-1728 | X10: 문도 | Y10: 총회등록 | Z10: 러시아 | AA10: 한국 | AB10: 경기도 | AE10: 147-1기 | AG10: 국내성도
A11: 10 | B11: 00311023-00027 | C11: 15 | D11: 국내성도 | E11: 국내_청년 | F11: 00350330-00205 | G11: 김세진 | H11: 00360527-00006 | I11: 00390826-00075 | J11: x | K11: x | M11: 2구역 | Q11: 4청년 | R11: 주유리 | S11: Дю Юрий | T11: 남 | U11: 32377 | V11: 37 | W11: 010-3141-8193 | X11: 문도 | Y11: 총회등록 | Z11: 러시아 | AA11: 한국 | AB11: 서울특별시 | AG11: 국내성도
A12: 11 | B12: 00390826-00117 | C12: 12 | D12: 국내성도 | E12: 국내_청년 | F12: 00350330-00205 | G12: 김세진 | H12: 00360527-00006 | I12: 00390826-00075 | J12: x | K12: x | M12: 2구역 | Q12: 4청년 | R12: 손이고르아루투로비치 | S12: Сон Игорь Артурович | T12: 남 | U12: 36739 | V12: 25 | W12: 010-97112243 | X12: 성도 | Y12: 총회등록 | Z12: 우즈베키스탄 | AA12: 한국 | AB12: 서울특별시 | AE12: 147-4기 | AG12: 국내성도
A13: 12 | B13: 00360830-00347 | C13: 9 | D13: 국내성도 | E13: 국내_청년 | F13: 00350330-00205 | G13: 김세진 | H13: 00360527-00006 | I13: 00390826-00075 | J13: x | K13: x | M13: 2구역 | Q13: 4청년 | R13: 강파벨 | S13: Кан Павел | T13: 남 | U13: 33538 | V13: 34 | W13: 010-5552-2710 | X13: 성도 | Y13: 교회등록 | Z13: 카자흐스탄 | AA13: 한국 | AB13: 경상북도 | AC13: 출결제외 | AD13: 신앙유약 | AG13: 국내성도
A14: 13 | B14: 00400227-01416 | C14: 6 | D14: 국내성도 | E14: 국내_청년 | F14: 00350330-00205 | G14: 김세진 | H14: 00360527-00006 | I14: 00390826-00075 | J14: x | K14: x | M14: 2구역 | Q14: 4청년 | R14: 김예브게니알렉산드로비치 | S14: Ким Евгений Александрович | T14: 남 | U14: 33400 | V14: 34 | W14: 7-747-455-6934 | X14: 성도 | Y14: 입교 | Z14: 카자흐스탄 | AA14: 카자흐스탄 | AB14: 알마티 | AC14: 출결제외 | AD14: 신앙유약 | AE14: 149-1기 | AG14: 국내성도
A15: 14 | B15: 00261225-00087 | C15: 3 | D15: 국내성도 | E15: 국내_부녀 | F15: 00350330-00205 | G15: 차소연 | H15: 00341026-00033 | I15: 00261225-00087 | J15: 00290520-00027 | K15: x | M15: 1구역 | O15: 구역장 | Q15: 3부녀 | R15: 최승미 | S15: Цой Виктория(ЦойСынгМи) | T15: 여 | U15: 31249 | V15: 40 | W15: 010-8921-3985 | X15: 집사 | Y15: 총회등록 | Z15: 우즈베키스탄 | AA15: 한국 | AB15: 서울특별시 | AG15: 국내성도
A16: 15 | B16: 00290520-00027 | C16: 6 | D16: 국내성도 | E16: 국내_부녀 | F16: 00350330-00205 | G16: 차소연 | H16: 00341026-00033 | I16: 00261225-00087 | J16: 00290520-00027 | K16: x | M16: 1구역 | O16: 부구역장 | Q16: 3부녀 | R16: 정갈리나 | S16: Тен Галина | T16: 여 | U16: 29183 | V16: 46 | W16: 010-5329-6884 | X16: 집사 | Y16: 총회등록 | Z16: 카자흐스탄 | AA16: 한국 | AB16: 서울특별시 | AG16: 국내성도
A17: 16 | B17: 00361031-00487 | C17: 9 | D17: 국내성도 | E17: 국내_부녀 | F17: 00350330-00205 | G17: 차소연 | H17: 00341026-00033 | I17: 00261225-00087 | J17: 00290520-00027 | K17: x | M17: 1구역 | Q17: 3부녀 | R17: 최릴리야 | S17: Цой Лилия | T17: 여 | U17: 33815 | V17: 33 | W17: 010-7550-5848 | X17: 집사 | Y17: 총회등록 | Z17: 우즈베키스탄 | AA17: 한국 | AB17: 인천광역시 | AG17: 국내성도
A18: 17 | B18: 00311023-00028 | C18: 12 | D18: 국내성도 | E18: 국내_부녀 | F18: 00350330-00205 | G18: 차소연 | H18: 00341026-00033 | I18: 00261225-00087 | J18: 00290520-00027 | K18: x | M18: 1구역 | Q18: 3부녀 | R18: 박옐레나 | S18: Пак Елена | T18: 여 | U18: 32547 | V18: 36 | W18: 010-5615-2266 | X18: 집사 | Y18: 총회등록 | Z18: 우즈베키스탄 | AA18: 한국 | AB18: 경기도 | AG18: 국내성도
A19: 18 | B19: 00280508-00022 | C19: 15 | D19: 국내성도 | E19: 국내_부녀 | F19: 00350330-00205 | G19: 차소연 | H19: 00341026-00033 | I19: 00261225-00087 | J19: 00290520-00027 | K19: x | M19: 1구역 | Q19: 3부녀 | R19: 엘리나바투크흐티나 | S19: Батухтина Элина | T19: 여 | U19: 31504 | V19: 39 | W19: 010-4593-5238 | X19: 문도 | Y19: 총회등록 | Z19: 우크라이나 | AA19: 한국 | AB19: 서울특별시 | AC19: 출결제외 | AD19: 신앙유약 | AG19: 국내성도
A20: 19 | B20: 00360830-00346 | C20: 18 | D20: 국내성도 | E20: 국내_부녀 | F20: 00350330-00205 | G20: 차소연 | H20: 00341026-00033 | I20: 00360830-00346 | J20: 00350330-00153 | K20: x | M20: 2구역 | O20: 구역장 | Q20: 3부녀 | R20: 김예카테리나 | S20: Ким Екатерина | T20: 여 | U20: 33312 | V20: 34 | W20: 010-5877-6557 | X20: 집사 | Y20: 총회등록 | Z20: 우즈베키스탄 | AA20: 한국 | AB20: 서울특별시 | AG20: 국내성도
A21: 20 | B21: 00350330-00153 | C21: 21 | D21: 국내성도 | E21: 국내_부녀 | F21: 00350330-00205 | G21: 차소연 | H21: 00341026-00033 | I21: 00360830-00346 | J21: 00350330-00153 | K21: x | M21: 2구역 | O21: 부구역장 | Q21: 3부녀 | R21: 문발레리야 | S21: Мун Валерия | T21: 여 | U21: 32771 | V21: 36 | W21: 010-7296-2009 | X21: 집사 | Y21: 총회등록 | Z21: 카자흐스탄 | AA21: 한국 | AB21: 서울특별시 | AG21: 국내성도
A22: 21 | B22: 00371217-01047 | C22: 24 | D22: 국내성도 | E22: 국내_부녀 | F22: 00350330-00205 | G22: 차소연 | H22: 00341026-00033 | I22: 00360830-00346 | J22: 00350330-00153 | K22: x | M22: 2구역 | O22: 새신자팀장 | P22: 구역장 | Q22: 3부녀 | R22: 칸타코바안나일리니치나 | S22: Кантакова Анна | T22: 여 | U22: 31722 | V22: 39 | W22: 010-2887-6167 | X22: 집사 | Y22: 총회등록 | Z22: 러시아 | AA22: 한국 | AB22: 서울특별시 | AG22: 국내성도
A23: 22 | B23: 00340624-00330 | C23: 27 | D23: 국내성도 | E23: 국내_부녀 | F23: 00350330-00205 | G23: 차소연 | H23: 00341026-00033 | I23: 00360830-00346 | J23: 00350330-00153 | K23: x | M23: 2구역 | Q23: 3부녀 | R23: 최유나 | S23: Цой Ольга | T23: 여 | U23: 31062 | V23: 41 | W23: 010-2570-6278 | X23: 집사 | Y23: 총회등록 | Z23: 한국 | AA23: 한국 | AB23: 서울특별시 | AG23: 국내성도
A24: 23 | B24: 00270903-00002 | C24: 30 | D24: 국내성도 | E24: 국내_부녀 | F24: 00350330-00205 | G24: 차소연 | H24: 00341026-00033 | I24: 00360830-00346 | J24: 00350330-00153 | K24: x | M24: 2구역 | Q24: 3부녀 | R24: 정류드밀라 | S24: Тен Людмила | T24: 여 | U24: 30208 | V24: 43 | W24: 010-7624-7907 | X24: 집사 | Y24: 총회등록 | Z24: 카자흐스탄 | AA24: 한국 | AB24: 서울특별시 | AG24: 국내성도
A25: 24 | B25: 00310314-00227 | C25: 33 | D25: 국내성도 | E25: 국내_부녀 | F25: 00350330-00205 | G25: 차소연 | H25: 00341026-00033 | I25: 00360830-00346 | J25: 00350330-00153 | K25: x | M25: 2구역 | Q25: 3부녀 | R25: 한옐레나 | S25: Хан Елена | T25: 여 | U25: 31075 | V25: 41 | W25: 010-8285-1011 | X25: 집사 | Y25: 총회등록 | Z25: 러시아 | AA25: 한국 | AB25: 서울특별시 | AC25: 출결제외 | AD25: 신앙유약 | AG25: 국내성도
A26: 25 | B26: 00320813-00009 | C26: 36 | D26: 국내성도 | E26: 국내_부녀 | F26: 00350330-00205 | G26: 차소연 | H26: 00341026-00033 | I26: 00360830-00346 | J26: 00350330-00153 | K26: x | M26: 2구역 | Q26: 3부녀 | R26: 이다리야B | S26: Ли Дарья | T26: 여 | U26: 31736 | V26: 39 | W26: 010-4045-1523 | X26: 문도 | Y26: 총회등록 | Z26: 우즈베키스탄 | AA26: 한국 | AB26: 서울특별시 | AC26: 출결제외 | AD26: 신앙유약 | AG26: 국내성도
A27: 26 | B27: 00341026-00033 | C27: 39 | D27: 국내성도 | E27: 국내_부녀 | F27: 00350330-00205 | G27: 차소연 | H27: 00341026-00033 | I27: 00341026-00033 | J27: 00270104-00035 | K27: 00371218-00466 | M27: 3구역 | O27: 팀장 | P27: 구역장 | Q27: 3부녀 | R27: 차소연 | S27: Ча Лариса | T27: 여 | U27: 30625 | V27: 42 | W27: 010-2882-8927 | X27: 집사 | Y27: 총회등록 | Z27: 한국 | AA27: 한국 | AB27: 전라남도 | AG27: 국내성도
A28: 27 | B28: 00270104-00035 | C28: 42 | D28: 국내성도 | E28: 국내_부녀 | F28: 00350330-00205 | G28: 차소연 | H28: 00341026-00033 | I28: 00341026-00033 | J28: 00270104-00035 | K28: 00371218-00466 | M28: 3구역 | O28: 부구역장 | Q28: 3부녀 | R28: 굴나라사드코바 | S28: Садыкова Гульнара | T28: 여 | U28: 30935 | V28: 41 | W28: 010-6406-8815 | X28: 집사 | Y28: 총회등록 | Z28: 키르기스스탄 | AA28: 한국 | AB28: 서울특별시 | AG28: 국내성도
A29: 28 | B29: 00371218-00466 | C29: 45 | D29: 국내성도 | E29: 국내_부녀 | F29: 00350330-00205 | G29: 차소연 | H29: 00341026-00033 | I29: 00341026-00033 | J29: 00270104-00035 | K29: 00371218-00466 | M29: 3구역 | O29: 부구역장 | Q29: 3부녀 | R29: 이이리나라디오노브나 | S29: Ли Ирина | T29: 여 | U29: 33662 | V29: 33 | W29: 010-2394-2802 | X29: 집사 | Y29: 총회등록 | Z29: 우즈베키스탄 | AA29: 한국 | AB29: 서울특별시 | AG29: 국내성도
A30: 29 | B30: 00371218-00453 | C30: 48 | D30: 국내성도 | E30: 국내_부녀 | F30: 00350330-00205 | G30: 차소연 | H30: 00341026-00033 | I30: 00341026-00033 | J30: 00270104-00035 | K30: 00371218-00466 | M30: 3구역 | Q30: 1자문 | R30: 김류드밀라 | S30: Ким Людмила | T30: 여 | U30: 18173 | V30: 76 | W30: 010-9692-4972 | X30: 성도 | Y30: 총회등록 | Z30: 우즈베키스탄 | AA30: 한국 | AB30: 경기도 | AG30: 국내성도
A31: 30 | B31: 00350330-00148 | C31: 51 | D31: 국내성도 | E31: 국내_부녀 | F31: 00350330-00205 | G31: 차소연 | H31: 00341026-00033 | I31: 00341026-00033 | J31: 00270104-00035 | K31: 00371218-00466 | M31: 3구역 | Q31: 3부녀 | R31: 주숙자 | S31: Дю Светлана | T31: 여 | U31: 21465 | V31: 67 | W31: 010-5567-8193 | X31: 집사 | Y31: 총회등록 | Z31: 러시아 | AA31: 한국 | AB31: 서울특별시 | AG31: 국내성도
A32: 31 | B32: 00390826-00066 | C32: 54 | D32: 국내성도 | E32: 국내_부녀 | F32: 00350330-00205 | G32: 차소연 | H32: 00341026-00033 | I32: 00341026-00033 | J32: 00270104-00035 | K32: 00371218-00466 | M32: 3구역 | Q32: 3부녀 | R32: 박이리나빅토로브나 | S32: Пак Ирина Викторовна | T32: 여 | U32: 24988 | V32: 57 | W32: 010-5201-5526 | X32: 성도 | Y32: 입교 | Z32: 키르기스스탄 | AA32: 한국 | AB32: 충청북도 | AE32: 147-1기 | AG32: 국내성도
A33: 32 | B33: 00390826-00069 | C33: 57 | D33: 국내성도 | E33: 국내_부녀 | F33: 00350330-00205 | G33: 차소연 | H33: 00341026-00033 | I33: 00341026-00033 | J33: 00270104-00035 | K33: 00371218-00466 | M33: 3구역 | Q33: 3부녀 | R33: 이소피야 | S33: Ли София (LISOFIIA) | T33: 여 | U33: 25896 | V33: 55 | W33: 010-8205-9722 | X33: 성도 | Y33: 총회등록 | Z33: 키르기스스탄 | AA33: 한국 | AB33: 인천광역시 | AE33: 147-1기 | AG33: 국내성도
A34: 33 | B34: 00400819-00001 | C34: 60 | D34: 국내성도 | E34: 국내_부녀 | F34: 00350330-00205 | G34: 차소연 | H34: 00341026-00033 | I34: 00341026-00033 | J34: 00270104-00035 | K34: 00371218-00466 | M34: 3구역 | Q34: 3부녀 | R34: 두드키나스베틀라나미하일로브나 | S34: ДУДКИНА СВЕТЛАНА МИХАЙЛОВНА | T34: 여 | U34: 22442 | V34: 64 | W34: 010-2213-7839 | X34: 성도 | Y34: 입교 | Z34: 러시아 | AA34: 한국 | AB34: 경기도 | AE34: 151-1기 | AG34: 국내성도
A35: 34 | B35: 00410325-00429 | C35: 63 | D35: 우즈베키스탄(타슈켄트) | E35: 국내_부녀 | F35: 00350330-00205 | G35: 차소연 | H35: 00341026-00033 | I35: 00341026-00033 | J35: 00270104-00035 | K35: 00371218-00466 | M35: 3구역 | N35: 새신자 | Q35: 1자문 | R35: 박인가니콜라예브나 | S35: PAK IN-GA NIKOLAYEVNA | T35: 여 | U35: 19444 | V35: 72 | W35: 010-9589-6878 | X35: 성도 | Y35: 입교 | Z35: 우즈베키스탄 | AA35: 한국 | AB35: 광주 | AE35: 153-5기 | AG35: 국내성도
A36: 35 | B36: 00410325-00430 | C36: 66 | D36: 국내성도 | E36: 국내_부녀 | F36: 00350330-00205 | G36: 차소연 | H36: 00341026-00033 | I36: 00341026-00033 | J36: 00270104-00035 | K36: 00371218-00466 | M36: 3구역 | N36: 새신자 | Q36: 3부녀 | R36: 출리나율리야그리고리예브나 | S36: Чулина Юлия Григорьевна | T36: 여 | U36: 35278 | V36: 29 | W36: 010-8441-1321 | X36: 성도 | Y36: 입교 | Z36: 러시아 | AA36: 한국 | AB36: 군산 | AE36: 153-5기 | AG36: 국내성도
A37: 36 | B37: 00400227-01414 | C37: 69 | D37: 국내성도 | E37: 국내_부녀 | F37: 00350330-00205 | G37: 차소연 | H37: 00341026-00033 | I37: 00341026-00033 | J37: 00270104-00035 | K37: 00371218-00466 | M37: 3구역 | Q37: 4청년 | R37: 리알렉시나블라딜레노브나 | S37: Ли Алексина Владиленовна | T37: 여 | U37: 33012 | V37: 35 | W37: 010-4244-3010 | X37: 성도 | Y37: 교회등록 | Z37: 카자흐스탄 | AA37: 한국 | AE37: 149-1기 | AG37: 국내성도
A38: 37 | B38: 00400227-01392 | C38: 72 | D38: 국내성도 | E38: 국내_부녀 | F38: 00350330-00205 | G38: 차소연 | H38: 00341026-00033 | I38: 00341026-00033 | J38: 00270104-00035 | K38: 00371218-00466 | M38: 3구역 | Q38: 3부녀 | R38: 리스베틀라나아나톨리예브나 | S38: Ли Светлана Анатольевна | T38: 여 | U38: 23079 | V38: 62 | W38: 010-2117-9127 | X38: 성도 | Y38: 입교 | Z38: 카자흐스탄 | AA38: 한국 | AB38: 경기도 | AD38: 신앙유약(24-01-16) | AE38: 149-1기 | AG38: 국내성도
A39: 38 | B39: 00400530-00093 | C39: 75 | D39: 국내성도 | E39: 국내_부녀 | F39: 00350330-00205 | G39: 차소연 | H39: 00341026-00033 | I39: 00341026-00033 | J39: 00270104-00035 | K39: 00371218-00466 | M39: 3구역 | Q39: 1자문 | R39: 이림마니콜라예브나 | S39: Ли Римма Николаевна | T39: 여 | U39: 19818 | V39: 71 | W39: 998-90-290-3254 | X39: 성도 | Y39: 입교 | Z39: 우즈베키스탄 | AA39: 한국 | AB39: 경기도 | AC39: 출결제외 | AE39: 150-4기 | AG39: 국내성도
A40: 38 | B40: 00350720-00084 | C40: 77 | E40: 국내_부녀 | F40: 00350330-00205 | G40: 차소연 | H40: 00341026-00033 | I40: 00341026-00033 | M40: 3-2구역 | P40: 베드로지파 | R40: 최라리라 | S40: Цой Лариса
...

Sheet 전체조직도 10월
AE2: 요한지파 과천교회 국제부 CIS & 해외선교부 러시아어권지역 조직도
AU4: 2024.10.10 기준
AG6: CIS지역 & 러시아지역
AB7: CIS 지역 | AG7: 부장 | AH7: 이진모 | AM7: 러시아지역&카자흐스탄알마티,우크라이나키이우
AB8: 총무 | AD8: 박지민 | AM8: 총서무 | AP8: 이시우
AB9: 지역장 | AD9: 진실혜 | AM9: 부서기/서무 | AP9: 임영선
AB10: 총서기 | AD10: 이시우 | AM10: 부서기/서무 | AP10: 안소연
AB11: 회계 | AD11: 이난희
Z14: 전도과장 | AA14: 진실혜 | AC14: 교육과장 | AD14: 박지호 | AM14: 섭외과장 | AP14: 이시우 | AR14: 문화과장 | AS14: 박지호 | AU14: 센터서무 | AV14: 박소정
Z15: 전도서기 | AA15: 최유담 | AC15: 교육서기 | AD15: 이지영 | AM15: 신앙관리과장 | AP15: 안윤희 | AR15: 온라인컨텐츠과장 | AS15: 스미르노바예브게니야 | AU15: 센터부서무 | AV15: 김형구
Z16: 전도서기 | AA16: 명민수 | AC16: 교육과운영서기 | AD16: 최지선 | AM16: 신앙관리과서기 | AP16: 이은지 | AR16: 기획과장 | AS16: 김요환 | AU16: 센터부서무 | AV16: 정재홍
Z17: 전도서기 | AA17: 이수지 | AC17: 교육과운영서기 | AD17: 차성숙 | AR17: 통번역과장 | AS17: 김옥사나
AC18: 교육과부서기 | AD18: 김지연
AC19: 교육과부서기 | AD19: 김효정
AD23: CIS 국내
AG26: 국내거주
AG27: 장년팀장: 김세진 & 부녀팀장: 차소연 & 청년팀장:자카르첸코마리야
W30: 장: CIS01 | X30: =COUNTA(X31:X43) -> 7 | Z30: 부: CIS01 | AA30: =COUNTA(AA31:AA41) -> 5 | AC30: 부: CIS02 | AD30: =COUNTA(AD31:AD41) -> 7 | AF30: 자: CIS01 부: CIS03 | AG30: =COUNTA(AG31:AG43) -> 13 | AI30: 부: CIS04 | AJ30: =COUNTA(AJ31:AJ41) -> 4 | AL30: 부: CIS05 | AM30: =COUNTA(AM31:AM41) -> 8 | AO30: 부: CIS06 | AP30: =COUNTA(AP31:AP41) -> 7 | AR30: 부: CIS07 | AS30: =COUNTA(AS31:AS41) -> 5 | AU30: 청: CIS01 | AV30: =COUNTA(AV31:AV41) -> 7 | AX30: 청: CIS02 | AY30: =COUNTA(AY31:AY41) -> 5 | BA30: 청: CIS03 | BB30: =COUNTA(BB31:BB41) -> 2 | BD30: 청장: CIS04 | BE30: =COUNTA(BE31:BE43) -> 5 | BM30: 파견 | BN30: =COUNTA(BN31:BN43) -> 11
W31: 김세진 | X31: 장년 | Z31: 최승미 | AA31: 부녀 | AB31: 구역장 | AC31: 김예카테리나 | AD31: 부녀 | AE31: 구역장 | AF31: 차소연 | AG31: 부녀 | AH31: 구역장 | AI31: 이진모 | AK31: 구역장 | AL31: 홍수정 | AM31: 부녀 | AN31: 구역장 | AO31: 김현진 | AP31: 부녀 | AQ31: 구역장 | AR31: 한엘자 | AS31: 부녀 | AT31: 구역장 | AU31: 이시우 | AV31: 청년 | AW31: 구역장 | AX31: 진실혜 | AY31: 청년 | AZ31: 구역장 | BA31: 자카르첸코마리야 | BB31: 청년 | BC31: 구역장 | BD31: 김세르게이발레리예비치 | BE31: 청년 | BM31: 김요환(22.04) | BN31: 사당
W32: 허드미트리 | X32: 장년 | Y32: 구역장 | Z32: 정갈리나 | AA32: 부녀 | AB32: 부구역장 | AC32: 문발레리야 | AD32: 부녀 | AE32: 부구역장 | AF32: 굴나라사드코바 | AG32: 부녀 | AH32: 부구역장 | AI32: 박지민 | AL32: 박소정 | AM32: 부녀 | AN32: 부구역장 | AO32: 이수현 | AP32: 부녀 | AQ32: 부구역장 | AR32: 박스베틀라나발레리야노브나 | AS32: 부녀 | AU32: 박지호 | AV32: 청년 | AW32: 부구역장 | AX32: 한올가 | AY32: 청년 | AZ32: 부구역장 | BA32: 박알리나루슬라노브나 | BB32: 청년 | BD32: 주유리 | BE32: 청년 | BM32: 최유담(22.12.22) | BN32: 약수
W33: 이드미트리 | X33: 장년 | Y33: 부구역장 | Z33: 최릴리야 | AA33: 부녀 | AC33: 칸타코바안나일리니치나 | AD33: 부녀 | AF33: 이이리나라디오노브나 | AG33: 부녀 | AH33: 부구역장 | AI33: 최트로핌 | AJ33: 자문 | AL33: 김민정 | AM33: 부녀 | AO33: 김완희 | AP33: 자문 | AR33: 토포로브스카야류드밀라 | AS33: 부녀 | AU33: 주마리나 | AV33: 청년 | AX33: 🔺김올가 | AY33: 청년 | BA33: 틴옐레나비탈리예브나 | BD33: 손이고르아루투로비치 | BE33: 청년 | BM33: 명민수(23.01.05) | BN33: 군포
W34: 박뱌체슬라브 | X34: 장년 | Z34: 박옐레나 | AA34: 부녀 | AC34: 최유나 | AD34: 부녀 | AF34: 김류드밀라 | AG34: 자문 | AI34: 최라리사 | AJ34: 자문 | AL34: 김옥사나 | AM34: 부녀 | AO34: 김희영 | AP34: 부녀 | AR34: 바그뉵나탈리야이바노브나 | AS34: 부녀 | AU34: 배알리나 | AV34: 청년 | AX34: 🔺남마르가리따 | AY34: 청년 | BA34: 똔키흐발레리야 | BD34: 🔺김예브게니알렉산드로비치 | BE34: 청년 | BM34: 김효정(23.06.20) | BN34: 서울역
W35: 한세묜세묘노비치 | X35: 장년 | Z35: 🔺엘리나바투크흐티나 | AA35: 부녀 | AC35: 정류드밀라 | AD35: 부녀 | AF35: 주숙자 | AG35: 부녀 | AI35: 박모이세이 | AJ35: 자문 | AL35: 이지영 | AM35: 부녀 | AN35: 부구역장 | AO35: 유지헌 | AP35: 부녀 | AR35: 도로페예바올가이바노브나 | AS35: 부녀 | AU35: 김따띠야나게오르게브나 | AV35: 청년 | AX35: 🔺안혜림 | AY35: 청년 | BA35: 스테파노바아나스타시야 | BD35: 🔺강파벨 | BE35: 청년 | BM35: 김형구(23.05.01) | BN35: 신사
W36: 오가이디미트리 | X36: 장년 | AC36: 🔺한옐레나 | AD36: 부녀 | AF36: 박이리나빅토로브나 | AG36: 부녀 | AI36: 쿠즈올가 | AJ36: 부녀 | AL36: 임영선 | AM36: 부녀 | AO36: 정희정 | AP36: 부녀 | AU36: 이정주 | AV36: 청년 | AX36: 🔺한블라디슬라브 | BA36: 포보로즈뉴크드므트로올렉산드로브츠 | BM36: 정재홍(23.05.01) | BN36: 안양
W37: 강블라디미르파블로비치 | X37: 장년 | AC37: 🔺이다리야B | AD37: 부녀 | AF37: 이소피아 | AG37: 부녀 | AI37: 🔺강예카테리나 | AL37: 안소연 | AM37: 부녀 | AO37: 이은정 | AP37: 부녀 | AU37: 스미르노바예브게니야 | AV37: 청년 | BA37: 멜느크세르기발레리요브츠 | BM37: 이난희 | BN37: 안양
W38: 김에두아르드 | AF38: 리알렉시나블라딜레노브나 | AG38: 청년 | AL38: 🔺김스베틀라나 | AM38: 부녀 | BM38: 김지연 | BN38: 안양
AF39: 두드키나스베트라나 | AG39: 부녀 | BM39: 이수지 | BN39: 안양
AF40: 리스베틀라나아나톨리예브나 | AG40: 부녀 | BM40: 안윤희 | BN40: 군포
AF41: 🔺이림마니콜라예브나 Ли Римма Николаевна | AG41: 자문 | BM41: 이은지 | BN41: 인덕원
AF42: 박인가니콜라예브나 | AG42: 자문
AF43: 출리나율리야그리고리예브나 | AG43: 부녀
AC46: 해외선교부
BM47: 우크라이나키이우지역 | CG47: 카자흐스탄알마티지역 | DB47: 카자흐스탄악토베지역
CS49: =SUM(CD55,CG55,CJ55,CM55,CP55,CS55) -> 33
H51: 러시아크림공화국 팀장: 이다리야A | AC51: 러시아 모스크바지역 해외지역 강사: | AX51: 우즈베키스탄(타슈켄트) 팀장: 박류드밀라 | BN51: 강사: 이진모 | CH51: 카자흐스탄팀장: 기블레르마리나 | DD51: 팀장:후사이노바베라
H52: 통역: 배알리나 | R52: =SUM(F55,I55,L55,O55) -> 25 | AX52: 통역: 배알리나 | BN52: 팀장: 자카르첸코마리야 | CH52: 통역:
AJ54: c
E55: (크림반도) 사명자구역 CIS01 | F55: =COUNTA(F56:F64) -> 9 | H55: (크림반도) CIS02 | I55: =COUNTA(I56:I63) -> 5 | K55: (크림반도) CIS03 | L55: =COUNTA(L56:L62) -> 6 | N55: (크림반도) CIS04 | O55: =COUNTA(O56:O62) -> 5 | Q55: (크림반도) 사랑구역 CIS05 | R55: 8 | W55: (러시아) CIS01 | X55: =COUNTA(X56:X63) -> 5 | Z55: (러시아) CIS02 | AA55: =COUNTA(AA56:AA62) -> 6 | AC55: (러시아) CIS03 | AD55: 13 | AF55: (러시아) CIS04 | AG55: =COUNTA(AG56:AG68) -> 8 | AI55: (러시아) CIS05 | AJ55: =COUNTA(AJ56:AJ66) -> 7 | AL55: (러시아) CIS06 | AM55: =COUNTA(AM56:AM66) -> 8 | AO55: (러시아) CIS07 | AP55: =COUNTA(AP56:AP71) -> 4 | AU55: 우즈베키스탄(타슈켄트) CIS01 | AV55: =COUNTA(AV56:AV66) -> 7 | AX55: 우즈베키스탄(타슈켄트) 사명자 CIS02 | AY55: =COUNTA(AY56:AY66) -> 3 | BA55: 우즈베키스탄(타슈켄트) CIS03 | BB55: 5 | BM55: (우크라이나) CIS01 | BN55: =COUNTA(BN56:BN65) -> 7 | BP55: (우크라이나) CIS02 | BQ55: =COUNTA(BQ56:BQ65) -> 5 | BZ55: (카자흐스탄) CIS01 | CA55: =COUNTA(CA56:CA63) -> 6 | CC55: (카자흐스탄) CIS02 | CD55: =COUNTA(CD56:CD63) -> 3 | CF55: (카자흐스탄) CIS03 | CG55: =COUNTA(CG56:CG63) -> 7 | CI55: (카자흐스탄) CIS04 | CJ55: =COUNTA(CJ56:CJ63) -> 6 | CL55: (카자흐스탄) CIS05 | CM55: =COUNTA(CM56:CM66) -> 10 | CO55: (카자흐스탄) 사명자구역 CIS06 | CP55: =COUNTA(CP56:CP66) -> 7 | DA55: (카자흐스탄) 사명자구역 CIS01 | DB55: =COUNTA(DB56:DB63) -> 5 | DD55: (카자흐스탄) CIS02 | DE55: =COUNTA(DE56:DE63) -> 6 | DG55: (카자흐스탄) CIS03 | DH55: =COUNTA(DH56:DH63) -> 5 | DJ55: =SUM(DB55,DE55,DH55) -> 16
E56: 이다리야A | F56: 자문 | G56: 팀장 | H56: 칸니베츠류드밀라 | I56: 자문 | J56: 구역장 | K56: 솔로도브닉안드레이 | L56: 장년 | M56: 구역장 | N56: 마의코마르가리따 | O56: 부녀 | P56: 구역장 | Q56: 이다리야A | R56: 자문 | W56: 스미르노바예브게니야 | X56: 청년 | Y56: 구역장 | Z56: 부하리놉알렉세이유리예비치 | AA56: 장년 | AB56: 새신자구역장 | AC56: 코르네예바예카테리나유리예브나(크림부) | AD56: 부녀 | AE56: 새신자구역장 | AF56: 소히보바예카테리나알렉세예브나 Сохибова Екатерина Алексеевна | AG56: 부녀 | AH56: 구역장 | AI56: 모르구노바올가 | AK56: 구역장장 | AL56: 셀륜안토니나 | AN56: 구역장장 | AO56: 주마리나(청-한국) | AU56: 박류드밀라 | AV56: 자문 | AW56: 팀장 | AX56: 박류드밀라 | AZ56: 팀장 | BA56: 박류드밀라 | BC56: 팀장 | BM56: 쿨르느츠빅토리아 | BN56: 청년 | BO56: 팀장 | BP56: 쿨르느츠빅토리아 | BR56: 구역장 | BZ56: 최트로핌 | CB56: 구역장 | CC56: 최아파나시니콜라예비치 | CD56: 자문 | CE56: 구역장 | CF56: 미로노바마리나아나톨리예브나 | CG56: 부녀 | CH56: 구역장 | CI56: 칼가노바류드밀라 | CJ56: 자문 | CK56: 구역장 | CL56: 조니나(카.자) | CN56: 구역장 | CO56: 기블레르마리나 | CP56: 부녀 | CQ56: 팀장 | DA56: 후사이노바베라발렌티노브나 | DB56: 부녀 | DC56: 팀장 | DD56: 쿠자흐메토바사라아흐메토브나 | DE56: 부녀 | DF56: 구역장 | DG56: 나우루즈바옙아흐마디아타튜르코비치(카.새청) | DH56: 청년 | DI56: 새신자구역장
E57: 우사초브빅토르 | F57: 자문 | G57: 새구 | H57: 페트렌코스베틀라나 | I57: 자문 | J57: 부구역장 | K57: 칸니베츠겐나디 | L57: 자문 | N57: 블라슈크알라니콜라예브나 | O57: 부녀 | P57: 부구역장 | Q57: 보츠코바나탈리야아나톨리예브나 | W57: 디야츠코바야나유리예브나 Дьячкова Яна Юрьевн | X57: 청년 | Y57: 부구역장 | Z57: 예브도키몹로만예브게니예비치 | AA57: 장년 | AC57: 바세니나올가알렉산드로브나 Васенина Ольга Александровна | AD57: 부녀 | AE57: 부구역장장 | AF57: 예브도키모바나탈리야세르게예브나 Евдокимова Наталья Сергеевна | AG57: 부녀 | AH57: 부구역장 | AI57: 무하메토바리다이스마길로브나 | AJ57: 자문 | AL57: 키셀레바아나스타시야아나톨리예브나(38) | AM57: 부녀 | AO57: 🔺타토얀그레타바가노브나 Татоян Грета | AP57: 부녀 | AU57: 김플로라 | AV57: 자문 | AX57: 김엘리자베따(우즈벡) | AY57: 부녀 | BA57: 한예카테리나발렌티노브나 Хан Екатерина | BB57: 부녀 | BM57: 안토넨코뱌체슬라브볼로드므로브 | BN57: 장년 | BO57: 새신자구역장 | BP57: 돌가카테르나볼로드므리브나 Долга Катерина Владимировна | BQ57: 청년 | BZ57: 이알렉세이 | CA57: 장년 | CB57: 부구역장 | CC57: 제놉 빅토르 페트로비치 Зенов Виктор Петрович | CD57: 자문 | CF57: 예고로바류드밀라 | CG57: 부녀 | CI57: 헤가이타마라 | CJ57: 자문 | CK57: 부구역장 | CL57: 아만졸로바굴미라아미로브나(카자흐) | CM57: 부녀 | CN57: 부구역장 | CO57: 조니나 | CP57: 자문 | DA57: 마흐무토바줄피야얄쿠노브나 Махмутова Зульфия Ялкуновна | DB57: 청년 | DD57: 칸라리사표도로브나(부구님) | DE57: 자문 | DF57: 부구역장 | DG57: 나우루즈바옙 키릴 아타튜르코비치(카자흐) | DH57: 청년 | DI57: 새신자구역장
...

Sheet 41.10월 취합마스터파일
T1: 조직개편전 | V1: 새신자입교후 | W1: 5.27일 행정적용후 | AF1: ㅇ
S2: 국내성도 | T2: 71 | U2: =COUNTIF($F$15:$F$625,S2) -> 72 | V2: 71 | W2: =COUNTIF($F$15:$F$684,$S2) -> 72 | Y2: 73
S3: 러시아(모스크바) | T3: 76 | U3: =COUNTIF($F$15:$F$625,S3) -> 65 | V3: 76 | W3: =COUNTIF($F$15:$F$684,$S3) -> 70 | Y3: 70
S4: 카자흐스탄(알마티) | T4: 57 | U4: =COUNTIF($F$15:$F$625,S4) -> 59 | V4: 57 | W4: =COUNTIF($F$15:$F$684,$S4) -> 59 | Y4: 59
S5: 우크라이나(키이우) | T5: 49 | U5: =COUNTIF($F$15:$F$625,S5) -> 55 | V5: 49 | W5: =COUNTIF($F$15:$F$684,$S5) -> 55 | Y5: 55
S6: 러시아(크림공화국) | T6: 69 | U6: =COUNTIF($F$15:$F$625,S6) -> 49 | V6: 69 | W6: =COUNTIF($F$15:$F$684,$S6) -> 50 | Y6: 50
S7: 우즈베키스탄(타슈켄트) | W7: =COUNTIF($F$15:$F$684,$S7) -> 51 | Y7: 51
S8: 카자흐스탄(악토베) | W8: =COUNTIF($F$15:$F$684,$S8) -> 50 | Y8: 50
T10: =COUNTIF($F$15:$F$684,$S10) -> 0 | U10: =COUNTIF($F$15:$F$684,$S10) -> 0 | V10: =COUNTIF($F$15:$F$684,$S10) -> 0 | W10: =COUNTIF($F$15:$F$684,$S10) -> 0
S11: 해외개척 | T11: 195 | U11: =COUNTIF($F$15:$F$625,S11) -> 167 | V11: =T11+42 -> 237 | W11: =COUNTIF($F$15:$F$684,$S11) -> 211 | Y11: 211
T12: =SUM(T2:T11) -> 517 | U12: =SUM(U2:U11) -> 467 | V12: =SUM(V2:V11) -> 559 | W12: =SUM(W2:W11) -> 618
D13: 총인원 | E13: =SUBTOTAL(103,$F$15:F684) -> 618 | AF13: 불필요시 삭제하면 됩니다.
C14: 번호 | D14: 고유번호 | E14: 인원수 | F14: 지역 | G14: 팀 | H14: 담당팀장 | I14: 팀장 | J14: 구역장 | K14: 부구역장(1) | L14: 부구역장(2) | M14: 구역 | N14: 새신자 | O14: 직책 | P14: 겸직 | Q14: 부서 | R14: 이름(KR) | S14: 이름(RU) | T14: 성별 | U14: 생년월일 | V14: (만)나이 | W14: 전화번호 | X14: 직분 | Y14: 등록상태 | Z14: 국적 | AA14: 국가 | AB14: 도시명 | AC14: 출결 여부 | AD14: 사유/기간 | AE14: 센터기수 | AF14: 기타사항 | AG14: 변경전 지역
C15: 1 | D15: 00360527-00006 | E15: =SUBTOTAL(103,$Q$15:Q15) -> 1 | F15: 국내성도 | G15: 국내_장년 | H15: 김세진 | I15: 00360527-00006 | J15: 00360830-00345 | K15: 00390826-00075 | L15: x | M15: 1구역 | O15: 국내총괄팀장 | P15: 구역장 | Q15: 2장년 | R15: 김세진 | S15: Ким Сергей | T15: 남 | U15: 32431 | V15: =DATEDIF(U15,TODAY(),"Y") -> 37 | W15: 010.6640.3437 | X15: 집사 | Y15: 총회등록 | Z15: 우즈베키스탄/한국(국적취득) | AA15: 한국 | AB15: 서울특별시 | AG15: 국내성도
C16: 2 | D16: 00360830-00345 | E16: =SUBTOTAL(103,$Q$15:Q16) -> 2 | F16: 국내성도 | G16: 국내_장년 | H16: 김세진 | I16: 00360527-00006 | J16: 00360830-00345 | K16: 00390826-00075 | L16: x | M16: 1구역 | O16: 구역장 | Q16: 2장년 | R16: 허드미트리 | S16: Хе Дмитрий | T16: 남 | U16: 32370 | V16: =DATEDIF(U16,TODAY(),"Y") -> 37 | W16: 010-9575-8815 | X16: 집사 | Y16: 총회등록 | Z16: 우즈베키스탄 | AA16: 한국 | AB16: 서울특별시 | AG16: 국내성도
C17: 3 | D17: 00291129-00211 | E17: =SUBTOTAL(103,$Q$15:Q17) -> 3 | F17: 해외개척 | G17: 국내_장년 | H17: 김세진 | I17: 00360527-00006 | J17: 00360830-00345 | K17: 00390826-00075 | L17: x | M17: 1구역 | Q17: 2장년 | R17: 김에두아르드 | S17: Ким Эдуард | T17: 남 | U17: 29900 | V17: =DATEDIF(U17,TODAY(),"Y") -> 44 | W17: 010-2426-2496/(+1(506) 898-3709) | X17: 집사 | Y17: 총회등록 | Z17: 우크라이나 | AA17: 캐나다 | AB17: 프레더릭턴 | AG17: 해외개척
C18: 4 | D18: 00360830-00344 | E18: =SUBTOTAL(103,$Q$15:Q18) -> 4 | F18: 국내성도 | G18: 국내_장년 | H18: 김세진 | I18: 00360527-00006 | J18: 00360830-00345 | K18: 00390826-00075 | L18: x | M18: 1구역 | Q18: 2장년 | R18: 이드미트리 | S18: Ли Дмитрий | T18: 남 | U18: 32279 | V18: =DATEDIF(U18,TODAY(),"Y") -> 37 | W18: 010-2351-0933 | X18: 집사 | Y18: 총회등록 | Z18: 우즈베키스탄 | AA18: 한국 | AB18: 서울특별시 | AG18: 국내성도
C19: 5 | D19: 00320813-00008 | E19: =SUBTOTAL(103,$Q$15:Q19) -> 5 | F19: 국내성도 | G19: 국내_장년 | H19: 김세진 | I19: 00360527-00006 | J19: 00360830-00345 | K19: 00390826-00075 | L19: x | M19: 1구역 | Q19: 2장년 | R19: 박뱌체슬라브 | S19: Пак Вячеслав | T19: 남 | U19: 31456 | V19: =DATEDIF(U19,TODAY(),"Y") -> 39 | W19: 010-4374-0713 | X19: 집사 | Y19: 총회등록 | Z19: 우즈베키스탄 | AA19: 한국 | AB19: 서울특별시 | AG19: 국내성도
C20: 6 | D20: 00371218-00469 | E20: =SUBTOTAL(103,$Q$15:Q20) -> 6 | F20: 국내성도 | G20: 국내_장년 | H20: 김세진 | I20: 00360527-00006 | J20: 00360830-00345 | K20: 00390826-00075 | L20: x | M20: 1구역 | Q20: 2장년 | R20: 한세묜세묘노비치 | S20: Хан Семён | T20: 남 | U20: 33599 | V20: =DATEDIF(U20,TODAY(),"Y") -> 34 | W20: 010-8433-2802 | X20: 집사 | Y20: 총회등록 | Z20: 우즈베키스탄 | AA20: 한국 | AB20: 서울특별시 | AG20: 국내성도
C21: 7 | D21: 00360810-00494 | E21: =SUBTOTAL(103,$Q$15:Q21) -> 7 | F21: 국내성도 | G21: 국내_장년 | H21: 김세진 | I21: 00360527-00006 | J21: 00360830-00345 | K21: 00390826-00075 | L21: x | M21: 1구역 | Q21: 2장년 | R21: 오가이디미트리 | S21: Огай Дмитрий | T21: 남 | U21: 31780 | V21: =DATEDIF(U21,TODAY(),"Y") -> 39 | W21: 010-4333-4896 | X21: 집사 | Y21: 총회등록 | Z21: 우즈베키스탄 | AA21: 한국 | AB21: 전라남도 | AG21: 국내성도
C22: 8 | D22: 00371217-01048 | E22: =SUBTOTAL(103,$Q$15:Q22) -> 8 | F22: 국내성도 | G22: 국내_장년 | H22: 김세진 | I22: 00360527-00006 | J22: 00360830-00345 | K22: 00390826-00075 | L22: x | M22: 1구역 | O22: 새신자팀장 | P22: 구역장 | Q22: 2장년 | R22: 강블라디미르파블로비치 | S22: Кан Владимир | T22: 남 | U22: 33031 | V22: =DATEDIF(U22,TODAY(),"Y") -> 35 | W22: 010-5820-6557 | X22: 집사 | Y22: 총회등록 | Z22: 러시아 | AA22: 한국 | AB22: 서울특별시 | AG22: 국내성도
C23: 9 | D23: 00360830-00343 | E23: =SUBTOTAL(103,$Q$15:Q23) -> 9 | F23: 국내성도 | G23: 국내_장년 | H23: 김세진 | I23: 00360527-00006 | J23: 00360830-00345 | K23: 00390826-00075 | L23: x | M23: 1구역 | Q23: 2장년 | R23: 박드미트리 | S23: Пак Дмитрий | T23: 남 | U23: 30685 | V23: =DATEDIF(U23,TODAY(),"Y") -> 42 | W23: 010-2856-8404 | X23: 성도 | Y23: 교회등록 | Z23: 우즈베키스탄 | AA23: 한국 | AB23: 경기도 | AC23: 출결제외 | AD23: 신앙유약 | AG23: 국내성도
C24: 10 | D24: 00390826-00075 | E24: =SUBTOTAL(103,$Q$15:Q24) -> 10 | F24: 국내성도 | G24: 국내_청년 | H24: 김세진 | I24: 00360527-00006 | J24: 00390826-00075 | K24: x | L24: x | M24: 2구역 | O24: 구역장 | Q24: 4청년 | R24: 김세르게이발레리예비치 | S24: Ким Сергей Валерьевич | T24: 남 | U24: 32305 | V24: =DATEDIF(U24,TODAY(),"Y") -> 37 | W24: 010-8441-1728 | X24: 문도 | Y24: 총회등록 | Z24: 러시아 | AA24: 한국 | AB24: 경기도 | AE24: 147-1기 | AG24: 국내성도
C25: 11 | D25: 00311023-00027 | E25: =SUBTOTAL(103,$Q$15:Q25) -> 11 | F25: 국내성도 | G25: 국내_청년 | H25: 김세진 | I25: 00360527-00006 | J25: 00390826-00075 | K25: x | L25: x | M25: 2구역 | Q25: 4청년 | R25: 주유리 | S25: Дю Юрий | T25: 남 | U25: 32377 | V25: =DATEDIF(U25,TODAY(),"Y") -> 37 | W25: 010-3141-8193 | X25: 문도 | Y25: 총회등록 | Z25: 러시아 | AA25: 한국 | AB25: 서울특별시 | AG25: 국내성도
C26: 12 | D26: 00390826-00117 | E26: =SUBTOTAL(103,$Q$15:Q26) -> 12 | F26: 국내성도 | G26: 국내_청년 | H26: 자카르첸코마리야 | I26: 00310314-00231 | J26: 00390826-00075 | K26: x | L26: x | M26: 2구역 | Q26: 4청년 | R26: 손이고르아루투로비치 | S26: Сон Игорь Артурович | T26: 남 | U26: 36739 | V26: =DATEDIF(U26,TODAY(),"Y") -> 25 | W26: 010-97112243 | X26: 성도 | Y26: 총회등록 | Z26: 우즈베키스탄 | AA26: 한국 | AB26: 서울특별시 | AE26: 147-4기 | AG26: 국내성도
C27: 13 | D27: 00360830-00347 | E27: =SUBTOTAL(103,$Q$15:Q27) -> 13 | F27: 국내성도 | G27: 국내_청년 | H27: 자카르첸코마리야 | I27: 00310314-00231 | J27: 00390826-00075 | K27: x | L27: x | M27: 2구역 | Q27: 4청년 | R27: 강파벨 | S27: Кан Павел | T27: 남 | U27: 33538 | V27: =DATEDIF(U27,TODAY(),"Y") -> 34 | W27: 010-5552-2710 | X27: 성도 | Y27: 교회등록 | Z27: 카자흐스탄 | AA27: 한국 | AB27: 경상북도 | AC27: 출결제외 | AD27: 신앙유약 | AG27: 국내성도
C28: 14 | D28: 00400227-01416 | E28: =SUBTOTAL(103,$Q$15:Q28) -> 14 | F28: 국내성도 | G28: 국내_청년 | H28: 김세진 | I28: 00360527-00006 | J28: 00390826-00075 | K28: x | L28: x | M28: 2구역 | Q28: 4청년 | R28: 김예브게니알렉산드로비치 | S28: Ким Евгений Александрович | T28: 남 | U28: 33400 | V28: =DATEDIF(U28,TODAY(),"Y") -> 34 | W28: 7-747-455-6934 | X28: 성도 | Y28: 입교 | Z28: 카자흐스탄 | AA28: 카자흐스탄 | AB28: 알마티 | AC28: 출결제외 | AD28: 신앙유약 | AE28: 149-1기 | AG28: 국내성도
C29: 15 | D29: 00261225-00087 | E29: =SUBTOTAL(103,$Q$15:Q29) -> 15 | F29: 국내성도 | G29: 국내_부녀 | H29: 차소연 | I29: 00341026-00033 | J29: 00261225-00087 | K29: 00290520-00027 | L29: x | M29: 1구역 | O29: 구역장 | Q29: 3부녀 | R29: 최승미 | S29: Цой Виктория(ЦойСынгМи) | T29: 여 | U29: 31249 | V29: =DATEDIF(U29,TODAY(),"Y") -> 40 | W29: 010-8921-3985 | X29: 집사 | Y29: 총회등록 | Z29: 우즈베키스탄 | AA29: 한국 | AB29: 서울특별시 | AG29: 국내성도
C30: 16 | D30: 00290520-00027 | E30: =SUBTOTAL(103,$Q$15:Q30) -> 16 | F30: 국내성도 | G30: 국내_부녀 | H30: 차소연 | I30: 00341026-00033 | J30: 00261225-00087 | K30: 00290520-00027 | L30: x | M30: 1구역 | O30: 부구역장 | Q30: 3부녀 | R30: 정갈리나 | S30: Тен Галина | T30: 여 | U30: 29183 | V30: =DATEDIF(U30,TODAY(),"Y") -> 46 | W30: 010-5329-6884 | X30: 집사 | Y30: 총회등록 | Z30: 카자흐스탄 | AA30: 한국 | AB30: 서울특별시 | AG30: 국내성도
C31: 17 | D31: 00361031-00487 | E31: =SUBTOTAL(103,$Q$15:Q31) -> 17 | F31: 국내성도 | G31: 국내_부녀 | H31: 차소연 | I31: 00341026-00033 | J31: 00261225-00087 | K31: 00290520-00027 | L31: x | M31: 1구역 | Q31: 3부녀 | R31: 최릴리야 | S31: Цой Лилия | T31: 여 | U31: 33815 | V31: =DATEDIF(U31,TODAY(),"Y") -> 33 | W31: 010-7550-5848 | X31: 집사 | Y31: 총회등록 | Z31: 우즈베키스탄 | AA31: 한국 | AB31: 인천광역시 | AG31: 국내성도
C32: 18 | D32: 00311023-00028 | E32: =SUBTOTAL(103,$Q$15:Q32) -> 18 | F32: 국내성도 | G32: 국내_부녀 | H32: 차소연 | I32: 00341026-00033 | J32: 00261225-00087 | K32: 00290520-00027 | L32: x | M32: 1구역 | Q32: 3부녀 | R32: 박옐레나 | S32: Пак Елена | T32: 여 | U32: 32547 | V32: =DATEDIF(U32,TODAY(),"Y") -> 36 | W32: 010-5615-2266 | X32: 집사 | Y32: 총회등록 | Z32: 우즈베키스탄 | AA32: 한국 | AB32: 경기도 | AG32: 국내성도
C33: 19 | D33: 00280508-00022 | E33: =SUBTOTAL(103,$Q$15:Q33) -> 19 | F33: 국내성도 | G33: 국내_부녀 | H33: 차소연 | I33: 00341026-00033 | J33: 00261225-00087 | K33: 00290520-00027 | L33: x | M33: 1구역 | Q33: 3부녀 | R33: 엘리나바투크흐티나 | S33: Батухтина Элина | T33: 여 | U33: 31504 | V33: =DATEDIF(U33,TODAY(),"Y") -> 39 | W33: 010-4593-5238 | X33: 문도 | Y33: 총회등록 | Z33: 우크라이나 | AA33: 한국 | AB33: 서울특별시 | AC33: 출결제외 | AD33: 신앙유약 | AG33: 국내성도
C34: 20 | D34: 00360830-00346 | E34: =SUBTOTAL(103,$Q$15:Q34) -> 20 | F34: 국내성도 | G34: 국내_부녀 | H34: 차소연 | I34: 00341026-00033 | J34: 00360830-00346 | K34: 00350330-00153 | L34: x | M34: 2구역 | O34: 구역장 | Q34: 3부녀 | R34: 김예카테리나 | S34: Ким Екатерина | T34: 여 | U34: 33312 | V34: =DATEDIF(U34,TODAY(),"Y") -> 34 | W34: 010-5877-6557 | X34: 집사 | Y34: 총회등록 | Z34: 우즈베키스탄 | AA34: 한국 | AB34: 서울특별시 | AG34: 국내성도
C35: 21 | D35: 00350330-00153 | E35: =SUBTOTAL(103,$Q$15:Q35) -> 21 | F35: 국내성도 | G35: 국내_부녀 | H35: 차소연 | I35: 00341026-00033 | J35: 00360830-00346 | K35: 00350330-00153 | L35: x | M35: 2구역 | O35: 부구역장 | Q35: 3부녀 | R35: 문발레리야 | S35: Мун Валерия | T35: 여 | U35: 32771 | V35: =DATEDIF(U35,TODAY(),"Y") -> 36 | W35: 010-7296-2009 | X35: 집사 | Y35: 총회등록 | Z35: 카자흐스탄 | AA35: 한국 | AB35: 서울특별시 | AG35: 국내성도
C36: 22 | D36: 00371217-01047 | E36: =SUBTOTAL(103,$Q$15:Q36) -> 22 | F36: 국내성도 | G36: 국내_부녀 | H36: 차소연 | I36: 00341026-00033 | J36: 00360830-00346 | K36: 00350330-00153 | L36: x | M36: 2구역 | O36: 새신자팀장 | P36: 구역장 | Q36: 3부녀 | R36: 칸타코바안나일리니치나 | S36: Кантакова Анна | T36: 여 | U36: 31722 | V36: =DATEDIF(U36,TODAY(),"Y") -> 39 | W36: 010-2887-6167 | X36: 집사 | Y36: 총회등록 | Z36: 러시아 | AA36: 한국 | AB36: 서울특별시 | AG36: 국내성도
C37: 23 | D37: 00340624-00330 | E37: =SUBTOTAL(103,$Q$15:Q37) -> 23 | F37: 국내성도 | G37: 국내_부녀 | H37: 차소연 | I37: 00341026-00033 | J37: 00360830-00346 | K37: 00350330-00153 | L37: x | M37: 2구역 | Q37: 3부녀 | R37: 최유나 | S37: Цой Ольга | T37: 여 | U37: 31062 | V37: =DATEDIF(U37,TODAY(),"Y") -> 41 | W37: 010-2570-6278 | X37: 집사 | Y37: 총회등록 | Z37: 한국 | AA37: 한국 | AB37: 서울특별시 | AG37: 국내성도
C38: 24 | D38: 00270903-00002 | E38: =SUBTOTAL(103,$Q$15:Q38) -> 24 | F38: 국내성도 | G38: 국내_부녀 | H38: 차소연 | I38: 00341026-00033 | J38: 00360830-00346 | K38: 00350330-00153 | L38: x | M38: 2구역 | Q38: 3부녀 | R38: 정류드밀라 | S38: Тен Людмила | T38: 여 | U38: 30208 | V38: =DATEDIF(U38,TODAY(),"Y") -> 43 | W38: 010-7624-7907 | X38: 집사 | Y38: 총회등록 | Z38: 카자흐스탄 | AA38: 한국 | AB38: 서울특별시 | AG38: 국내성도
C39: 25 | D39: 00310314-00227 | E39: =SUBTOTAL(103,$Q$15:Q39) -> 25 | F39: 국내성도 | G39: 국내_부녀 | H39: 차소연 | I39: 00341026-00033 | J39: 00360830-00346 | K39: 00350330-00153 | L39: x | M39: 2구역 | Q39: 3부녀 | R39: 한옐레나 | S39: Хан Елена | T39: 여 | U39: 31075 | V39: =DATEDIF(U39,TODAY(),"Y") -> 41 | W39: 010-8285-1011 | X39: 집사 | Y39: 총회등록 | Z39: 러시아 | AA39: 한국 | AB39: 서울특별시 | AC39: 출결제외 | AD39: 신앙유약 | AG39: 국내성도
C40: 26 | D40: 00320813-00009 | E40: =SUBTOTAL(103,$Q$15:Q40) -> 26 | F40: 국내성도 | G40: 국내_부녀 | H40: 차소연 | I40: 00341026-00033 | J40: 00360830-00346 | K40: 00350330-00153 | L40: x | M40: 2구역 | Q40: 3부녀 | R40: 이다리야B | S40: Ли Дарья | T40: 여 | U40: 31736 | V40: =DATEDIF(U40,TODAY(),"Y") -> 39 | W40: 010-4045-1523 | X40: 문도 | Y40: 총회등록 | Z40: 우즈베키스탄 | AA40: 한국 | AB40: 서울특별시 | AC40: 출결제외 | AD40: 신앙유약 | AG40: 국내성도
C41: 27 | D41: 00341026-00033 | E41: =SUBTOTAL(103,$Q$15:Q41) -> 27 | F41: 국내성도 | G41: 국내_부녀 | H41: 차소연 | I41: 00341026-00033 | J41: 00341026-00033 | K41: 00270104-00035 | L41: 00371218-00466 | M41: 3구역 | O41: 팀장 | P41: 구역장 | Q41: 3부녀 | R41: 차소연 | S41: Ча Лариса | T41: 여 | U41: 30625 | V41: =DATEDIF(U41,TODAY(),"Y") -> 42 | W41: 010-2882-8927 | X41: 집사 | Y41: 총회등록 | Z41: 한국 | AA41: 한국 | AB41: 전라남도 | AG41: 국내성도
...

Sheet 현황파악
T1: 조직개편전 | V1: 새신자입교후 | W1: 5.27일 행정적용후 | AF1: ㅇ
S2: 국내성도 | T2: 71 | U2: =COUNTIF($F$15:$F$626,S2) -> 73 | V2: 71 | W2: =COUNTIF($F$15:$F$656,$S2) -> 73
S3: 러시아(모스크바) | T3: 76 | U3: =COUNTIF($F$15:$F$626,S3) -> 65 | V3: 76 | W3: =COUNTIF($F$15:$F$656,$S3) -> 70
S4: 우크라이나(키이우) | T4: 57 | U4: =COUNTIF($F$15:$F$626,S4) -> 55 | V4: 57 | W4: =COUNTIF($F$15:$F$656,$S4) -> 55
S5: 크림공화국 | T5: 49 | U5: =COUNTIF($F$15:$F$626,S5) -> 0 | V5: 49 | W5: =COUNTIF($F$15:$F$656,$S5) -> 0
S6: 카자흐스탄(알마티) | T6: 69 | U6: =COUNTIF($F$15:$F$626,S6) -> 59 | V6: 69 | W6: =COUNTIF($F$15:$F$656,$S6) -> 59
S7: 카자흐스탄(악토베) | W7: =COUNTIF($F$15:$F$656,$S7) -> 50
S8: 우크라이나오데사
S9: 우크라이나리비우
S10: 우즈베키스탄(타슈켄트) | T10: =COUNTIF($F$15:$F$656,$S10) -> 51 | U10: =COUNTIF($F$15:$F$656,$S10) -> 51 | V10: =COUNTIF($F$15:$F$656,$S10) -> 51 | W10: =COUNTIF($F$15:$F$656,$S10) -> 51
S11: 해외개척 | T11: 195 | U11: =COUNTIF($F$15:$F$626,S11) -> 167 | V11: =T11+42 -> 237 | W11: =COUNTIF($F$15:$F$656,$S11) -> 185
T12: =SUM(T2:T11) -> 568 | U12: =SUM(U2:U11) -> 470 | V12: =SUM(V2:V11) -> 610 | W12: =SUM(W2:W11) -> 543
D13: 총인원 | E13: =SUBTOTAL(103,$F$15:F685) -> 619
C14: 번호 | D14: 고유번호 | E14: 인원수 | F14: 지역 | G14: 팀 | H14: 담당팀장 | I14: 팀장 | J14: 구역장 | K14: 부구역장(1) | L14: 부구역장(2) | M14: 구역 | N14: 새신자 | O14: 직책 | P14: 겸직 | Q14: 부서 | R14: 이름(KR) | S14: 이름(RU) | T14: 성별 | U14: 생년월일 | V14: (만)나이 | W14: 전화번호 | X14: 직분 | Y14: 등록상태 | Z14: 국적 | AA14: 국가 | AB14: 도시명 | AC14: 출결 여부 | AD14: 사유/기간 | AE14: 센터기수 | AF14: 숫자 | AG14: 변경전 지역 | AH14: 예배현황
C15: 1 | D15: 00360527-00006 | E15: =SUBTOTAL(103,$Q$15:Q15) -> 1 | F15: 국내성도 | G15: 국내_장년 | H15: 김세진 | I15: 00360527-00006 | J15: 00360830-00345 | K15: 00390826-00075 | L15: x | M15: 1구역 | O15: 국내총괄팀장 | P15: 구역장 | Q15: 2장년 | R15: 김세진 | S15: Ким Сергей | T15: 남 | U15: 32431 | V15: =DATEDIF(U15,TODAY(),"Y") -> 37 | W15: 010.6640.3437 | X15: 집사 | Y15: 총회등록 | Z15: 우즈베키스탄/한국(국적취득) | AA15: 한국 | AB15: 서울특별시 | AG15: 국내성도
C16: 2 | D16: 00360830-00345 | E16: =SUBTOTAL(103,$Q$15:Q16) -> 2 | F16: 국내성도 | G16: 국내_장년 | H16: 김세진 | I16: 00360527-00006 | J16: 00360830-00345 | K16: 00390826-00075 | L16: x | M16: 1구역 | O16: 구역장 | Q16: 2장년 | R16: 허드미트리 | S16: Хе Дмитрий | T16: 남 | U16: 32370 | V16: =DATEDIF(U16,TODAY(),"Y") -> 37 | W16: 010-9575-8815 | X16: 집사 | Y16: 총회등록 | Z16: 우즈베키스탄 | AA16: 한국 | AB16: 서울특별시 | AG16: 국내성도
C17: 3 | D17: 00291129-00211 | E17: =SUBTOTAL(103,$Q$15:Q17) -> 3 | F17: 해외개척 | G17: 국내_장년 | H17: 김세진 | I17: 00360527-00006 | J17: 00360830-00345 | K17: 00390826-00075 | L17: x | M17: 1구역 | Q17: 2장년 | R17: 김에두아르드 | S17: Ким Эдуард | T17: 남 | U17: 29900 | V17: =DATEDIF(U17,TODAY(),"Y") -> 44 | W17: 010-2426-2496/(+1(506) 898-3709) | X17: 집사 | Y17: 총회등록 | Z17: 우크라이나 | AA17: 캐나다 | AB17: 프레더릭턴 | AG17: 해외개척
C18: 4 | D18: 00360830-00344 | E18: =SUBTOTAL(103,$Q$15:Q18) -> 4 | F18: 국내성도 | G18: 국내_장년 | H18: 김세진 | I18: 00360527-00006 | J18: 00360830-00345 | K18: 00390826-00075 | L18: x | M18: 1구역 | Q18: 2장년 | R18: 이드미트리 | S18: Ли Дмитрий | T18: 남 | U18: 32279 | V18: =DATEDIF(U18,TODAY(),"Y") -> 37 | W18: 010-2351-0933 | X18: 집사 | Y18: 총회등록 | Z18: 우즈베키스탄 | AA18: 한국 | AB18: 서울특별시 | AG18: 국내성도
C19: 5 | D19: 00320813-00008 | E19: =SUBTOTAL(103,$Q$15:Q19) -> 5 | F19: 국내성도 | G19: 국내_장년 | H19: 김세진 | I19: 00360527-00006 | J19: 00360830-00345 | K19: 00390826-00075 | L19: x | M19: 1구역 | Q19: 2장년 | R19: 박뱌체슬라브 | S19: Пак Вячеслав | T19: 남 | U19: 31456 | V19: =DATEDIF(U19,TODAY(),"Y") -> 39 | W19: 010-4374-0713 | X19: 집사 | Y19: 총회등록 | Z19: 우즈베키스탄 | AA19: 한국 | AB19: 서울특별시 | AG19: 국내성도
C20: 6 | D20: 00371218-00469 | E20: =SUBTOTAL(103,$Q$15:Q20) -> 6 | F20: 국내성도 | G20: 국내_장년 | H20: 김세진 | I20: 00360527-00006 | J20: 00360830-00345 | K20: 00390826-00075 | L20: x | M20: 1구역 | Q20: 2장년 | R20: 한세묜세묘노비치 | S20: Хан Семён | T20: 남 | U20: 33599 | V20: =DATEDIF(U20,TODAY(),"Y") -> 34 | W20: 010-8433-2802 | X20: 집사 | Y20: 총회등록 | Z20: 우즈베키스탄 | AA20: 한국 | AB20: 서울특별시 | AG20: 국내성도
C21: 7 | D21: 00360810-00494 | E21: =SUBTOTAL(103,$Q$15:Q21) -> 7 | F21: 국내성도 | G21: 국내_장년 | H21: 김세진 | I21: 00360527-00006 | J21: 00360830-00345 | K21: 00390826-00075 | L21: x | M21: 1구역 | Q21: 2장년 | R21: 오가이디미트리 | S21: Огай Дмитрий | T21: 남 | U21: 31780 | V21: =DATEDIF(U21,TODAY(),"Y") -> 39 | W21: 010-4333-4896 | X21: 집사 | Y21: 총회등록 | Z21: 우즈베키스탄 | AA21: 한국 | AB21: 전라남도 | AG21: 국내성도
C22: 8 | D22: 00371217-01048 | E22: =SUBTOTAL(103,$Q$15:Q22) -> 8 | F22: 국내성도 | G22: 국내_장년 | H22: 김세진 | I22: 00360527-00006 | J22: 00360830-00345 | K22: 00390826-00075 | L22: x | M22: 1구역 | O22: 새신자팀장 | P22: 구역장 | Q22: 2장년 | R22: 강블라디미르파블로비치 | S22: Кан Владимир | T22: 남 | U22: 33031 | V22: =DATEDIF(U22,TODAY(),"Y") -> 35 | W22: 010-5820-6557 | X22: 집사 | Y22: 총회등록 | Z22: 러시아 | AA22: 한국 | AB22: 서울특별시 | AG22: 국내성도
C23: 9 | D23: 00360830-00343 | E23: =SUBTOTAL(103,$Q$15:Q23) -> 9 | F23: 국내성도 | G23: 국내_장년 | H23: 김세진 | I23: 00360527-00006 | J23: 00360830-00345 | K23: 00390826-00075 | L23: x | M23: 1구역 | Q23: 2장년 | R23: 박드미트리 | S23: Пак Дмитрий | T23: 남 | U23: 30685 | V23: =DATEDIF(U23,TODAY(),"Y") -> 42 | W23: 010-2856-8404 | X23: 성도 | Y23: 교회등록 | Z23: 우즈베키스탄 | AA23: 한국 | AB23: 경기도 | AC23: 출결제외 | AD23: 신앙유약 | AG23: 국내성도
C24: 10 | D24: 00390826-00075 | E24: =SUBTOTAL(103,$Q$15:Q24) -> 10 | F24: 국내성도 | G24: 국내_청년 | H24: 김세진 | I24: 00360527-00006 | J24: 00390826-00075 | K24: x | L24: x | M24: 2구역 | O24: 구역장 | Q24: 4청년 | R24: 김세르게이발레리예비치 | S24: Ким Сергей Валерьевич | T24: 남 | U24: 32305 | V24: =DATEDIF(U24,TODAY(),"Y") -> 37 | W24: 010-8441-1728 | X24: 문도 | Y24: 총회등록 | Z24: 러시아 | AA24: 한국 | AB24: 경기도 | AE24: 147-1기 | AG24: 국내성도
C25: 11 | D25: 00311023-00027 | E25: =SUBTOTAL(103,$Q$15:Q25) -> 11 | F25: 국내성도 | G25: 국내_청년 | H25: 김세진 | I25: 00360527-00006 | J25: 00390826-00075 | K25: x | L25: x | M25: 2구역 | Q25: 4청년 | R25: 주유리 | S25: Дю Юрий | T25: 남 | U25: 32377 | V25: =DATEDIF(U25,TODAY(),"Y") -> 37 | W25: 010-3141-8193 | X25: 문도 | Y25: 총회등록 | Z25: 러시아 | AA25: 한국 | AB25: 서울특별시 | AG25: 국내성도
C26: 12 | D26: 00390826-00117 | E26: =SUBTOTAL(103,$Q$15:Q26) -> 12 | F26: 국내성도 | G26: 국내_청년 | H26: 자카르첸코마리야 | I26: 00310314-00231 | J26: 00390826-00075 | K26: x | L26: x | M26: 2구역 | Q26: 4청년 | R26: 손이고르아루투로비치 | S26: Сон Игорь Артурович | T26: 남 | U26: 36739 | V26: =DATEDIF(U26,TODAY(),"Y") -> 25 | W26: 010-97112243 | X26: 성도 | Y26: 총회등록 | Z26: 우즈베키스탄 | AA26: 한국 | AB26: 서울특별시 | AE26: 147-4기 | AG26: 국내성도
C27: 13 | D27: 00360830-00347 | E27: =SUBTOTAL(103,$Q$15:Q27) -> 13 | F27: 국내성도 | G27: 국내_청년 | H27: 자카르첸코마리야 | I27: 00310314-00231 | J27: 00390826-00075 | K27: x | L27: x | M27: 2구역 | Q27: 4청년 | R27: 강파벨 | S27: Кан Павел | T27: 남 | U27: 33538 | V27: =DATEDIF(U27,TODAY(),"Y") -> 34 | W27: 010-5552-2710 | X27: 성도 | Y27: 교회등록 | Z27: 카자흐스탄 | AA27: 한국 | AB27: 경상북도 | AC27: 출결제외 | AD27: 신앙유약 | AG27: 국내성도
C28: 14 | D28: 00400227-01416 | E28: =SUBTOTAL(103,$Q$15:Q28) -> 14 | F28: 국내성도 | G28: 국내_청년 | H28: 김세진 | I28: 00360527-00006 | J28: 00390826-00075 | K28: x | L28: x | M28: 2구역 | Q28: 4청년 | R28: 김예브게니알렉산드로비치 | S28: Ким Евгений Александрович | T28: 남 | U28: 33400 | V28: =DATEDIF(U28,TODAY(),"Y") -> 34 | W28: 7-747-455-6934 | X28: 성도 | Y28: 입교 | Z28: 카자흐스탄 | AA28: 카자흐스탄 | AB28: 알마티 | AC28: 출결제외 | AD28: 신앙유약 | AE28: 149-1기 | AG28: 국내성도
C29: 15 | D29: 00261225-00087 | E29: =SUBTOTAL(103,$Q$15:Q29) -> 15 | F29: 국내성도 | G29: 국내_부녀 | H29: 차소연 | I29: 00341026-00033 | J29: 00261225-00087 | K29: 00290520-00027 | L29: x | M29: 1구역 | O29: 구역장 | Q29: 3부녀 | R29: 최승미 | S29: Цой Виктория(ЦойСынгМи) | T29: 여 | U29: 31249 | V29: =DATEDIF(U29,TODAY(),"Y") -> 40 | W29: 010-8921-3985 | X29: 집사 | Y29: 총회등록 | Z29: 우즈베키스탄 | AA29: 한국 | AB29: 서울특별시 | AG29: 국내성도
C30: 16 | D30: 00290520-00027 | E30: =SUBTOTAL(103,$Q$15:Q30) -> 16 | F30: 국내성도 | G30: 국내_부녀 | H30: 차소연 | I30: 00341026-00033 | J30: 00261225-00087 | K30: 00290520-00027 | L30: x | M30: 1구역 | O30: 부구역장 | Q30: 3부녀 | R30: 정갈리나 | S30: Тен Галина | T30: 여 | U30: 29183 | V30: =DATEDIF(U30,TODAY(),"Y") -> 46 | W30: 010-5329-6884 | X30: 집사 | Y30: 총회등록 | Z30: 카자흐스탄 | AA30: 한국 | AB30: 서울특별시 | AG30: 국내성도
C31: 17 | D31: 00361031-00487 | E31: =SUBTOTAL(103,$Q$15:Q31) -> 17 | F31: 국내성도 | G31: 국내_부녀 | H31: 차소연 | I31: 00341026-00033 | J31: 00261225-00087 | K31: 00290520-00027 | L31: x | M31: 1구역 | Q31: 3부녀 | R31: 최릴리야 | S31: Цой Лилия | T31: 여 | U31: 33815 | V31: =DATEDIF(U31,TODAY(),"Y") -> 33 | W31: 010-7550-5848 | X31: 집사 | Y31: 총회등록 | Z31: 우즈베키스탄 | AA31: 한국 | AB31: 인천광역시 | AG31: 국내성도
C32: 18 | D32: 00311023-00028 | E32: =SUBTOTAL(103,$Q$15:Q32) -> 18 | F32: 국내성도 | G32: 국내_부녀 | H32: 차소연 | I32: 00341026-00033 | J32: 00261225-00087 | K32: 00290520-00027 | L32: x | M32: 1구역 | Q32: 3부녀 | R32: 박옐레나 | S32: Пак Елена | T32: 여 | U32: 32547 | V32: =DATEDIF(U32,TODAY(),"Y") -> 36 | W32: 010-5615-2266 | X32: 집사 | Y32: 총회등록 | Z32: 우즈베키스탄 | AA32: 한국 | AB32: 경기도 | AG32: 국내성도
C33: 19 | D33: 00280508-00022 | E33: =SUBTOTAL(103,$Q$15:Q33) -> 19 | F33: 국내성도 | G33: 국내_부녀 | H33: 차소연 | I33: 00341026-00033 | J33: 00261225-00087 | K33: 00290520-00027 | L33: x | M33: 1구역 | Q33: 3부녀 | R33: 엘리나바투크흐티나 | S33: Батухтина Элина | T33: 여 | U33: 31504 | V33: =DATEDIF(U33,TODAY(),"Y") -> 39 | W33: 010-4593-5238 | X33: 문도 | Y33: 총회등록 | Z33: 우크라이나 | AA33: 한국 | AB33: 서울특별시 | AC33: 출결제외 | AD33: 신앙유약 | AG33: 국내성도
C34: 20 | D34: 00360830-00346 | E34: =SUBTOTAL(103,$Q$15:Q34) -> 20 | F34: 국내성도 | G34: 국내_부녀 | H34: 차소연 | I34: 00341026-00033 | J34: 00360830-00346 | K34: 00350330-00153 | L34: x | M34: 2구역 | O34: 구역장 | Q34: 3부녀 | R34: 김예카테리나 | S34: Ким Екатерина | T34: 여 | U34: 33312 | V34: =DATEDIF(U34,TODAY(),"Y") -> 34 | W34: 010-5877-6557 | X34: 집사 | Y34: 총회등록 | Z34: 우즈베키스탄 | AA34: 한국 | AB34: 서울특별시 | AG34: 국내성도
C35: 21 | D35: 00350330-00153 | E35: =SUBTOTAL(103,$Q$15:Q35) -> 21 | F35: 국내성도 | G35: 국내_부녀 | H35: 차소연 | I35: 00341026-00033 | J35: 00360830-00346 | K35: 00350330-00153 | L35: x | M35: 2구역 | O35: 부구역장 | Q35: 3부녀 | R35: 문발레리야 | S35: Мун Валерия | T35: 여 | U35: 32771 | V35: =DATEDIF(U35,TODAY(),"Y") -> 36 | W35: 010-7296-2009 | X35: 집사 | Y35: 총회등록 | Z35: 카자흐스탄 | AA35: 한국 | AB35: 서울특별시 | AG35: 국내성도
C36: 22 | D36: 00371217-01047 | E36: =SUBTOTAL(103,$Q$15:Q36) -> 22 | F36: 국내성도 | G36: 국내_부녀 | H36: 차소연 | I36: 00341026-00033 | J36: 00360830-00346 | K36: 00350330-00153 | L36: x | M36: 2구역 | O36: 새신자팀장 | P36: 구역장 | Q36: 3부녀 | R36: 칸타코바안나일리니치나 | S36: Кантакова Анна | T36: 여 | U36: 31722 | V36: =DATEDIF(U36,TODAY(),"Y") -> 39 | W36: 010-2887-6167 | X36: 집사 | Y36: 총회등록 | Z36: 러시아 | AA36: 한국 | AB36: 서울특별시 | AG36: 국내성도
C37: 23 | D37: 00340624-00330 | E37: =SUBTOTAL(103,$Q$15:Q37) -> 23 | F37: 국내성도 | G37: 국내_부녀 | H37: 차소연 | I37: 00341026-00033 | J37: 00360830-00346 | K37: 00350330-00153 | L37: x | M37: 2구역 | Q37: 3부녀 | R37: 최유나 | S37: Цой Ольга | T37: 여 | U37: 31062 | V37: =DATEDIF(U37,TODAY(),"Y") -> 41 | W37: 010-2570-6278 | X37: 집사 | Y37: 총회등록 | Z37: 한국 | AA37: 한국 | AB37: 서울특별시 | AG37: 국내성도
C38: 24 | D38: 00270903-00002 | E38: =SUBTOTAL(103,$Q$15:Q38) -> 24 | F38: 국내성도 | G38: 국내_부녀 | H38: 차소연 | I38: 00341026-00033 | J38: 00360830-00346 | K38: 00350330-00153 | L38: x | M38: 2구역 | Q38: 3부녀 | R38: 정류드밀라 | S38: Тен Людмила | T38: 여 | U38: 30208 | V38: =DATEDIF(U38,TODAY(),"Y") -> 43 | W38: 010-7624-7907 | X38: 집사 | Y38: 총회등록 | Z38: 카자흐스탄 | AA38: 한국 | AB38: 서울특별시 | AG38: 국내성도
C39: 25 | D39: 00310314-00227 | E39: =SUBTOTAL(103,$Q$15:Q39) -> 25 | F39: 국내성도 | G39: 국내_부녀 | H39: 차소연 | I39: 00341026-00033 | J39: 00360830-00346 | K39: 00350330-00153 | L39: x | M39: 2구역 | Q39: 3부녀 | R39: 한옐레나 | S39: Хан Елена | T39: 여 | U39: 31075 | V39: =DATEDIF(U39,TODAY(),"Y") -> 41 | W39: 010-8285-1011 | X39: 집사 | Y39: 총회등록 | Z39: 러시아 | AA39: 한국 | AB39: 서울특별시 | AC39: 출결제외 | AD39: 신앙유약 | AG39: 국내성도
C40: 26 | D40: 00320813-00009 | E40: =SUBTOTAL(103,$Q$15:Q40) -> 26 | F40: 국내성도 | G40: 국내_부녀 | H40: 차소연 | I40: 00341026-00033 | J40: 00360830-00346 | K40: 00350330-00153 | L40: x | M40: 2구역 | Q40: 3부녀 | R40: 이다리야B | S40: Ли Дарья | T40: 여 | U40: 31736 | V40: =DATEDIF(U40,TODAY(),"Y") -> 39 | W40: 010-4045-1523 | X40: 문도 | Y40: 총회등록 | Z40: 우즈베키스탄 | AA40: 한국 | AB40: 서울특별시 | AC40: 출결제외 | AD40: 신앙유약 | AG40: 국내성도
...

Sheet 취합 마스터 파일 가이드
B2: 취합 마스터 파일 | C2: 주의!! 인원 기준이 아닌 구역 기준으로 지역/팀/팀장 표기 !!!
B3: 번호 | C3: 단순 일련번호, 팀과 구역 순서로 부여된 번호 | E3: CUST_ID | F3: 국가코드 | G3: 부여코드 | K3: 행정마스터 파일이란?
B4: CUST_ID (임의 변경하지 말 것) | C4: ① 코드 부여 기준: 국가코드 2자리 +숫자 4자리 = 6자리 (주의!! 임의 변경하지 말 것) | E4: 크림반도 | F4: Crimean Pen | G4: CP | K4: - 모든 지역의 데이터취합에 기본이되는 중심축
C5: ② 지역별 고유번호 순서(00230101-00101)로 CUST_ID를 부여한다. | E5: 러시아 | F5: RUsia | G5: RU | K5: - 성도님들의 정보관리 용이
C6: ③ 한번 부여된 번호는 재사용 X | E6: 카자흐스탄 | F6: KaZakhstan | G6: KZ
C7: ④ 지역 이동 후 재이동시 기존 사용했던 CUST_ID가 있더라도 재사용하지 않고, 새로 부여한다. | E7: 우크라이나 | F7: UKraina | G7: UK
C8: ⑤ 인원 중 파견된 지역으로 소속된 구역이 두군데 이상일 경우 | E8: 우즈베키스탄 | F8: UZbekistan | G8: UZ
C9: → 부여된 CUST_ID 앞 "중복"언더바 표기 EX> 중복_CP1001 | E9: 한국 | F9: KoRea | G9: KR
B10: 인원수 | C10: 함수: SUBTOTAL(103,$M$12:M12) $M$12→ 이름셀 절대참조: M12 →이름셀 상대참조 | E10: 해외개척 | F10: NEW | G10: NW
B11: 지역 | C11: 40(2023).08.17 기준
C12: ① 국내성도/해외개척/러시아지역/카자흐스탄(알마티) 4군데만 그 외 없음
B13: 팀 | C13: ① 국내성도 - 장년구역1개, 부녀3구역,청년3구역, 국내거주자 중 새신자 팀에 편성된 인원일부 구성
C14: ② 해외개척 - 러시아, 카자흐스탄 지역 이동 전 편성된 새신자 구역 (?)
C15: ③ 러시아 - 크림반도, 우즈베키스탄, 우크라이나로 구성
C16: (※ 40(2023)08.20 기준 카자흐스탄→ 카자흐스탄 알마티로 전원이동)
C17: ④ 카자흐스탄 알마티
B18: 팀장 | C18: 크림공화국: 이다리야A / 러시아: 스미르노바예브게니야 / 우즈베키스탄: 박류드밀라
C19: 우크라이나: 자카흐첸코마리아 카자흐스탄: 기블레르마리나
C20: 국내팀장: 김세진 / 새신자 팀장: 배알리나
B21: 구역 | C21: 해외의 경우 숫자로 표기: 1구역/2구역
C22: 국내의 경우 부서+숫자: 장년1구역/ 부녀1구역
C23: 구역장이 겸임하는 다른 구역 표기 X
B24: 새신자 | C24: : 입교후 1년 이내 인원
B25: 직책 | C25: ① 중복된 구역이 있을 경우 실제 구역장 사명 역할을 하는 구역에만 직책표기 주의!
C26: (중복된 구역 모두 사명 기재시 직책 필터링 시 계수 불일치
C27: ② 두 구역이상 구역장의 경우 : 겸임 직책은 '/' 이어 표기
C28: ③ 직책명:
C29: EX 새신자 구역장 2구역/러시아1구역장, 구역장/청년회새신자팀장
B30: 부서 | C30: ① 타 지역 파견된 인원은 사명자의 직책이 있더라도 인원 계수는 소속된 지역의 부서별 인원으로 계수한다
C31: 부서명 표기된 인원으로 계수하기 위함
C32: 예시 : 러시아 구역 구역원 - 부서명 표기/ 새신자구역 구역장 - 부서명 미표기 ∴
C33: ② 자문/장년/부녀/청년/학생/교역 셀 색상 조건부 서식으로 지정
B34: 이름(KR) | C34: 한국 이름은 띄어쓰기 X
B35: 이름(RU) | C35: 러어 이름과 성 띄어쓰기
B36: 성별 | C36: 남/여 만 기입할것
B37: 생년월일 | C37: YYYY-MM-DD 형식 반드시 지킬것
B38: (만)나이 | C38: 함수 DATEDIF(O12,TODAY(),"y") O12: 생년월일셀
B39: 고유번호 | C39: 8자리-5자리 EX> 00300725-00026
B40: 직분 | C40: 문도/성도/집사/교역자 만 입력할 것
B41: 등록상태 | C41: 입교/교회등록/총회등록 만 입력할 것

Sheet 참고조직도 12월
AE2: 요한지파 과천교회 국제부 CIS & 해외선교부 러시아어권지역 조직도
AU4: 2024.10.10 기준
AG6: CIS지역 & 러시아지역
AB7: CIS 지역 | AG7: 부장 | AH7: 이진모 | AM7: 러시아지역&카자흐스탄알마티,우크라이나키이우
AB8: 총무 | AD8: 박지민 | AM8: 총서무 | AP8: 이시우
AB9: 지역장 | AD9: 진실혜 | AM9: 부서기/서무 | AP9: 임영선
AB10: 총서기 | AD10: 이시우 | AM10: 부서기/서무 | AP10: 안소연
AB11: 회계 | AD11: 이난희
Z14: 전도과장 | AA14: 진실혜 | AC14: 교육과장 | AD14: 박지호 | AM14: 섭외과장 | AP14: 이시우 | AR14: 문화과장 | AS14: 박지호 | AU14: 센터서무 | AV14: 박소정
Z15: 전도서기 | AA15: 최유담 | AC15: 교육서기 | AD15: 이지영 | AM15: 신앙관리과장 | AP15: 안윤희 | AR15: 온라인컨텐츠과장 | AS15: 스미르노바예브게니야 | AU15: 센터부서무 | AV15: 김형구
Z16: 전도서기 | AA16: 명민수 | AC16: 교육과운영서기 | AD16: 최지선 | AM16: 신앙관리과서기 | AP16: 이은지 | AR16: 기획과장 | AS16: 김요환 | AU16: 센터부서무 | AV16: 정재홍
Z17: 전도서기 | AA17: 이수지 | AC17: 교육과운영서기 | AD17: 차성숙 | AR17: 통번역과장 | AS17: 김옥사나
AC18: 교육과부서기 | AD18: 김지연
AC19: 교육과부서기 | AD19: 김효정
AD23: CIS 국내
AG26: 국내거주
AG27: 장년팀장: 김세진 & 부녀팀장: 차소연 & 청년팀장:자카르첸코마리야
W30: 장: CIS01 | X30: =COUNTA(X31:X43) -> 8 | Z30: 부: CIS01 | AA30: =COUNTA(AA31:AA41) -> 5 | AC30: 부: CIS02 | AD30: =COUNTA(AD31:AD41) -> 7 | AF30: 자: CIS01 부: CIS03 | AG30: =COUNTA(AG31:AG43) -> 13 | AI30: 부: CIS04 | AJ30: =COUNTA(AJ31:AJ41) -> 4 | AL30: 부: CIS05 | AM30: =COUNTA(AM31:AM41) -> 8 | AO30: 부: CIS06 | AP30: =COUNTA(AP31:AP41) -> 7 | AR30: 부: CIS07 | AS30: =COUNTA(AS31:AS41) -> 2 | AU30: 청: CIS01 | AV30: =COUNTA(AV31:AV41) -> 7 | AX30: 청: CIS02 | AY30: =COUNTA(AY31:AY41) -> 5 | BA30: 청: CIS03 | BB30: =COUNTA(BB31:BB41) -> 2 | BD30: 청장: CIS04 | BE30: =COUNTA(BE31:BE43) -> 5 | BM30: 파견 | BN30: =COUNTA(BN31:BN43) -> 11
W31: 김세진 | X31: 장년 | Z31: 최승미 | AA31: 부녀 | AB31: 구역장 | AC31: 김예카테리나 | AD31: 부녀 | AE31: 구역장 | AF31: 차소연 | AG31: 부녀 | AH31: 구역장 | AI31: 이진모 | AK31: 구역장 | AL31: 홍수정 | AM31: 부녀 | AN31: 구역장 | AO31: 김현진 | AP31: 부녀 | AQ31: 구역장 | AR31: 한엘자 | AS31: 부녀 | AT31: 구역장 | AU31: 이시우 | AV31: 청년 | AW31: 구역장 | AX31: 진실혜 | AY31: 청년 | AZ31: 구역장 | BA31: 자카르첸코마리야 | BB31: 청년 | BC31: 구역장 | BD31: 김세르게이발레리예비치 | BE31: 청년 | BM31: 김요환(22.04) | BN31: 사당
W32: 허드미트리 | X32: 장년 | Y32: 구역장 | Z32: 정갈리나 | AA32: 부녀 | AB32: 부구역장 | AC32: 문발레리야 | AD32: 부녀 | AE32: 부구역장 | AF32: 굴나라사드코바 | AG32: 부녀 | AH32: 부구역장 | AI32: 박지민 | AL32: 박소정 | AM32: 부녀 | AN32: 부구역장 | AO32: 이수현 | AP32: 부녀 | AQ32: 부구역장 | AR32: 박스베틀라나발레리야노브나 | AS32: 부녀 | AU32: 박지호 | AV32: 청년 | AW32: 부구역장 | AX32: 한올가 | AY32: 청년 | AZ32: 부구역장 | BA32: 박알리나루슬라노브나 | BB32: 청년 | BD32: 주유리 | BE32: 청년 | BM32: 최유담(22.12.22) | BN32: 약수
W33: 이드미트리 | X33: 장년 | Y33: 부구역장 | Z33: 최릴리야 | AA33: 부녀 | AC33: 칸타코바안나일리니치나 | AD33: 부녀 | AF33: 이이리나라디오노브나 | AG33: 부녀 | AH33: 부구역장 | AI33: 최트로핌 | AJ33: 자문 | AL33: 김민정 | AM33: 부녀 | AO33: 김완희 | AP33: 자문 | AR33: 토포로브스카야류드밀라 | AU33: 주마리나 | AV33: 청년 | AX33: 🔺김올가 | AY33: 청년 | BA33: 틴옐레나비탈리예브나 | BD33: 손이고르아루투로비치 | BE33: 청년 | BM33: 명민수(23.01.05) | BN33: 군포
W34: 박뱌체슬라브 | X34: 장년 | Z34: 박옐레나 | AA34: 부녀 | AC34: 최유나 | AD34: 부녀 | AF34: 김류드밀라 | AG34: 자문 | AI34: 최라리사 | AJ34: 자문 | AL34: 김옥사나 | AM34: 부녀 | AO34: 김희영 | AP34: 부녀 | AR34: 바그뉵나탈리야이바노브나 | AU34: 배알리나 | AV34: 청년 | AX34: 🔺남마르가리따 | AY34: 청년 | BA34: 똔키흐발레리야 | BD34: 🔺김예브게니알렉산드로비치 | BE34: 청년 | BM34: 김효정(23.06.20) | BN34: 서울역
W35: 한세묜세묘노비치 | X35: 장년 | Z35: 🔺엘리나바투크흐티나 | AA35: 부녀 | AC35: 정류드밀라 | AD35: 부녀 | AF35: 주숙자 | AG35: 부녀 | AI35: 박모이세이 | AJ35: 자문 | AL35: 이지영 | AM35: 부녀 | AN35: 부구역장 | AO35: 유지헌 | AP35: 부녀 | AR35: 도로페예바올가이바노브나 | AU35: 김따띠야나게오르게브나 | AV35: 청년 | AX35: 🔺안혜림 | AY35: 청년 | BA35: 포보로즈뉴크드므트로올렉산드로브츠 | BD35: 🔺강파벨 | BE35: 청년 | BM35: 김형구(23.05.01) | BN35: 신사
W36: 오가이디미트리 | X36: 장년 | AC36: 🔺한옐레나 | AD36: 부녀 | AF36: 박이리나빅토로브나 | AG36: 부녀 | AI36: 쿠즈올가 | AJ36: 부녀 | AL36: 임영선 | AM36: 부녀 | AO36: 정희정 | AP36: 부녀 | AU36: 이정주 | AV36: 청년 | AX36: 🔺한블라디슬라브 | BA36: 멜느크세르기발레리요브츠 | BM36: 정재홍(23.05.01) | BN36: 안양
W37: 강블라디미르파블로비치 | X37: 장년 | AC37: 🔺이다리야B | AD37: 부녀 | AF37: 이소피아 | AG37: 부녀 | AI37: 🔺강예카테리나 | AL37: 안소연 | AM37: 부녀 | AO37: 이은정 | AP37: 부녀 | AU37: 스미르노바예브게니야 | BM37: 이난희 | BN37: 안양
W38: 김에두아르드 | AF38: 리알렉시나블라딜레노브나 | AG38: 청년 | AL38: 🔺김스베틀라나 | AM38: 부녀 | AU38: 🔺임리아나 | AV38: 청년 | BM38: 김지연 | BN38: 안양
W39: 🔺박드미트리 | X39: 장년 | AF39: 두드키나스베트라나 | AG39: 부녀 | BM39: 이수지 | BN39: 안양
AF40: 🔺리스베틀라나아나톨리예브나 | AG40: 부녀 | BM40: 안윤희 | BN40: 군포
AF41: 🔺이림마니콜라예브나 Ли Римма Николаевна | AG41: 자문 | BM41: 이은지 | BN41: 인덕원
AF42: 박인가니콜라예브나 | AG42: 자문
AF43: 출리나율리야그리고리예브나 | AG43: 부녀
AC46: 해외선교부
BM47: 우크라이나키이우지역 | CR47: 카자흐스탄알마티지역 | DG47: 카자흐스탄악토베지역
H51: 러시아크림공화국 팀장: 이다리야A | AC51: 러시아 모스크바지역 해외지역 강사: | AX51: 우즈베키스탄(타슈켄트) 팀장: 박류드밀라 | BN51: 강사: 이진모 | BT51: 우크라이나 새신자3팀 | CS51: 카자흐스탄팀장: 기블레르마리나 | DI51: 팀장:후사이노바베라
H52: 통역: 배알리나 | R52: =SUM(F55,I55,L55,O55) -> 25 | AX52: 통역: 배알리나 | BN52: 팀장: 자카르첸코마리야 | BT52: 우크라이나청년새신자팀장: 자카르첸코마리야 | CS52: 통역:
AJ54: c
E55: (크림반도) 사명자구역 CIS01 | F55: =COUNTA(F56:F64) -> 9 | H55: (크림반도) CIS02 | I55: =COUNTA(I56:I63) -> 5 | K55: (크림반도) CIS03 | L55: =COUNTA(L56:L62) -> 6 | N55: (크림반도) CIS04 | O55: =COUNTA(O56:O62) -> 5 | Q55: (크림반도) 사랑구역 CIS05 | R55: 8 | W55: (러시아) CIS01 | X55: =COUNTA(X56:X63) -> 5 | Z55: (러시아) CIS02 | AA55: =COUNTA(AA56:AA62) -> 6 | AC55: (러시아) CIS03 | AD55: 13 | AF55: (러시아) CIS04 | AG55: =COUNTA(AG56:AG68) -> 8 | AI55: (러시아) CIS05 | AJ55: =COUNTA(AJ56:AJ66) -> 7 | AL55: (러시아) CIS06 | AM55: =COUNTA(AM56:AM66) -> 6 | AO55: (러시아) 신앙관리구역 | AP55: =COUNTA(AP56:AP73) -> 8 | AU55: 우즈베키스탄(타슈켄트) CIS01 | AV55: =COUNTA(AV56:AV66) -> 7 | AX55: 우즈베키스탄(타슈켄트) 사명자 CIS02 | AY55: =COUNTA(AY56:AY66) -> 3 | BA55: 우즈베키스탄(타슈켄트) CIS03 | BB55: 5 | BD55: 새 : CIS15=>3 | BE55: =COUNTA(BE56:BE66) -> 5 | BM55: (우크라이나) CIS01 | BN55: =COUNTA(BN56:BN65) -> 7 | BP55: (우크라이나) CIS02 | BQ55: =COUNTA(BQ56:BQ65) -> 5 | BS55: 새 : CIS4 | BT55: =COUNTA(BT56:BT73) -> 16 | BV55: 새 : CIS5 | BW55: =COUNTA(BW56:BW73) -> 15 | BY55: 새 : CIS11 | BZ55: =COUNTA(BZ56:BZ70) -> 11 | CB55: 새 : CIS13 | CC55: =COUNTA(CC56:CC66) -> 9 | CK55: (카자흐스탄) CIS01 | CL55: =COUNTA(CL56:CL63) -> 6 | CN55: (카자흐스탄) CIS02 | CO55: =COUNTA(CO56:CO63) -> 3 | CQ55: (카자흐스탄) CIS03 | CR55: =COUNTA(CR56:CR63) -> 7 | CT55: (카자흐스탄) CIS04 | CU55: =COUNTA(CU56:CU63) -> 6 | CW55: (카자흐스탄) CIS05 | CX55: =COUNTA(CX56:CX66) -> 10 | CZ55: (카자흐스탄) 사명자구역 CIS06 | DA55: =COUNTA(DA56:DA66) -> 7 | DF55: (카자흐스탄) 사명자구역 CIS01 | DG55: =COUNTA(DG56:DG63) -> 5 | DI55: (카자흐스탄) CIS02 | DJ55: =COUNTA(DJ56:DJ63) -> 6 | DL55: (카자흐스탄) CIS03 | DM55: =COUNTA(DM56:DM63) -> 6 | DO55: 새 : CIS04 | DP55: =COUNTA(DP56:DP69) -> 13
E56: 이다리야A | F56: 자문 | G56: 팀장 | H56: 칸니베츠류드밀라 | I56: 자문 | J56: 구역장 | K56: 솔로도브닉안드레이 | L56: 장년 | M56: 구역장 | N56: 마의코마르가리따 | O56: 부녀 | P56: 구역장 | Q56: 이다리야A | R56: 자문 | W56: 스미르노바예브게니야 | X56: 청년 | Y56: 구역장 | Z56: 부하리놉알렉세이유리예비치 | AA56: 장년 | AB56: 새신자구역장 | AC56: 코르네예바예카테리나유리예브나(크림부) | AD56: 부녀 | AE56: 새신자구역장 | AF56: 소히보바예카테리나알렉세예브나 Сохибова Екатерина Алексеевна | AG56: 부녀 | AH56: 구역장 | AI56: 모르구노바올가 | AK56: 구역장장 | AL56: 셀륜안토니나 | AN56: 구역장장 | AU56: 박류드밀라 | AV56: 자문 | AW56: 팀장 | AX56: 박류드밀라 | AZ56: 팀장 | BA56: 박류드밀라 | BC56: 팀장 | BD56: 틴옐레나비탈리예브나 | BM56: 쿨르느츠빅토리아 | BN56: 청년 | BO56: 팀장 | BP56: 쿨르느츠빅토리아 | BR56: 구역장 | BS56: 예구폽빅토르발레리예비치 | BT56: 청년 | BU56: 구역장 | BV56: 랴부쉬즈갈르나므콜라이브나 Рябущиць Галина Миколаївна | BW56: 청년 | BX56: 구역장 | BY56: 멜느크비타므콜라이브나 | BZ56: 부녀 | CA56: 팀장장 | CB56: 칼라챤갈르나카미브나 | CK56: 최트로핌 | CM56: 구역장 | CN56: 최아파나시니콜라예비치 | CO56: 자문 | CP56: 구역장 | CQ56: 미로노바마리나아나톨리예브나 | CR56: 부녀 | CS56: 구역장 | CT56: 칼가노바류드밀라 | CU56: 자문 | CV56: 구역장 | CW56: 조니나(카.자) | CY56: 구역장 | CZ56: 기블레르마리나 | DA56: 부녀 | DB56: 팀장 | DF56: 후사이노바베라발렌티노브나 | DG56: 부녀 | DH56: 팀장 | DI56: 쿠자흐메토바사라아흐메토브나 | DJ56: 부녀 | DK56: 구역장 | DL56: 나우루즈바옙아흐마디아타튜르코비치(카.새청) | DM56: 청년 | DN56: 새신자구역장 | DO56: 를끼나나탈리야블라디미로브나 (부-카자흐)
E57: 우사초브빅토르 | F57: 자문 | G57: 새구 | H57: 페트렌코스베틀라나 | I57: 자문 | J57: 부구역장 | K57: 칸니베츠겐나디 | L57: 자문 | N57: 블라슈크알라니콜라예브나 | O57: 부녀 | P57: 부구역장 | Q57: 보츠코바나탈리야아나톨리예브나 | W57: 디야츠코바야나유리예브나 Дьячкова Яна Юрьевн | X57: 청년 | Y57: 부구역장 | Z57: 예브도키몹로만예브게니예비치 | AA57: 장년 | AC57: 바세니나올가알렉산드로브나 Васенина Ольга Александровна | AD57: 부녀 | AE57: 부구역장장 | AF57: 예브도키모바나탈리야세르게예브나 Евдокимова Наталья Сергеевна | AG57: 부녀 | AH57: 부구역장 | AI57: 무하메토바리다이스마길로브나 | AJ57: 자문 | AL57: 키셀레바아나스타시야아나톨리예브나(38) | AM57: 부녀 | AO57: 🔺타토얀그레타바가노브나 Татоян Грета | AP57: 부녀 | AU57: 김플로라 | AV57: 자문 | AX57: 김엘리자베따 | AY57: 부녀 | BA57: 한예카테리나발렌티노브나 Хан Екатерина | BB57: 부녀 | BD57: 유르코바폴리나발레리예브나 | BE57: 부녀 | BM57: 안토넨코뱌체슬라브볼로드므로브 | BN57: 장년 | BO57: 새신자구역장 | BP57: 돌가카테르나볼로드므리브나 Долга Катерина Владимировна | BQ57: 청년 | BS57: 크라브체냐마리야페트리브나 | BT57: 청년 | BU57: 부구역장 | BV57: 크라베츠마르가르타아르테미브나 Кравець Маргарита Артемівна | BW57: 학생 | BX57: 부구역장 | BY57: 므하일류크카테르나므콜라이브나 | BZ57: 부녀 | CA57: 부구역장 | CB57: 우츠바토바알라므하일리브나 | CC57: 부녀 | CD57: 부구역장 | CK57: 이알렉세이 | CL57: 장년 | CM57: 부구역장 | CN57: 제놉 빅토르 페트로비치 Зенов Виктор Петрович | CO57: 자문 | CQ57: 예고로바류드밀라 | CR57: 부녀 | CT57: 헤가이타마라 | CU57: 자문 | CV57: 부구역장 | CW57: 아만졸로바굴미라아미로브나(카자흐) | CX57: 부녀 | CY57: 부구역장 | CZ57: 조니나 | DA57: 자문 | DF57: 마흐무토바줄피야얄쿠노브나 Махмутова Зульфия Ялкуновна | DG57: 청년 | DI57: 칸라리사표도로브나(부구님) | DJ57: 자문 | DK57: 부구역장 | DL57: 나우루즈바옙 키릴 아타튜르코비치(카자흐) | DM57: 청년 | DN57: 새신자구역장 | DO57: 김릴리야미하일로브나 Ким Лилия Михайловна | DP57: 부녀 | DQ57: 새신자부구역장장
E58: 모르구노바올가 | F58: 자문 | G58: 새구 | H58: 예기얀발렌티나 | I58: 자문 | K58: 오삿치데니스니콜라예비치 | L58: 장년 | N58: 추이코라리사세묘노브나 | O58: 자문 | Q58: 스미르노바올레나빅토리브나 | W58: 디야츠코바빅토리야유리예브나 | X58: 청년 | Z58: 🔺즈가넨코세르게이알렉산드로비치 | AA58: 장년 | AC58: 디야츠코바예카테리나유리예브나 Дьячкова Екатерина Юрьевна | AD58: 부녀 | AF58: 질린스카야옐레나레오니도브나 | AG58: 부녀 | AI58: 코발축류드밀라빅토로브나 | AJ58: 자문 | AL58: 아브라모바아가브닉발레리예브나(35) | AM58: 부녀 | AO58: 🔺쵸르나야스베틀라나알렉산드로브나 Чёрная Светлана | AP58: 부녀 | AU58: 박바딤 | AV58: 자문 | AX58: 박지나이다엔디노브나 | AY58: 부녀 | BA58: 발로바타티야나티모페예브나 | BB58: 자문 | BD58: 울키나빅토리야뱌체슬라보브나 | BE58: 청년 | BM58: 체첼니즈카한나 | BN58: 부녀 | BP58: 칼라챤갈르나카미브나 Калачян Галина Камівна | BQ58: 청년 | BR58: 새신자구역장 | BS58: 마카예바알리나비탈리이브나 | BT58: 청년 | BV58: 므쉬신마르타이바니브나 Мищишин Марта Іванівна | BW58: 청년 | BY58: 🔺파치예카테리나 | BZ58: 부녀 | CB58: 미로쉬느첸코알라볼로드므리브나 | CC58: 부녀 | CK58: 코로봅이고르블라디미로비치 Коробов Игорь | CL58: 장년 | CN58: 🔺두비닌발레리발렌티노비치 | CO58: 장년 | CQ58: 안알렉산드라게로브나 | CR58: 부녀 | CT58: 최라리사 | CV58: 부구역장 | CW58: 스기브녜바 류드밀라 미하일로브나 카키모브나 Сгибнева Людмила Михайловна | CX58: 자문 | CZ58: 로마노바소피야 | DA58: 자문 | DF58: 🔺이브라기모바나시야 Ибрагимова Насия Ахметовна | DG58: 부녀 | DI58: 나우루즈바예바아이자다카키모브나 | DJ58: 자문 | DL58: 라리오놉 다울렛 알렉세예비치(카자흐) | DM58: 청년 | DO58: 이디리소바아나라아산베코브나 Идирисова Анара | DP58: 부녀
...

Sheet 참고 취합마스터파일
U1: 조직개편전 | W1: 새신자입교후 | X1: 5.27일 행정적용후
T2: 국내성도 | U2: 71 | V2: =COUNTIF($F$15:$F$678,T2) -> 73 | W2: 71 | X2: =COUNTIF($F$15:$F$678,$T2) -> 73
