Workbook
Name D: #REF!
Name 국내: #REF!
Name 명단: #REF!
Name 슬라이서_새신자111: #REF!
Name 슬라이서_지역: #REF!
Name 슬라이서_지역111: #REF!

Sheet 42년6월 조직도
AR2: 요한지파 과천교회 국제부 CIS & 해외선교부 러시아어권지역 조직도
BH4: 2025.06.15 기준
AW6: CIS지역 & 러시아지역
AR7: CIS 지역 | AW7: 부장 | AX7: 박지민 | BE7: 해선부
AR8: 지역장 | AT8: 진실혜 | BC8: 총서무 | BF8: 이시우
AR9: 총서기 | AT9: 이시우 | BC9: 부서기/서무 | BF9: 임영선
AR10: 회계 | AT10: 이난희 | BC10: 부서기/서무 | BF10: 안소연
BC11: 부서기 | BF11: 이송희
AP14: 전도과 | AS14: 교육과 | BC14: 신앙관리과 부과장 | BF14: 안윤희 | BH14: 센터서무 | BI14: 박소정
AP15: 전도서기 | AQ15: 최유담 | AS15: 교육행정서기 | AT15: 이지영 | BC15: 통번역과 부과장 | BF15: 이시우 | BH15: 센터부서무 | BI15: 김형구
AP16: 전도서기 | AQ16: 이수지 | AS16: 교육과운영서기 | AT16: 김지연 | BC16: 온라인컨텐츠과장 | BF16: 스미르노바예브게니야 | BH16: 센터부서무 | BI16: 정재홍
AS17: 교육과부서기 | AT17: 김효정
AS18: 교육행정서기 | AT18: 배기란
AS19: 교육행정서기 | AT19: 임진수
AV23: 국제부 CIS 국내
AW26: 국내거주
AW27: 장년팀장: 김세진 부녀팀장: 박지민
AJ30: 장: CIS01 | AK30: =COUNTA(AK31:AK43) -> 6 | AM30: 청장: CIS02 | AN30: =COUNTA(AN31:AN43) -> 7 | AP30: 부: CIS01 | AQ30: =COUNTA(AQ31:AQ41) -> 8 | AS30: 부: CIS02 | AT30: =COUNTA(AT31:AT41) -> 7 | AV30: 자: CIS01 부: CIS03 | AW30: =COUNTA(AW31:AW43) -> 9 | AY30: 부: CIS04 | AZ30: =COUNTA(AZ31:AZ41) -> 6 | BB30: 부: CIS05-1 | BC30: =COUNTA(BC31:BC41) -> 7 | BE30: 부: CIS05-2 | BF30: =COUNTA(BF31:BF41) -> 8 | BH30: 부: CIS07 | BI30: =COUNTA(BI31:BI41) -> 5 | BK30: 청: CIS01 | BL30: =COUNTA(BL31:BL41) -> 6 | BN30: 청: CIS02 | BO30: =COUNTA(BO31:BO41) -> 8 | BV30: 파견 | BW30: =COUNTA(BW31:BW42) -> 11
AJ31: 주유리 | AK31: 청년 | AL31: 구역장 | AM31: 김세르게이발레리예비치 | AN31: 청년 | AO31: 구역장 | AP31: 박지민(안윤희) | AS31: 김예카테리나 | AT31: 부녀 | AU31: 구역장 | AV31: 이이리나라디오노브나 | AW31: 부녀 | AX31: 구역장 | AY31: 박지민 | AZ31: 교역 | BA31: 구역장 | BB31: 홍수정 | BC31: 부녀 | BD31: 구역장 | BE31: 홍수정 | BF31: 부녀 | BH31: 한엘자 | BI31: 부녀 | BJ31: 구역장 | BK31: 이시우 | BL31: 청년 | BM31: 구역장 | BN31: 진실혜 | BO31: 청년 | BP31: 구역장 | BV31: 최유담 | BW31: 약수
AJ32: 김세진 | AK32: 장년 | AM32: 한세묜세묘노비치 | AN32: 장년 | AP32: 최릴리야 | AQ32: 부녀 | AS32: 문발레리야 | AT32: 부녀 | AU32: 부구역장 | AV32: 정갈리나 | AW32: 부녀 | AX32: 부구역장 | AY32: 이진모 | AZ32: 교역 | BB32: 박소정 | BC32: 부녀 | BD32: 부구역장 | BE32: 김현진 | BF32: 부녀 | BG32: 부구역장 | BH32: 박스베틀라나발레리야노브나 | BI32: 부녀 | BJ32: 부구역장 | BK32: 주마리나 | BL32: 청년 | BN32: 한올가 | BO32: 청년 | BP32: 부구역장 | BV32: 김효정 | BW32: 서울역
AJ33: 허드미트리 | AK33: 장년 | AM33: 강블라디미르파블로비치 | AN33: 장년 | AP33: 박옐레나 | AQ33: 부녀 | AS33: 칸타코바안나일리니치나 | AT33: 부녀 | AV33: 굴나라사드코바 | AW33: 부녀 | AY33: 박모이세이 | AZ33: 자문 | BB33: 김옥사나 | BC33: 부녀 | BE33: 이수현 | BF33: 부녀 | BH33: 토포로브스카야류드밀라 | BI33: 부녀 | BK33: 배알리나 | BL33: 청년 | BN33: 이정주 | BO33: 청년 | BV33: 김형구 | BW33: 신사
AJ34: 이드미트리 | AK34: 장년 | AM34: 손이고르아루투로비치 | AN34: 청년 | AP34: 최유나 | AQ34: 부녀 | AS34: 정류드밀라 | AT34: 부녀 | AV34: 김류드밀라 | AW34: 자문 | AY34: 쿠즈올가 | AZ34: 부녀 | BB34: 이지영 | BC34: 부녀 | BE34: 김희영 | BF34: 부녀 | BH34: 바그뉵나탈리야이바노브나 | BI34: 부녀 | BK34: 김따띠야나게오르게브나 | BL34: 청년 | BN34: 박지호 | BO34: 청년 | BV34: 정재홍 | BW34: 신사
AJ35: 박뱌체슬라브 | AK35: 장년 | AM35: 야쿠빈스키이드미트리이고레비치(155기) | AN35: 청년 | AP35: 🔺엘리나바투크흐티나 | AQ35: 부녀 | AS35: 최승미 | AT35: 부녀 | AV35: 주숙자 | AW35: 부녀 | AY35: 🔺강예카테리나 | AZ35: 부녀 | BB35: 임영선 | BC35: 부녀 | BD35: 부구역장 | BE35: 유지헌 | BF35: 부녀 | BH35: 도로페예바올가이바노브나 | BI35: 부녀 | BK35: 스미르노바예브게니야 | BL35: 청년 | BN35: 박혜주 | BO35: 청년 | BV35: 이난희 | BW35: 사당
AJ36: 김에두아르드 | AK36: 장년 | AM36: 🔺김예브게니알렉산드로비치 | AN36: 청년 | AP36: 🔺한옐레나 | AQ36: 부녀 | AS36: 🔺이다리야B | AT36: 부녀 | AV36: 박이리나빅토로브나 | AW36: 부녀 | AY36: 🔺한블라디슬라브 | AZ36: 청년 | BB36: 안소연 | BC36: 부녀 | BE36: 정희정 | BF36: 부녀 | BK36: 김요환 | BL36: 청년 | BN36: 자카르첸코마리야 | BO36: 청년 | BV36: 김지연 | BW36: 서울역
AM37: 🔺강파벨 | AN37: 청년 | AP37: 🔺리스베틀라나아나톨리예브나 | AQ37: 부녀 | AS37: 🔺김올가 | AT37: 청년 | AV37: 이소피아 | AW37: 부녀 | BB37: 한송연 | BC37: 부녀 | BE37: 이은정 | BF37: 부녀 | BK37: 배병건 | BN37: 박알리나루슬라노브나 | BO37: 청년 | BV37: 이수지 | BW37: 약수
AP38: 🔺이림마니콜라예브나 Ли Римма Николаевна | AQ38: 자문 | AV38: 두드키나스베트라나 | AW38: 부녀 | BE38: 박은혜 | BF38: 부녀 | BN38: 🔺남마르가리따 | BO38: 청년 | BV38: 안윤희 | BW38: 군포
AP39: 리알렉시나블라딜레노브나 | AQ39: 청년 | AV39: 출리나율리야그리고리예브나 | AW39: 부녀 | BV39: 이송희 | BW39: 서울시흥
BV40: 배기란 | BW40: 신사
BV41: 임진수 | BW41: 신사
AV47: 해외선교부
CB48: 우크라이나키이우지역
CB50: 강사: 이진모
I53: 러시아크림공화국 팀장: 이다리야A | AK53: 러시아 모스크바지역 해외지역 강사: | BH53: 우즈베키스탄(타슈켄트) 팀장: 박류드밀라 | BW53: 우크라이나 장년팀 | CK53: 우크라이나 부녀팀
I54: 통역: 배알리나 | BH54: 통역: 배알리나 | BW54: 우크라이나장년회팀장: 트로얀볼로드므르이바노브치 | CK54: 우크라이나부녀회팀장: 트로얀라르사아나톨리이브나
AQ56: c
C57: (크림반도) 사명자구역 CIS01 | D57: =COUNTA(D58:D66) -> 9 | F57: (크림반도) CIS02 | G57: =COUNTA(G58:G65) -> 7 | I57: (크림반도) CIS03 | J57: =COUNTA(J58:J64) -> 6 | L57: (크림반도) CIS04 | M57: =COUNTA(M58:M64) -> 5 | O57: (크림반도) 사랑구역 CIS05 | P57: 3 | R57: (크림반도) 사랑구역 CIS06 | S57: 3 | X57: (러시아) CIS01 | Y57: =COUNTA(Y58:Y65) -> 5 | AA57: (러시아) CIS02 | AB57: =COUNTA(AB58:AB72) -> 11 | AD57: (러시아) CIS03 | AE57: =COUNTA(AE58:AE72) -> 8 | AG57: (러시아) CIS04 | AH57: =COUNTA(AH58:AH68) -> 6 | AJ57: (러시아) CIS05 | AK57: =COUNTA(AK58:AK68) -> 8 | AM57: (러시아) CIS06 | AN57: =COUNTA(AN58:AN70) -> 4 | AP57: (러시아) CIS07 | AQ57: =COUNTA(AQ58:AQ68) -> 8 | AS57: (러시아) CIS08 | AT57: =COUNTA(AT58:AT68) -> 8 | AV57: (러시아) 신앙관리구역 | AW57: =COUNTA(AW58:AW77) -> 6 | BE57: 우즈베키스탄(타슈켄트) 사명자 CIS01 | BF57: =COUNTA(BF58:BF68) -> 3 | BH57: 우즈베키스탄 CIS02 | BI57: =COUNTA(BI58:BI68) -> 7 | BK57: 우즈베키스탄 CIS03 | BL57: 5 | BN57: 우즈베키스탄 CIS04 | BO57: =COUNTA(BO58:BO68) -> 6 | BV57: 새 : CIS01 | BW57: =COUNTA(BW58:BW70) -> 11 | BY57: 새 : CIS2 | BZ57: =COUNTA(BZ58:BZ73) -> 10 | CE57: 새 : CIS01-1 | CF57: =COUNTA(CF58:CF73) -> 13 | CH57: 새 : CIS01-2 | CI57: =COUNTA(CI58:CI73) -> 7 | CK57: 새 : CIS01-3 | CL57: =COUNTA(CL58:CL68) -> 5 | CN57: 새 : CIS02 | CO57: =COUNTA(CO58:CO68) -> 7 | CQ57: 새 : CIS03 | CR57: =COUNTA(CR58:CR70) -> 4 | CT57: 새 : CIS04 | CU57: =COUNTA(CU58:CU72) -> 9
C58: 이다리야A | D58: 자문 | E58: 팀장 | F58: 칸니베츠류드밀라 | G58: 자문 | H58: 구역장 | I58: 솔로도브닉안드레이 | J58: 장년 | K58: 구역장 | L58: 마의코마르가리따 | M58: 부녀 | N58: 구역장 | O58: 스미르노바올레나빅토리브나 | P58: 부녀 | Q58: 구역장 | R58: 이다리야A | S58: 자문 | X58: 스미르노바예브게니야 | Y58: 청년 | Z58: 구역장 | AA58: 부하리놉알렉세이유리예비치 | AB58: 장년 | AC58: 새신자구역장 | AD58: 셰르바코프드미트리발레리예비치 | AE58: 장년 | AF58: 새신자구역장 | AG58: 코르네예바예카테리나유리예브나(크림부) | AH58: 부녀 | AI58: 새신자구역장 | AJ58: 소히보바예카테리나알렉세예브나 Сохибова Екатерина Алексеевна | AK58: 부녀 | AL58: 새신자구역장 | AM58: 바세니나올가알렉산드로브나 Васенина Ольга Александровна | AN58: 부녀 | AO58: 구역장 | AP58: 모르구노바올가 | AR58: 구역장 | AS58: 시들랴레비치크세니야겐나디예브나(29) | AT58: 부녀 | AU58: 구역장 | AV58: 스미르노바예브게니야 | AX58: 구역장 | BE58: 박류드밀라 | BG58: 팀장 | BH58: 박류드밀라 | BI58: 자문 | BJ58: 팀장 | BK58: 박류드밀라 | BM58: 팀장 | BN58: 틴옐레나비탈리예브나 | BV58: 트로얀볼로드므르이바노브치 | BW58: 장년 | BX58: 구역장 | BY58: 안토넨코 뱌체슬라브 | BZ58: 장년 | CA58: 구역장 | CE58: 트로얀라르사아나톨리이브나 Троян Лариса Анатоліївна | CF58: 부녀 | CG58: 팀장 | CH58: 판텔레예바니나바슬리브나 | CI58: 부녀 | CJ58: 부구역장 | CK58: 일킵갈리나바실리브나 | CL58: 청년 | CM58: 부구역장 | CN58: 이바노바발렌트나세르기이브나 | CO58: 부녀 | CP58: 구역장 | CQ58: 네샤딤알라아나톨리예브나 | CS58: 구역장 | CT58: 마의코마르가리따
C59: 우사초브빅토르 | D59: 자문 | E59: 새구 | F59: 사모쉬키나이리나니콜라예브나 | G59: 자문 | H59: 부구역장 | I59: 보론코프이반드미트로비치 | J59: 청년 | K59: 부구역장 | L59: 블라슈크알라니콜라예브나 | M59: 부녀 | N59: 부구역장 | O59: 코노노바옐레나바실리예브나 | P59: 부녀 | R59: 보츠코바나탈리야아나톨리예브나 | S59: 부녀 | X59: 디야츠코바야나유리예브나 Дьячкова Яна Юрьевн | Y59: 청년 | Z59: 부구역장 | AA59: 부슬로브스키로만블라디미로비치 | AB59: 장년 | AC59: 부구역장 | AD59: 이바놉블라디슬랍안드레예비치 | AE59: 장년 | AG59: 무라비요바나탈리야알렉산드로브나 Муравьёва Наталья Александровна | AH59: 부녀 | AJ59: 카사트키나옐레나게오르기예브나 Касаткина Елена Георгиевна | AK59: 부녀 | AL59: 부구역장장 | AM59: 예브도키모바나탈리야세르게예브나 Евдокимова Наталья Сергеевна | AN59: 부녀 | AO59: 부구역장 | AP59: 페드첸코옐레나알렉산드로브나 | AQ59: 부녀 | AR59: 부구역장 | AS59: 아브라모바아가브닉발레리예브나(35) | AT59: 부녀 | AV59: 🔺쵸르나야스베틀라나알렉산드로브나 Чёрная Светлана | AW59: 부녀 | BE59: 김엘리자베따 | BF59: 부녀 | BH59: 김플로라 | BI59: 자문 | BK59: 한예카테리나발렌티노브나 Хан Екатерина | BL59: 부녀 | BN59: 유르코바폴리나발레리예브나 | BO59: 부녀 | BP59: 부구역장 | BV59: 바즐축안드리이바노브치 | BW59: 장년 | BX59: 부구역장 | BY59: 스브스툰므콜라보르소브치 Свистун Николай Борисович | BZ59: 장년 | CA59: 부구역장 | CE59: 라자렌쿠스베틀라나블라디미르 | CF59: 부녀 | CH59: 막발라무샴바제 | CI59: 부녀 | CK59: 코발렌코 류보브 이바니브나 Коваленко Любов Іванівна | CL59: 자문 | CN59: 판첸코나탈리야이바니브나 | CO59: 부녀 | CP59: 구역장 | CQ59: 벡마토바마이람칸자파르사드코브나 | CR59: 자문 | CS59: 부구역장 | CT59: 카츠코브시카류드믈라올렉산드리브나 | CU59: 부녀
C60: 모르구노바올가 | D60: 자문 | E60: 새구 | F60: 예기얀발렌티나 | G60: 자문 | I60: 칸니베츠겐나디 | J60: 자문 | L60: 추이코라리사세묘노브나 | M60: 자문 | O60: 사르다랸사티크우나노브나 | P60: 부녀 | R60: 파니나옐레나유리예브나 | S60: 부녀 | X60: 디야츠코바빅토리야유리예브나 | Y60: 청년 | AA60: 카자콥콘스탄틴알렉산드로비치 | AB60: 장년 | AD60: 벡케르안드레이야코블레비치 | AE60: 청년 | AG60: 솔로도브닉나탈리야알렉산드로브나 Солодовник Наталья Александровна | AH60: 부녀 | AJ60: 미나소바갈리나예브게니예브나 | AK60: 부녀 | AM60: 굴리나마리나알렉산드로브나 Гулина Марина Александровна | AN60: 부녀 | AP60: 프로코피예바타티야나표도로브나(58) | AQ60: 부녀 | AR60: 부구역장 | AS60: 오코네쉬니코바일리나세르게예브나(26) | AT60: 청년 | AV60: 🔺우마로바마디나알리세로브나 Умарова Мадина Алишеровна | AW60: 청년 | BE60: 박지나이다엔디노브나 | BF60: 부녀 | BH60: 박바딤 | BI60: 자문 | BK60: 발로바타티야나티모페예브나 | BL60: 자문 | BN60: 울키나빅토리야뱌체슬라보브나 | BO60: 청년 | BV60: 골로브코안드리아나톨리요브치 | BW60: 장년 | BY60: 쁠레솝스키흐스타니슬라프이바노비치 Плесовских Станислав Иванович | BZ60: 장년 | CE60: 체첼니즈카한나 | CF60: 부녀 | CH60: 모로즈이르나므하일리브나 | CI60: 부녀 | CK60: 랴쉔코스비틀라나야키브나 | CL60: 자문 | CN60: 나우멘코타티야나바실리예브나 | CO60: 부녀 | CQ60: 므론츠코바리디야올렉시이브나 | CR60: 자문 | CT60: 쿨리니치타티야나알렉산드로브나 | CU60: 부녀
C61: 셰르바코프드미트리발레리예비치 | D61: 장년 | E61: 새팀 | F61: 페트렌코스베틀라나 | G61: 자문 | I61: 오삿치데니스니콜라예비치 | J61: 장년 | L61: 라브준율리야므콜라이브나 | M61: 부녀 | O61: 가브릴로바옐레나알렉세예브나 | P61: 부녀 | X61: 페트로샨아스믹이쉬하노브나 Петросян Асмик Ишхановна | Y61: 청년 | AA61: 주마쉡누르벡쿠바느치베코비치 | AB61: 장년 | AD61: 익나티옙예브게니미하일로비치 | AE61: 청년 | AG61: 포미체바올레샤아다모브나 Фомичева Олеся Адамовна | AH61: 부녀 | AJ61: 아미르하냔루시네오비코브나 Амирханян Лусине Овиковна | AK61: 부녀 | AM61: 브라기나예브게니야빅토로브나 Брагина Евгения Викторовна | AN61: 부녀 | AP61: 무하메토바리다이스마길로브나 | AQ61: 자문 | AS61: 키셀레바아나스타시야아나톨리예브나(38) | AT61: 부녀 | AV61: 🔺샤틴스카이테엘랴나유리예브나 Шатинскайте Эляна Юрьевна | AW61: 부녀 | BE61: 오레나 | BF61: 부녀 | BH61: 문엘리자벳 | BI61: 자문 | BK61: 박인가니콜라예브나 | BL61: 자문 | BN61: 레임바예바말리카아흐마도브나 | BO61: 청년 | BV61: 주콥안드레이올레고비치 | BW61: 장년 | BX61: 카자흐스탄 | BY61: 스크리프첸코표트르알렉세예비치 Скрипченко Петр Алексеевич | BZ61: 장년 | CA61: 카자흐스탄 | CE61: 골로브코나디야느크포리브나 | CF61: 자문 | CH61: 다즈카야올가세르기이브나 Дацкая Ольга Сергіївна | CI61: 부녀 | CJ61: 구역장장 | CK61: 마누엘안토니오올레나레오니디브나 | CL61: 부녀 | CN61: 니지예바류드믈라므콜라이브나 | CO61: 부녀 | CQ61: 세레다이르나그르고리브나 | CR61: 부녀 | CT61: 푸즈냐스베틀라나바실리예브나 | CU61: 부녀
...

Sheet Sheet1
A1: 번호 | B1: 고유번호 | C1: 인원수 | D1: 지역 | E1: 팀 | F1: 지역총괄팀장 | G1: 담당팀장 | H1: 팀장 | I1: 구역장 | J1: 부구역장(1) | K1: 부구역장(2) | L1: 부구역장(3) | M1: 부구역장(4) | N1: 구역 | O1: 새신자 | P1: 행정직책 | Q1: CIS직책 | R1: 사명자교육이수 | S1: 겸직 및 이력 | T1: 부서 | U1: 이름(KR) | V1: 이름(RU) | W1: 성별 | X1: 생년월일 | Y1: (만)나이 | Z1: 전화번호 | AA1: 텔레사용자명 | AB1: 직분 | AC1: 등록상태 | AD1: 국적 | AE1: 국가 | AF1: 도시명 | AG1: 출결 여부 | AH1: 사유/기간 | AI1: 센터기수 | AJ1: 기타사항 | AK1: 시차 | AL1: 이동할지역 | AM1: Десятина(십일조) | AN1: Заметка(메모)
A2: 0 | C2: 0 | P2: 임원 | Q2: 부장 | U2: 박원희 | W2: 여 | Y2: 126 | Z2: 010-8207-2119 | AA2: @sweets1221 | AC2: 총회등록 | AD2: 한국 | AE2: 한국 | AG2: 중복
A3: 1 | B3: 00360527-00006 | C3: 12 | D3: 국내성도 | E3: 국내_장년 | F3: 00360527-00006 | G3: 김세진 | H3: 00360527-00006 | I3: 00360527-00006 | J3: x | N3: 청장1구역 | P3: 팀장 | Q3: 국내팀장 | S3: 구역장 | T3: 2장년 | U3: 김세진 | V3: Ким Сергей | W3: 남 | X3: 32431 | Y3: 37 | Z3: 010-6640-3437 | AA3: @execute25 | AB3: 집사 | AC3: 총회등록 | AD3: 우즈베키스탄/한국(국적취득) | AE3: 한국 | AF3: 경기도
A4: 2 | B4: 00360830-00345 | C4: 10 | D4: 국내성도 | E4: 국내_장년 | F4: 00360527-00006 | G4: 김세진 | H4: 00360527-00006 | I4: 00360527-00006 | J4: x | N4: 청장1구역 | T4: 2장년 | U4: 허드미트리 | V4: Хе Дмитрий | W4: 남 | X4: 32370 | Y4: 37 | Z4: 010-9575-8815 | AA4: @Dmitriyhe | AB4: 집사 | AC4: 총회등록 | AD4: 우즈베키스탄 | AE4: 한국 | AF4: 서울특별시
A5: 3 | B5: 00360830-00344 | C5: 8 | D5: 국내성도 | E5: 국내_장년 | F5: 00360527-00006 | G5: 김세진 | H5: 00360527-00006 | I5: 00360527-00006 | J5: x | N5: 청장1구역 | T5: 2장년 | U5: 이드미트리 | V5: Ли Дмитрий | W5: 남 | X5: 32279 | Y5: 37 | Z5: 010-2351-0933 | AA5: @DMITRIYLEE88 | AB5: 집사 | AC5: 총회등록 | AD5: 우즈베키스탄 | AE5: 한국 | AF5: 서울특별시
A6: 4 | B6: 00320813-00008 | C6: 6 | D6: 국내성도 | E6: 국내_장년 | F6: 00360527-00006 | G6: 김세진 | H6: 00360527-00006 | I6: 00360527-00006 | J6: x | N6: 청장1구역 | T6: 2장년 | U6: 박뱌체슬라브 | V6: Пак Вячеслав | W6: 남 | X6: 31456 | Y6: 39 | Z6: 010-4374-0713 | AA6: @vvv13park | AB6: 집사 | AC6: 총회등록 | AD6: 우즈베키스탄 | AE6: 한국 | AF6: 서울특별시
A7: 5 | B7: 00371218-00469 | C7: 4 | D7: 국내성도 | E7: 국내_장년 | F7: 00360527-00006 | G7: 김세진 | H7: 00360527-00006 | I7: 00360527-00006 | J7: x | N7: 청장1구역 | T7: 2장년 | U7: 한세묜세묘노비치 | V7: Хан Семён | W7: 남 | X7: 33599 | Y7: 34 | Z7: 010-8433-2802 | AB7: 집사 | AC7: 총회등록 | AD7: 우즈베키스탄 | AE7: 한국 | AF7: 서울특별시
A8: 6 | B8: 00371217-01048 | C8: 2 | D8: 국내성도 | E8: 국내_장년 | F8: 00360527-00006 | G8: 김세진 | H8: 00360527-00006 | I8: 00360527-00006 | J8: x | N8: 청장1구역 | Q8: 새신자팀장 | S8: 구역장 | T8: 2장년 | U8: 강블라디미르파블로비치 | V8: Кан Владимир | W8: 남 | X8: 33031 | Y8: 35 | Z8: 010-5820-6557 | AA8: @kanVladimir7 | AB8: 집사 | AC8: 총회등록 | AD8: 러시아 | AE8: 한국 | AF8: 서울특별시
A9: 8 | B9: 00410822-00002 | C9: 4 | D9: 국내성도 | E9: 새신자4팀 | F9: 00360527-00006 | G9: 김세진 | H9: 00360527-00006 | I9: 00360527-00006 | J9: x | N9: 청장1구역 | T9: 4청년 | U9: 야쿠빈스키이드미트리이고레비치 | V9: Якубинский Дмитрий Игоревич | W9: 남 | X9: 32741 | Y9: 36 | Z9: 010-5890-1703 | AA9: @dimadimadimadimadimadimadima1989 | AB9: 성도 | AC9: 교회등록 | AD9: 러시아 | AE9: 한국 | AF9: 인천광역시 | AI9: 155기
A10: 9 | B10: 00311023-00027 | C10: 6 | D10: 국내성도 | E10: 국내_청년 | F10: 00360527-00006 | G10: 김세진 | H10: 00360527-00006 | I10: 00360527-00006 | J10: x | N10: 청장1구역 | Q10: 센터사명자 | T10: 4청년 | U10: 주유리 | V10: Дю Юрий | W10: 남 | X10: 32377 | Y10: 37 | Z10: 010-3141-8193 | AA10: @DyuYurii | AB10: 문도 | AC10: 총회등록 | AD10: 러시아 | AE10: 한국 | AF10: 서울특별시
A11: 10 | B11: 00390826-00075 | C11: 8 | D11: 국내성도 | E11: 국내_청년 | F11: 00360527-00006 | G11: 김세진 | H11: 00360527-00006 | I11: 00360527-00006 | J11: x | N11: 청장1구역 | Q11: 센터사명자 | T11: 4청년 | U11: 김세르게이발레리예비치 | V11: Ким Сергей Валерьевич | W11: 남 | X11: 32305 | Y11: 37 | Z11: 010-8441-1728 | AA11: @k_i_m_sergey | AB11: 문도 | AC11: 총회등록 | AD11: 러시아 | AE11: 한국 | AF11: 경기도 | AI11: 147-1기
A12: 12 | B12: 00310314-00227 | C12: 10 | D12: 국내성도 | E12: 국내_부녀 | F12: 00360527-00006 | G12: 김세진 | H12: 00360527-00006 | I12: x | J12: x | N12: 신유구역 | T12: 3부녀 | U12: 한옐레나 | V12: Хан Елена | W12: 여 | X12: 31075 | Y12: 41 | Z12: 010-8285-1011 | AB12: 집사 | AC12: 입교 | AD12: 러시아 | AE12: 한국 | AF12: 서울특별시 | AH12: 출결제외해지(2025/3/1) | AJ12: 신앙유약
A13: 14 | B13: 00400227-01392 | C13: 12 | D13: 국내성도 | E13: 국내_부녀 | F13: 00360527-00006 | G13: 김세진 | H13: 00360527-00006 | I13: x | J13: x | N13: 신유구역 | T13: 3부녀 | U13: 리스베틀라나아나톨리예브나 | V13: Светлана ЛИ | W13: 여 | X13: 23079 | Y13: 62 | Z13: 010-2117-9127 | AA13: @Liswetik | AB13: 성도 | AC13: 입교 | AD13: 카자흐스탄 | AE13: 한국 | AF13: 경기도 | AH13: 출결제외해지(2025/3/1) | AI13: 149-1기 | AJ13: 신앙유약
A14: 15 | B14: 00361031-00487 | C14: 14 | D14: 국내성도 | E14: 국내_부녀 | F14: 00360527-00006 | G14: 김세진 | H14: 00360527-00006 | I14: x | J14: x | N14: 신유구역 | T14: 3부녀 | U14: 최릴리야 | V14: Цой Лилия | W14: 여 | X14: 33815 | Y14: 33 | Z14: 010-7550-5848 | AB14: 집사 | AC14: 입교 | AD14: 우즈베키스탄 | AE14: 한국 | AF14: 인천광역시
A15: 16 | B15: 00311023-00028 | C15: 16 | D15: 국내성도 | E15: 국내_부녀 | F15: 00360527-00006 | G15: 김세진 | H15: 00360527-00006 | I15: x | J15: x | N15: 신유구역 | T15: 3부녀 | U15: 박옐레나 | V15: Пак Елена | W15: 여 | X15: 32547 | Y15: 36 | Z15: 010-5615-2266 | AB15: 집사 | AC15: 입교 | AD15: 우즈베키스탄 | AE15: 한국 | AF15: 경기도
A16: 18 | B16: 00400227-01414 | C16: 18 | D16: 국내성도 | E16: 국내_청년 | F16: 00360527-00006 | G16: 김세진 | H16: 00360527-00006 | I16: 00350330-00205 | J16: x | N16: 신유구역 | T16: 4청년 | U16: 리알렉시나블라딜레노브나 | V16: Ли Алексина Владиленовна | W16: 여 | X16: 33012 | Y16: 35 | Z16: 010-4244-3010 | AB16: 성도 | AC16: 입교 | AD16: 카자흐스탄 | AE16: 한국 | AI16: 149-1기
A17: 19 | B17: 00360830-00342 | C17: 20 | D17: 국내성도 | E17: 국내_부녀 | F17: 00360527-00006 | G17: 김세진 | H17: 00360527-00006 | I17: 00360830-00341 | J17: 00410822-00001 | N17: 신유구역 | T17: 3부녀 | U17: 쿠즈올가 | V17: Кузь Ольга | W17: 여 | X17: 22276 | Y17: 65 | Z17: 010-2186-2669 | AB17: 성도 | AC17: 총회등록 | AD17: 우크라이나 | AE17: 한국 | AF17: 서울특별시
A18: 20 | B18: 00360830-00346 | C18: 22 | D18: 국내성도 | E18: 국내_부녀 | F18: 00360527-00006 | G18: 김세진 | H18: 00360527-00006 | I18: 00360830-00346 | J18: 00350330-00153 | N18: 1구역 | P18: 구역장 | Q18: 구역장 | T18: 3부녀 | U18: 김예카테리나 | V18: Ким Екатерина | W18: 여 | X18: 33312 | Y18: 34 | Z18: 010-5877-6557 | AA18: @Rina_Kim_1 | AB18: 집사 | AC18: 총회등록 | AD18: 우즈베키스탄 | AE18: 한국 | AF18: 서울특별시
A19: 21 | B19: 00350330-00153 | C19: 24 | D19: 국내성도 | E19: 국내_부녀 | F19: 00360527-00006 | G19: 김세진 | H19: 00360527-00006 | I19: 00360830-00346 | J19: 00350330-00153 | N19: 1구역 | P19: 부구역장 | Q19: 부구역장 | T19: 3부녀 | U19: 문발레리야 | V19: Мун Валерия | W19: 여 | X19: 32771 | Y19: 36 | Z19: 010-7296-2009 | AA19: @leramun | AB19: 집사 | AC19: 총회등록 | AD19: 카자흐스탄 | AE19: 한국 | AF19: 서울특별시
A20: 22 | B20: 00371217-01047 | C20: 26 | D20: 국내성도 | E20: 야쿠츠크 | F20: 00360527-00006 | G20: 김세진 | H20: 00360527-00006 | I20: 00360830-00346 | J20: 00350330-00153 | N20: 1구역 | P20: 팀장 | Q20: 새신자팀장 | T20: 3부녀 | U20: 칸타코바안나일리니치나 | V20: Кантакова Анна | W20: 여 | X20: 31722 | Y20: 39 | Z20: 010-2887-6167 | AA20: @annakantakova | AB20: 집사 | AC20: 총회등록 | AD20: 러시아 | AE20: 한국 | AF20: 경기도 | AH20: 출결제외해지(25/07/6~9/2)출산
A21: 23 | B21: 00270903-00002 | C21: 28 | D21: 국내성도 | E21: 국내_부녀 | F21: 00360527-00006 | G21: 김세진 | H21: 00360527-00006 | I21: 00360830-00346 | J21: 00350330-00153 | N21: 1구역 | T21: 3부녀 | U21: 정류드밀라 | V21: Тен Людмила | W21: 여 | X21: 30208 | Y21: 43 | Z21: 010-7624-7907 | AB21: 집사 | AC21: 총회등록 | AD21: 카자흐스탄 | AE21: 한국 | AF21: 서울특별시
A22: 24 | B22: 00261225-00087 | C22: 30 | D22: 국내성도 | E22: 국내_부녀 | F22: 00360527-00006 | G22: 김세진 | H22: 00360527-00006 | I22: 00360830-00346 | J22: 00350330-00153 | N22: 1구역 | T22: 3부녀 | U22: 최승미 | V22: Цой Виктория(ЦойСынгМи) | W22: 여 | X22: 31249 | Y22: 40 | Z22: 010-8921-3985 | AA22: @victoriachoi8 | AB22: 집사 | AC22: 총회등록 | AD22: 우즈베키스탄 | AE22: 한국 | AF22: 서울특별시
A23: 25 | B23: 00320813-00009 | C23: 32 | D23: 국내성도 | E23: 국내_부녀 | F23: 00360527-00006 | G23: 김세진 | H23: 00360527-00006 | I23: 00360830-00346 | J23: 00350330-00153 | N23: 1구역 | T23: 3부녀 | U23: 이다리야B | V23: Ли Дарья | W23: 여 | X23: 31736 | Y23: 39 | Z23: 010-4045-1523 | AB23: 문도 | AC23: 입교 | AD23: 우즈베키스탄 | AE23: 한국 | AF23: 서울특별시 | AH23: 출결제외해지(2025/3/1) | AJ23: 신앙유약
A24: 26 | B24: 00340624-00330 | C24: 34 | D24: 국내성도 | E24: 국내_부녀 | F24: 00360527-00006 | G24: 김세진 | H24: 00360527-00006 | I24: 00360830-00346 | J24: 00350330-00153 | N24: 1구역 | T24: 3부녀 | U24: 최유나 | V24: Цой Ольга | W24: 여 | X24: 31062 | Y24: 41 | Z24: 010-2570-6278 | AB24: 집사 | AC24: 총회등록 | AD24: 한국 | AE24: 한국 | AF24: 서울특별시
A25: 27 | B25: 00390826-00066 | C25: 36 | D25: 국내성도 | E25: 국내_부녀 | F25: 00360527-00006 | G25: 김세진 | H25: 00360527-00006 | I25: 00390826-00066 | J25: 00270104-00035 | K25: 00290520-00027 | N25: 2구역 | P25: 부구역장 | Q25: 부구역장 | T25: 3부녀 | U25: 박이리나빅토로브나 | V25: Пак Ирина Викторовна | W25: 여 | X25: 24988 | Y25: 57 | Z25: 010-5201-5526 | AA25: @ari2822 | AB25: 성도 | AC25: 총회등록 | AD25: 키르기스스탄 | AE25: 한국 | AF25: 충청북도 | AI25: 147-1기
A26: 28 | B26: 00270104-00035 | C26: 38 | D26: 국내성도 | E26: 국내_부녀 | F26: 00360527-00006 | G26: 김세진 | H26: 00360527-00006 | I26: 00390826-00066 | J26: 00270104-00035 | K26: 00290520-00027 | N26: 2구역 | P26: 부구역장 | Q26: 부구역장 | T26: 3부녀 | U26: 굴나라사드코바 | V26: Садыкова Гульнара | W26: 여 | X26: 30935 | Y26: 41 | Z26: 010-6406-8815 | AA26: @Nara_Seoul | AB26: 집사 | AC26: 총회등록 | AD26: 키르기스스탄 | AE26: 한국 | AF26: 서울특별시
A27: 29 | B27: 00290520-00027 | C27: 40 | D27: 국내성도 | E27: 국내_부녀 | F27: 00360527-00006 | G27: 김세진 | H27: 00360527-00006 | I27: 00390826-00066 | J27: 00270104-00035 | K27: 00290520-00027 | N27: 2구역 | P27: 부구역장 | Q27: 부구역장 | T27: 3부녀 | U27: 정갈리나 | V27: Тен Галина | W27: 여 | X27: 29183 | Y27: 46 | Z27: 010-5329-6884 | AA27: @Galina10j | AB27: 집사 | AC27: 총회등록 | AD27: 카자흐스탄 | AE27: 한국 | AF27: 서울특별시
A28: 30 | B28: 00371218-00466 | C28: 42 | D28: 국내성도 | E28: 국내_부녀 | F28: 00360527-00006 | G28: 김세진 | H28: 00360527-00006 | I28: 00390826-00066 | J28: 00270104-00035 | K28: 00290520-00027 | N28: 2구역 | T28: 3부녀 | U28: 이이리나라디오노브나 | V28: Ли Ирина | W28: 여 | X28: 33662 | Y28: 33 | Z28: 010-2394-2802 | AB28: 집사 | AC28: 입교 | AD28: 우즈베키스탄 | AE28: 한국 | AF28: 서울특별시
A29: 31 | B29: 00371218-00453 | C29: 44 | D29: 국내성도 | E29: 국내_부녀 | F29: 00360527-00006 | G29: 김세진 | H29: 00360527-00006 | I29: 00390826-00066 | J29: 00270104-00035 | K29: 00290520-00027 | N29: 2구역 | T29: 1자문 | U29: 김류드밀라 | V29: Ким Людмила | W29: 여 | X29: 18173 | Y29: 76 | Z29: 010-9692-4972 | AA29: @Milakim02 | AB29: 성도 | AC29: 총회등록 | AD29: 우즈베키스탄 | AE29: 한국 | AF29: 경기도
A30: 32 | B30: 00350330-00148 | C30: 46 | D30: 국내성도 | E30: 국내_부녀 | F30: 00360527-00006 | G30: 김세진 | H30: 00360527-00006 | I30: 00390826-00066 | J30: 00270104-00035 | K30: 00290520-00027 | N30: 2구역 | T30: 3부녀 | U30: 주숙자 | V30: Дю Светлана | W30: 여 | X30: 21465 | Y30: 67 | Z30: 010-5567-8193 | AA30: @DyuSvetlana | AB30: 집사 | AC30: 총회등록 | AD30: 러시아 | AE30: 한국 | AF30: 서울특별시
A31: 33 | B31: 00390826-00069 | C31: 48 | D31: 국내성도 | E31: 국내_부녀 | F31: 00360527-00006 | G31: 김세진 | H31: 00360527-00006 | I31: 00390826-00066 | J31: 00270104-00035 | K31: 00290520-00027 | N31: 2구역 | T31: 3부녀 | U31: 이소피야 | V31: Ли София (LISOFIIA) | W31: 여 | X31: 25896 | Y31: 55 | Z31: 010-8205-9722 | AA31: @Lisonehka | AB31: 성도 | AC31: 총회등록 | AD31: 키르기스스탄 | AE31: 한국 | AF31: 인천광역시 | AI31: 147-1기
A32: 34 | B32: 00410325-00430 | C32: 50 | D32: 국내성도 | E32: 국내_부녀 | F32: 00360527-00006 | G32: 김세진 | H32: 00360527-00006 | I32: 00390826-00066 | J32: 00270104-00035 | K32: 00290520-00027 | N32: 2구역 | T32: 3부녀 | U32: 출리나율리야그리고리예브나 | V32: Чулина Юлия Григорьевна | W32: 여 | X32: 35278 | Y32: 29 | Z32: 010-8441-1321 | AA32: @YuliaChulina | AB32: 성도 | AC32: 교회등록 | AD32: 러시아 | AE32: 한국 | AF32: 군산 | AI32: 153-5기
A33: 35 | B33: 00330216-00019 | C33: 52 | D33: 국내성도 | E33: 국내_부녀 | N33: 2구역 | T33: 3부녀 | U33: 황알렙지나 | W33: 여 | X33: 21302 | Y33: 67 | Z33: 010-4503-7372 | AE33: 한국 | AF33: 중랑구
A34: 36 | B34: 00400819-00001 | C34: 54 | D34: 국내성도 | E34: 국내_부녀 | F34: 00360527-00006 | G34: 김세진 | H34: 00360527-00006 | I34: 00390826-00066 | J34: 00270104-00035 | K34: 00290520-00027 | N34: 2구역 | T34: 3부녀 | U34: 두드키나스베틀라나미하일로브나 | V34: ДУДКИНА СВЕТЛАНА МИХАЙЛОВНА | W34: 여 | X34: 22442 | Y34: 64 | Z34: 010-2213-7839 | AB34: 성도 | AC34: 입교 | AD34: 러시아 | AE34: 한국 | AF34: 경기도 | AH34: 출결제외해지(2025/3/1) | AI34: 151-1기 | AJ34: 신앙유약
A35: 37 | B35: 00360830-00341 | C35: 56 | D35: 국내성도 | E35: 국내_부녀 | F35: 00360527-00006 | G35: 김세진 | H35: 00360527-00006 | I35: 00360830-00341 | J35: 00410822-00001 | N35: 3구역 | P35: 구역장 | Q35: 구역장 | T35: 3부녀 | U35: 한엘자 | V35: Хан Эльза | W35: 여 | X35: 20944 | Y35: 68 | Z35: 010-8939-1957 | AA35: @han_elza | AB35: 집사 | AC35: 총회등록 | AD35: 우즈베키스탄 | AE35: 한국 | AF35: 서울특별시
A36: 38 | B36: 00410822-00001 | C36: 58 | D36: 국내성도 | E36: 국내_부녀 | F36: 00360527-00006 | G36: 김세진 | H36: 00360527-00006 | I36: 00360830-00341 | J36: 00410822-00001 | N36: 3구역 | P36: 부구역장 | Q36: 부구역장 | T36: 3부녀 | U36: 박스베틀라나발레리야노브나 | V36: Pak Svetlana Valerlyanovna | W36: 여 | X36: 23254 | Y36: 62 | Z36: 010-4766-1953 | AB36: 성도 | AC36: 교회등록 | AD36: 우즈베키스탄 | AE36: 한국 | AI36: 155기 | AJ36: D
A37: 39 | B37: 00400530-00092 | C37: 60 | D37: 국내성도 | E37: 국내_부녀 | F37: 00360527-00006 | G37: 김세진 | H37: 00360527-00006 | I37: 00360830-00341 | J37: 00410822-00001 | N37: 3구역 | T37: 1자문 | U37: 박모이세이 | V37: Пак Моисей | W37: 남 | X37: 19784 | Y37: 71 | Z37: 010-4074-3821 | AB37: 집사 | AC37: 총회등록 | AD37: 우즈베키스탄 | AE37: 한국 | AF37: 경기도 | AI37: 150-4기
A38: 40 | B38: 00230828-00053 | C38: 62 | D38: 국내성도 | E38: 국내_부녀 | F38: 00360527-00006 | G38: 김세진 | H38: 00360527-00006 | I38: 00230828-00053 | J38: x | N38: 4구역 | P38: 구역장 | Q38: 구역장 | T38: 3부녀 | U38: 박소정 | V38: Пак Со Джон | W38: 여 | X38: 30920 | Y38: 41 | Z38: 010-4316-0828 | AA38: @sojeong84 | AB38: 집사 | AC38: 총회등록 | AD38: 한국 | AE38: 한국 | AF38: 경기도
A39: 41 | B39: 00271115-00181 | C39: 64 | D39: 국내성도 | E39: 국내_부녀 | F39: 00360527-00006 | G39: 김세진 | H39: 00360527-00006 | I39: 00230828-00053 | J39: x | N39: 4구역 | P39: 기능과 | Q39: 통번역팀장 | T39: 3부녀 | U39: 김옥사나 | V39: Ким Оксана | W39: 여 | X39: 31700 | Y39: 39 | Z39: 010-5635-1510 | AA39: @Kim_Sana181 | AB39: 집사 | AC39: 총회등록 | AD39: 우즈베키스탄 | AE39: 한국 | AF39: 서울특별시
A40: 42 | B40: 00280103-00165 | C40: 66 | D40: 국내성도 | E40: 국내_부녀 | F40: 00360527-00006 | G40: 김세진 | H40: 00360527-00006 | I40: 00230828-00053 | J40: x | N40: 4구역 | P40: 기능과 | T40: 3부녀 | U40: 이지영 | V40: Ли Джи Ён | W40: 여 | X40: 30683 | Y40: 42 | Z40: 010-6701-0334 | AA40: @Yijiyeong | AB40: 집사 | AC40: 총회등록 | AD40: 한국 | AE40: 한국 | AF40: 경기도
...

Sheet 42년6월 취합마스터파일
AC1: 39 | AD1: 2022
AD2: 2025 | AE2: 국가별 지역 관할
AD3: 2025 | AE3: 러시아 | AF3: 사할린
AD4: 2025 | AF4: 사하공화국 (야쿠티야),야쿠츠크
AD5: 2025
AD6: 2025
AD7: 2025 | AE7: 카자흐스탄 | AF7: 아스타나
AD8: 2025 | AF8: 카라간다
AD9: 2025
AD10: 2025
AD11: 2025 | AE11: 해외개척지역 | AF11: 벨라루스,폴란드,루마니아
AD12: 2025
AD13: 2025
AD14: 2025
AD15: 2025
AC16: 40 | AD16: 2023
AC17: 41 | AD17: 2024
AC18: 42 | AD18: 2025
B19: 700 | C19: 총인원 | D19: =SUBTOTAL(103,$E$21:E767) -> 700
B20: 번호 | C20: 고유번호 | D20: 인원수 | E20: 지역 | F20: 팀 | G20: 지역총괄팀장 | H20: 담당팀장 | I20: 팀장 | J20: 구역장 | K20: 부구역장(1) | L20: 부구역장(2) | M20: 부구역장(3) | N20: 부구역장(4) | O20: 구역 | P20: 새신자 | Q20: 행정직책 | R20: 직책 | S20: 겸직 | T20: 부서 | U20: 이름(KR) | V20: 이름(RU) | W20: 성별 | X20: 생년월일 | Y20: (만)나이 | Z20: 전화번호 | AA20: 텔레사용자명 | AB20: 직분 | AC20: 등록상태 | AD20: 국적 | AE20: 국가 | AF20: 도시명 | AG20: 출결 여부 | AH20: 사유/기간 | AI20: 센터기수 | AJ20: 기타사항 | AK20: 시차 | AL20: 체크2
B21: 1 | C21: 00311023-00027 | D21: =SUBTOTAL(103,$T$21:T21) -> 1 | E21: 국내성도 | F21: 국내_청년 | G21: 00350330-00205 | H21: 김세진 | I21: 00360527-00006 | J21: 00311023-00027 | K21: x | L21: x | O21: 1구역 | Q21: 구역장 | R21: 구역장 | T21: 4청년 | U21: 주유리 | V21: Дю Юрий | W21: 남 | X21: 32377 | Y21: =DATEDIF(X21,TODAY(),"Y") -> 37 | Z21: 010-3141-8193 | AA21: @DyuYurii | AB21: 문도 | AC21: 총회등록 | AD21: 러시아 | AE21: 한국 | AF21: 서울특별시
B22: 2 | C22: 00360527-00006 | D22: =SUBTOTAL(103,$T$21:T22) -> 2 | E22: 국내성도 | F22: 국내_장년 | G22: 00350330-00205 | H22: 김세진 | I22: 00360527-00006 | J22: 00311023-00027 | K22: x | L22: x | O22: 1구역 | Q22: 팀장 | R22: 국내총괄팀장 | S22: 구역장 | T22: 2장년 | U22: 김세진 | V22: Ким Сергей | W22: 남 | X22: 32431 | Y22: =DATEDIF(X22,TODAY(),"Y") -> 37 | Z22: 010-6640-3437 | AA22: @execute25 | AB22: 집사 | AC22: 총회등록 | AD22: 우즈베키스탄/한국(국적취득) | AE22: 한국 | AF22: 경기도
B23: 3 | C23: 00360830-00345 | D23: =SUBTOTAL(103,$T$21:T23) -> 3 | E23: 국내성도 | F23: 국내_장년 | G23: 00350330-00205 | H23: 김세진 | I23: 00360527-00006 | J23: 00311023-00027 | K23: x | L23: x | O23: 1구역 | T23: 2장년 | U23: 허드미트리 | V23: Хе Дмитрий | W23: 남 | X23: 32370 | Y23: =DATEDIF(X23,TODAY(),"Y") -> 37 | Z23: 010-9575-8815 | AA23: @Dmitriyhe | AB23: 집사 | AC23: 총회등록 | AD23: 우즈베키스탄 | AE23: 한국 | AF23: 서울특별시
B24: 4 | C24: 00291129-00211 | D24: =SUBTOTAL(103,$T$21:T24) -> 4 | E24: 우크라이나(키이우) | F24: 국내_장년 | G24: 00350330-00205 | H24: 김세진 | I24: 00360527-00006 | J24: 00311023-00027 | K24: x | L24: x | O24: 1구역 | T24: 2장년 | U24: 김에두아르드 | V24: Ким Эдуард | W24: 남 | X24: 29900 | Y24: =DATEDIF(X24,TODAY(),"Y") -> 44 | Z24: 010-2426-2496/(1(506)-898-3709) | AA24: @Edward_cbt | AB24: 집사 | AC24: 총회등록 | AD24: 우크라이나 | AE24: 캐나다 | AF24: 프레더릭턴
B25: 5 | C25: 00360830-00344 | D25: =SUBTOTAL(103,$T$21:T25) -> 5 | E25: 국내성도 | F25: 국내_장년 | G25: 00350330-00205 | H25: 김세진 | I25: 00360527-00006 | J25: 00311023-00027 | K25: x | L25: x | O25: 1구역 | T25: 2장년 | U25: 이드미트리 | V25: Ли Дмитрий | W25: 남 | X25: 32279 | Y25: =DATEDIF(X25,TODAY(),"Y") -> 37 | Z25: 010-2351-0933 | AA25: @DMITRIYLEE88 | AB25: 집사 | AC25: 총회등록 | AD25: 우즈베키스탄 | AE25: 한국 | AF25: 서울특별시
B26: 6 | C26: 00320813-00008 | D26: =SUBTOTAL(103,$T$21:T26) -> 6 | E26: 국내성도 | F26: 국내_장년 | G26: 00350330-00205 | H26: 김세진 | I26: 00360527-00006 | J26: 00311023-00027 | K26: x | L26: x | O26: 1구역 | T26: 2장년 | U26: 박뱌체슬라브 | V26: Пак Вячеслав | W26: 남 | X26: 31456 | Y26: =DATEDIF(X26,TODAY(),"Y") -> 39 | Z26: 010-4374-0713 | AA26: @vvv13park | AB26: 집사 | AC26: 총회등록 | AD26: 우즈베키스탄 | AE26: 한국 | AF26: 서울특별시
B27: 7 | C27: 00390826-00075 | D27: =SUBTOTAL(103,$T$21:T27) -> 7 | E27: 국내성도 | F27: 국내_청년 | G27: 00350330-00205 | H27: 김세진 | I27: 00360527-00006 | J27: 00390826-00075 | K27: 00371217-01048 | L27: x | O27: 2구역 | Q27: 구역장 | R27: 구역장 | T27: 4청년 | U27: 김세르게이발레리예비치 | V27: Ким Сергей Валерьевич | W27: 남 | X27: 32305 | Y27: =DATEDIF(X27,TODAY(),"Y") -> 37 | Z27: 010-8441-1728 | AA27: @k_i_m_sergey | AB27: 문도 | AC27: 총회등록 | AD27: 러시아 | AE27: 한국 | AF27: 경기도 | AI27: 147-1기
B28: 8 | C28: 00371217-01048 | D28: =SUBTOTAL(103,$T$21:T28) -> 8 | E28: 국내성도 | F28: 국내_장년 | G28: 00350330-00205 | H28: 김세진 | I28: 00360527-00006 | J28: 00390826-00075 | K28: 00371217-01048 | L28: x | O28: 2구역 | Q28: 팀장 | R28: 새신자팀장 | S28: 구역장 | T28: 2장년 | U28: 강블라디미르파블로비치 | V28: Кан Владимир | W28: 남 | X28: 33031 | Y28: =DATEDIF(X28,TODAY(),"Y") -> 35 | Z28: 010-5820-6557 | AA28: @kanVladimir7 | AB28: 집사 | AC28: 총회등록 | AD28: 러시아 | AE28: 한국 | AF28: 서울특별시
B29: 9 | C29: 00371218-00469 | D29: =SUBTOTAL(103,$T$21:T29) -> 9 | E29: 국내성도 | F29: 국내_장년 | G29: 00350330-00205 | H29: 김세진 | I29: 00360527-00006 | J29: 00390826-00075 | K29: 00371217-01048 | L29: x | O29: 2구역 | T29: 2장년 | U29: 한세묜세묘노비치 | V29: Хан Семён | W29: 남 | X29: 33599 | Y29: =DATEDIF(X29,TODAY(),"Y") -> 34 | Z29: 010-8433-2802 | AB29: 집사 | AC29: 총회등록 | AD29: 우즈베키스탄 | AE29: 한국 | AF29: 서울특별시
B30: 10 | C30: 00390826-00117 | D30: =SUBTOTAL(103,$T$21:T30) -> 10 | E30: 국내성도 | F30: 국내_청년 | G30: 00350330-00205 | H30: 김세진 | I30: 00360527-00006 | J30: 00390826-00075 | K30: 00371217-01048 | L30: x | O30: 2구역 | T30: 4청년 | U30: 손이고르아루투로비치 | V30: Сон Игорь Артурович | W30: 남 | X30: 36739 | Y30: =DATEDIF(X30,TODAY(),"Y") -> 25 | Z30: 010-97112243 | AB30: 성도 | AC30: 입교 | AD30: 우즈베키스탄 | AE30: 한국 | AF30: 서울특별시 | AI30: 147-4기
B31: 11 | C31: 00410822-00002 | D31: =SUBTOTAL(103,$T$21:T31) -> 11 | E31: 국내성도 | F31: 새신자4팀 | G31: 00350330-00205 | H31: 김세진 | I31: 00360527-00006 | J31: 00390826-00075 | K31: 00371217-01048 | L31: x | O31: 2구역 | T31: 4청년 | U31: 야쿠빈스키이드미트리이고레비치 | V31: Якубинский Дмитрий Игоревич | W31: 남 | X31: 32741 | Y31: =DATEDIF(X31,TODAY(),"Y") -> 36 | Z31: 010-5890-1703 | AA31: @dimadimadimadimadimadimadima1989 | AB31: 성도 | AC31: 교회등록 | AD31: 러시아 | AE31: 한국 | AF31: 인천광역시 | AI31: 155기
B32: 12 | C32: 00360830-00347 | D32: =SUBTOTAL(103,$T$21:T32) -> 12 | E32: 국내성도 | F32: 국내_청년 | G32: 00350330-00205 | H32: 김세진 | I32: 00360527-00006 | J32: 00390826-00075 | K32: 00371217-01048 | L32: x | O32: 2구역 | T32: 4청년 | U32: 강파벨 | V32: Кан Павел | W32: 남 | X32: 33538 | Y32: =DATEDIF(X32,TODAY(),"Y") -> 34 | Z32: 010-5552-2710 | AB32: 성도 | AC32: 입교 | AD32: 카자흐스탄 | AE32: 한국 | AF32: 경상북도 | AH32: 출결제외해지(2023/03/14) | AJ32: 신앙유약
B33: 13 | C33: 00400227-01416 | D33: =SUBTOTAL(103,$T$21:T33) -> 13 | E33: 국내성도 | F33: 국내_청년 | G33: 00350330-00205 | H33: 김세진 | I33: 00360527-00006 | J33: 00390826-00075 | K33: 00371217-01048 | L33: x | O33: 2구역 | T33: 4청년 | U33: 김예브게니알렉산드로비치 | V33: Ким Евгений Александрович | W33: 남 | X33: 33400 | Y33: =DATEDIF(X33,TODAY(),"Y") -> 34 | Z33: 7-747-455-6934 | AB33: 성도 | AC33: 입교 | AD33: 카자흐스탄 | AE33: 카자흐스탄 | AF33: 알마티 | AH33: 출결제외해지(2025/3/1) | AI33: 149-1기 | AJ33: 신앙유약
C34: 00261114-00053 | D34: =SUBTOTAL(103,$T$21:T34) -> 13 | F34: 국내_부녀 | G34: 00350330-00205 | H34: 박지민 | I34: 00341026-00033 | J34: 00261114-00053 | K34: x | L34: x | O34: 1구역 | Q34: 임원 | R34: 총무 | S34: 구역장 | U34: 박지민 | AC34: 총회등록 | AG34: 중복
B35: 14 | C35: 00361031-00487 | D35: =SUBTOTAL(103,$T$21:T35) -> 14 | E35: 국내성도 | F35: 국내_부녀 | G35: 00350330-00205 | H35: 박지민 | I35: 00261114-00053 | J35: 00261114-00053 | K35: x | L35: x | O35: 1구역 | T35: 3부녀 | U35: 최릴리야 | V35: Цой Лилия | W35: 여 | X35: 33815 | Y35: =DATEDIF(X35,TODAY(),"Y") -> 33 | Z35: 010-7550-5848 | AB35: 집사 | AC35: 총회등록 | AD35: 우즈베키스탄 | AE35: 한국 | AF35: 인천광역시
B36: 15 | C36: 00310314-00227 | D36: =SUBTOTAL(103,$T$21:T36) -> 15 | E36: 국내성도 | F36: 국내_부녀 | G36: 00350330-00205 | H36: 박지민 | I36: 00261114-00053 | J36: 00261114-00053 | K36: x | L36: x | O36: 1구역 | T36: 3부녀 | U36: 한옐레나 | V36: Хан Елена | W36: 여 | X36: 31075 | Y36: =DATEDIF(X36,TODAY(),"Y") -> 41 | Z36: 010-8285-1011 | AB36: 집사 | AC36: 입교 | AD36: 러시아 | AE36: 한국 | AF36: 서울특별시 | AH36: 출결제외해지(2025/3/1) | AJ36: 신앙유약
B37: 16 | C37: 00311023-00028 | D37: =SUBTOTAL(103,$T$21:T37) -> 16 | E37: 국내성도 | F37: 국내_부녀 | G37: 00350330-00205 | H37: 박지민 | I37: 00261114-00053 | J37: 00261114-00053 | K37: x | L37: x | O37: 1구역 | T37: 3부녀 | U37: 박옐레나 | V37: Пак Елена | W37: 여 | X37: 32547 | Y37: =DATEDIF(X37,TODAY(),"Y") -> 36 | Z37: 010-5615-2266 | AB37: 집사 | AC37: 입교 | AD37: 우즈베키스탄 | AE37: 한국 | AF37: 경기도
B38: 17 | C38: 00340624-00330 | D38: =SUBTOTAL(103,$T$21:T38) -> 17 | E38: 국내성도 | F38: 국내_부녀 | G38: 00350330-00205 | H38: 박지민 | I38: 00261114-00053 | J38: 00261114-00053 | K38: x | L38: x | O38: 1구역 | T38: 3부녀 | U38: 최유나 | V38: Цой Ольга | W38: 여 | X38: 31062 | Y38: =DATEDIF(X38,TODAY(),"Y") -> 41 | Z38: 010-2570-6278 | AB38: 집사 | AC38: 총회등록 | AD38: 한국 | AE38: 한국 | AF38: 서울특별시
B39: 18 | C39: 00280508-00022 | D39: =SUBTOTAL(103,$T$21:T39) -> 18 | E39: 국내성도 | F39: 국내_부녀 | G39: 00350330-00205 | H39: 박지민 | I39: 00261114-00053 | J39: 00261114-00053 | K39: x | L39: x | O39: 1구역 | T39: 3부녀 | U39: 엘리나바투크흐티나 | V39: Батухтина Элина | W39: 여 | X39: 31504 | Y39: =DATEDIF(X39,TODAY(),"Y") -> 39 | Z39: 010-4593-5238 | AB39: 문도 | AC39: 입교 | AD39: 우크라이나 | AE39: 한국 | AF39: 서울특별시 | AH39: 출결제외해지(2025/3/1) | AJ39: 신앙유약
B40: 19 | C40: 00400227-01392 | D40: =SUBTOTAL(103,$T$21:T40) -> 19 | E40: 국내성도 | F40: 국내_부녀 | G40: 00350330-00205 | H40: 박지민 | I40: 00261114-00053 | J40: 00261114-00053 | K40: x | L40: x | O40: 1구역 | T40: 3부녀 | U40: 리스베틀라나아나톨리예브나 | V40: Светлана ЛИ | W40: 여 | X40: 23079 | Y40: =DATEDIF(X40,TODAY(),"Y") -> 62 | Z40: 010-2117-9127 | AA40: @Liswetik | AB40: 성도 | AC40: 입교 | AD40: 카자흐스탄 | AE40: 한국 | AF40: 경기도 | AH40: 출결제외해지(2025/3/1) | AI40: 149-1기 | AJ40: 신앙유약
...

Sheet 42년5월 취합마스터파일
AF2: 국가별 지역 관할
AF3: 러시아 | AG3: 사할린
AG4: 사하공화국 (야쿠티야),야쿠츠크
AF7: 카자흐스탄 | AG7: 아스타나
AG8: 카라간다
AF11: 해외개척지역 | AG11: 벨라루스,폴란드,루마니아
C19: 674 | D19: 총인원 | E19: =SUBTOTAL(103,$F$21:F741) -> 674
C20: 번호 | D20: 고유번호 | E20: 인원수 | F20: 지역 | G20: 팀 | H20: 지역총괄팀장 | I20: 담당팀장 | J20: 팀장 | K20: 구역장 | L20: 부구역장(1) | M20: 부구역장(2) | N20: 부구역장(3) | O20: 부구역장(4) | P20: 구역 | Q20: 새신자 | R20: 행정직책 | S20: 직책 | T20: 겸직 | U20: 부서 | V20: 이름(KR) | W20: 이름(RU) | X20: 성별 | Y20: 생년월일 | Z20: (만)나이 | AA20: 전화번호 | AB20: 텔레사용자명 | AC20: 직분 | AD20: 등록상태 | AE20: 국적 | AF20: 국가 | AG20: 도시명 | AH20: 출결 여부 | AI20: 사유/기간 | AJ20: 센터기수 | AK20: 기타사항 | AL20: 체크 | AM20: 체크2
C21: 1 | D21: 00311023-00027 | E21: =SUBTOTAL(103,$U$21:U21) -> 1 | F21: 국내성도 | G21: 국내_청년 | H21: 00350330-00205 | I21: 김세진 | J21: 00360527-00006 | K21: 00311023-00027 | L21: x | M21: x | P21: 1구역 | R21: 구역장 | S21: 구역장 | U21: 4청년 | V21: 주유리 | W21: Дю Юрий | X21: 남 | Y21: 32377 | Z21: =DATEDIF(Y21,TODAY(),"Y") -> 37 | AA21: 010-3141-8193 | AB21: @DyuYurii | AC21: 문도 | AD21: 총회등록 | AE21: 러시아 | AF21: 한국 | AG21: 서울특별시
C22: 2 | D22: 00360527-00006 | E22: =SUBTOTAL(103,$U$21:U22) -> 2 | F22: 국내성도 | G22: 국내_장년 | H22: 00350330-00205 | I22: 김세진 | J22: 00360527-00006 | K22: 00311023-00027 | L22: x | M22: x | P22: 1구역 | R22: 팀장 | S22: 국내총괄팀장 | T22: 구역장 | U22: 2장년 | V22: 김세진 | W22: Ким Сергей | X22: 남 | Y22: 32431 | Z22: =DATEDIF(Y22,TODAY(),"Y") -> 37 | AA22: 010-6640-3437 | AB22: @execute25 | AC22: 집사 | AD22: 총회등록 | AE22: 우즈베키스탄/한국(국적취득) | AF22: 한국 | AG22: 경기도
C23: 3 | D23: 00360830-00345 | E23: =SUBTOTAL(103,$U$21:U23) -> 3 | F23: 국내성도 | G23: 국내_장년 | H23: 00350330-00205 | I23: 김세진 | J23: 00360527-00006 | K23: 00311023-00027 | L23: x | M23: x | P23: 1구역 | U23: 2장년 | V23: 허드미트리 | W23: Хе Дмитрий | X23: 남 | Y23: 32370 | Z23: =DATEDIF(Y23,TODAY(),"Y") -> 37 | AA23: 010-9575-8815 | AB23: @Dmitriyhe | AC23: 집사 | AD23: 총회등록 | AE23: 우즈베키스탄 | AF23: 한국 | AG23: 서울특별시
C24: 4 | D24: 00291129-00211 | E24: =SUBTOTAL(103,$U$21:U24) -> 4 | F24: 해외개척 | G24: 국내_장년 | H24: 00350330-00205 | I24: 김세진 | J24: 00360527-00006 | K24: 00311023-00027 | L24: x | M24: x | P24: 1구역 | U24: 2장년 | V24: 김에두아르드 | W24: Ким Эдуард | X24: 남 | Y24: 29900 | Z24: =DATEDIF(Y24,TODAY(),"Y") -> 44 | AA24: 010-2426-2496/(1(506)-898-3709) | AB24: @Edward_cbt | AC24: 집사 | AD24: 총회등록 | AE24: 우크라이나 | AF24: 캐나다 | AG24: 프레더릭턴
C25: 5 | D25: 00360830-00344 | E25: =SUBTOTAL(103,$U$21:U25) -> 5 | F25: 국내성도 | G25: 국내_장년 | H25: 00350330-00205 | I25: 김세진 | J25: 00360527-00006 | K25: 00311023-00027 | L25: x | M25: x | P25: 1구역 | U25: 2장년 | V25: 이드미트리 | W25: Ли Дмитрий | X25: 남 | Y25: 32279 | Z25: =DATEDIF(Y25,TODAY(),"Y") -> 37 | AA25: 010-2351-0933 | AB25: @DMITRIYLEE88 | AC25: 집사 | AD25: 총회등록 | AE25: 우즈베키스탄 | AF25: 한국 | AG25: 서울특별시
C26: 6 | D26: 00320813-00008 | E26: =SUBTOTAL(103,$U$21:U26) -> 6 | F26: 국내성도 | G26: 국내_장년 | H26: 00350330-00205 | I26: 김세진 | J26: 00360527-00006 | K26: 00311023-00027 | L26: x | M26: x | P26: 1구역 | U26: 2장년 | V26: 박뱌체슬라브 | W26: Пак Вячеслав | X26: 남 | Y26: 31456 | Z26: =DATEDIF(Y26,TODAY(),"Y") -> 39 | AA26: 010-4374-0713 | AB26: @vvv13park | AC26: 집사 | AD26: 총회등록 | AE26: 우즈베키스탄 | AF26: 한국 | AG26: 서울특별시
C27: 7 | D27: 00390826-00075 | E27: =SUBTOTAL(103,$U$21:U27) -> 7 | F27: 국내성도 | G27: 국내_청년 | H27: 00350330-00205 | I27: 김세진 | J27: 00360527-00006 | K27: 00390826-00075 | L27: 00371217-01048 | M27: x | P27: 2구역 | R27: 구역장 | S27: 구역장 | U27: 4청년 | V27: 김세르게이발레리예비치 | W27: Ким Сергей Валерьевич | X27: 남 | Y27: 32305 | Z27: =DATEDIF(Y27,TODAY(),"Y") -> 37 | AA27: 010-8441-1728 | AB27: @k_i_m_sergey | AC27: 문도 | AD27: 총회등록 | AE27: 러시아 | AF27: 한국 | AG27: 경기도 | AJ27: 147-1기
C28: 8 | D28: 00371217-01048 | E28: =SUBTOTAL(103,$U$21:U28) -> 8 | F28: 국내성도 | G28: 국내_장년 | H28: 00350330-00205 | I28: 김세진 | J28: 00360527-00006 | K28: 00390826-00075 | L28: 00371217-01048 | M28: x | P28: 2구역 | R28: 팀장 | S28: 새신자팀장 | T28: 구역장 | U28: 2장년 | V28: 강블라디미르파블로비치 | W28: Кан Владимир | X28: 남 | Y28: 33031 | Z28: =DATEDIF(Y28,TODAY(),"Y") -> 35 | AA28: 010-5820-6557 | AB28: @kanVladimir7 | AC28: 집사 | AD28: 총회등록 | AE28: 러시아 | AF28: 한국 | AG28: 서울특별시
C29: 9 | D29: 00371218-00469 | E29: =SUBTOTAL(103,$U$21:U29) -> 9 | F29: 국내성도 | G29: 국내_장년 | H29: 00350330-00205 | I29: 김세진 | J29: 00360527-00006 | K29: 00390826-00075 | L29: 00371217-01048 | M29: x | P29: 2구역 | U29: 2장년 | V29: 한세묜세묘노비치 | W29: Хан Семён | X29: 남 | Y29: 33599 | Z29: =DATEDIF(Y29,TODAY(),"Y") -> 34 | AA29: 010-8433-2802 | AC29: 집사 | AD29: 총회등록 | AE29: 우즈베키스탄 | AF29: 한국 | AG29: 서울특별시
C30: 10 | D30: 00390826-00117 | E30: =SUBTOTAL(103,$U$21:U30) -> 10 | F30: 국내성도 | G30: 국내_청년 | H30: 00350330-00205 | I30: 김세진 | J30: 00360527-00006 | K30: 00390826-00075 | L30: 00371217-01048 | M30: x | P30: 2구역 | U30: 4청년 | V30: 손이고르아루투로비치 | W30: Сон Игорь Артурович | X30: 남 | Y30: 36739 | Z30: =DATEDIF(Y30,TODAY(),"Y") -> 25 | AA30: 010-97112243 | AC30: 성도 | AD30: 입교 | AE30: 우즈베키스탄 | AF30: 한국 | AG30: 서울특별시 | AJ30: 147-4기
C31: 11 | D31: 00410822-00002 | E31: =SUBTOTAL(103,$U$21:U31) -> 11 | F31: 국내성도 | G31: 새신자4팀 | H31: 00350330-00205 | I31: 김세진 | J31: 00360527-00006 | K31: 00390826-00075 | L31: 00371217-01048 | M31: x | P31: 2구역 | U31: 4청년 | V31: 야쿠빈스키이드미트리이고레비치 | W31: Якубинский Дмитрий Игоревич | X31: 남 | Y31: 32741 | Z31: =DATEDIF(Y31,TODAY(),"Y") -> 36 | AA31: 010-5890-1703 | AB31: @dimadimadimadimadimadimadima1989 | AC31: 성도 | AD31: 교회등록 | AE31: 러시아 | AF31: 한국 | AG31: 인천광역시 연수구 | AJ31: 155기
C32: 12 | D32: 00360830-00347 | E32: =SUBTOTAL(103,$U$21:U32) -> 12 | F32: 국내성도 | G32: 국내_청년 | H32: 00350330-00205 | I32: 김세진 | J32: 00360527-00006 | K32: 00390826-00075 | L32: 00371217-01048 | M32: x | P32: 2구역 | U32: 4청년 | V32: 강파벨 | W32: Кан Павел | X32: 남 | Y32: 33538 | Z32: =DATEDIF(Y32,TODAY(),"Y") -> 34 | AA32: 010-5552-2710 | AC32: 성도 | AD32: 입교 | AE32: 카자흐스탄 | AF32: 한국 | AG32: 경상북도 | AI32: 출결제외해지(2023/03/14) | AK32: 신앙유약
C33: 13 | D33: 00400227-01416 | E33: =SUBTOTAL(103,$U$21:U33) -> 13 | F33: 국내성도 | G33: 국내_청년 | H33: 00350330-00205 | I33: 김세진 | J33: 00360527-00006 | K33: 00390826-00075 | L33: 00371217-01048 | M33: x | P33: 2구역 | U33: 4청년 | V33: 김예브게니알렉산드로비치 | W33: Ким Евгений Александрович | X33: 남 | Y33: 33400 | Z33: =DATEDIF(Y33,TODAY(),"Y") -> 34 | AA33: 7-747-455-6934 | AC33: 성도 | AD33: 입교 | AE33: 카자흐스탄 | AF33: 카자흐스탄 | AG33: 알마티 | AI33: 출결제외해지(2025/3/1) | AJ33: 149-1기 | AK33: 신앙유약
C34: 14 | D34: 00261114-00053 | E34: =SUBTOTAL(103,$U$21:U34) -> 13 | G34: 국내_부녀 | H34: 00350330-00205 | I34: 박지민 | J34: 00341026-00033 | K34: 00261114-00053 | L34: x | M34: x | P34: 1구역 | R34: 임원 | S34: 부장 | T34: 구역장 | V34: 박지민 | AD34: 총회등록 | AH34: 중복
C35: 15 | D35: 00361031-00487 | E35: =SUBTOTAL(103,$U$21:U35) -> 14 | F35: 국내성도 | G35: 국내_부녀 | H35: 00350330-00205 | I35: 박지민 | J35: 00261114-00053 | K35: 00261114-00053 | L35: x | M35: x | P35: 1구역 | U35: 3부녀 | V35: 최릴리야 | W35: Цой Лилия | X35: 여 | Y35: 33815 | Z35: =DATEDIF(Y35,TODAY(),"Y") -> 33 | AA35: 010-7550-5848 | AC35: 집사 | AD35: 총회등록 | AE35: 우즈베키스탄 | AF35: 한국 | AG35: 인천광역시
C36: 16 | D36: 00310314-00227 | E36: =SUBTOTAL(103,$U$21:U36) -> 15 | F36: 국내성도 | G36: 국내_부녀 | H36: 00350330-00205 | I36: 박지민 | J36: 00261114-00053 | K36: 00261114-00053 | L36: x | M36: x | P36: 1구역 | U36: 3부녀 | V36: 한옐레나 | W36: Хан Елена | X36: 여 | Y36: 31075 | Z36: =DATEDIF(Y36,TODAY(),"Y") -> 41 | AA36: 010-8285-1011 | AC36: 집사 | AD36: 입교 | AE36: 러시아 | AF36: 한국 | AG36: 서울특별시 | AI36: 출결제외해지(2025/3/1) | AK36: 신앙유약
C37: 17 | D37: 00311023-00028 | E37: =SUBTOTAL(103,$U$21:U37) -> 16 | F37: 국내성도 | G37: 국내_부녀 | H37: 00350330-00205 | I37: 박지민 | J37: 00261114-00053 | K37: 00261114-00053 | L37: x | M37: x | P37: 1구역 | U37: 3부녀 | V37: 박옐레나 | W37: Пак Елена | X37: 여 | Y37: 32547 | Z37: =DATEDIF(Y37,TODAY(),"Y") -> 36 | AA37: 010-5615-2266 | AC37: 집사 | AD37: 총회등록 | AE37: 우즈베키스탄 | AF37: 한국 | AG37: 경기도
C38: 18 | D38: 00340624-00330 | E38: =SUBTOTAL(103,$U$21:U38) -> 17 | F38: 국내성도 | G38: 국내_부녀 | H38: 00350330-00205 | I38: 박지민 | J38: 00261114-00053 | K38: 00261114-00053 | L38: x | M38: x | P38: 1구역 | U38: 3부녀 | V38: 최유나 | W38: Цой Ольга | X38: 여 | Y38: 31062 | Z38: =DATEDIF(Y38,TODAY(),"Y") -> 41 | AA38: 010-2570-6278 | AC38: 집사 | AD38: 총회등록 | AE38: 한국 | AF38: 한국 | AG38: 서울특별시
C39: 19 | D39: 00280508-00022 | E39: =SUBTOTAL(103,$U$21:U39) -> 18 | F39: 국내성도 | G39: 국내_부녀 | H39: 00350330-00205 | I39: 박지민 | J39: 00261114-00053 | K39: 00261114-00053 | L39: x | M39: x | P39: 1구역 | U39: 3부녀 | V39: 엘리나바투크흐티나 | W39: Батухтина Элина | X39: 여 | Y39: 31504 | Z39: =DATEDIF(Y39,TODAY(),"Y") -> 39 | AA39: 010-4593-5238 | AC39: 문도 | AD39: 입교 | AE39: 우크라이나 | AF39: 한국 | AG39: 서울특별시 | AI39: 출결제외해지(2025/3/1) | AK39: 신앙유약
C40: 20 | D40: 00400227-01392 | E40: =SUBTOTAL(103,$U$21:U40) -> 19 | F40: 국내성도 | G40: 국내_부녀 | H40: 00350330-00205 | I40: 박지민 | J40: 00261114-00053 | K40: 00261114-00053 | L40: x | M40: x | P40: 1구역 | U40: 3부녀 | V40: 리스베틀라나아나톨리예브나 | W40: Светлана ЛИ | X40: 여 | Y40: 23079 | Z40: =DATEDIF(Y40,TODAY(),"Y") -> 62 | AA40: 010-2117-9127 | AB40: @Liswetik | AC40: 성도 | AD40: 입교 | AE40: 카자흐스탄 | AF40: 한국 | AG40: 경기도 | AI40: 출결제외해지(2025/3/1) | AJ40: 149-1기 | AK40: 신앙유약
C41: 21 | D41: 00400530-00093 | E41: =SUBTOTAL(103,$U$21:U41) -> 20 | F41: 국내성도 | G41: 국내_부녀 | H41: 00350330-00205 | I41: 박지민 | J41: 00261114-00053 | K41: 00261114-00053 | L41: x | M41: x | P41: 1구역 | U41: 1자문 | V41: 이림마니콜라예브나 | W41: Ли Римма Николаевна | X41: 여 | Y41: 19818 | Z41: =DATEDIF(Y41,TODAY(),"Y") -> 71 | AA41: 998-90-290-3254 | AC41: 성도 | AD41: 입교 | AE41: 우즈베키스탄 | AF41: 한국 | AG41: 경기도 | AI41: 출결제외해지일 (2025/4/1) | AJ41: 150-4기 | AK41: 신앙유약
C42: 22 | D42: 00400227-01414 | E42: =SUBTOTAL(103,$U$21:U42) -> 21 | F42: 국내성도 | G42: 국내_부녀 | H42: 00350330-00205 | I42: 박지민 | J42: 00261114-00053 | K42: 00261114-00053 | L42: x | M42: x | P42: 1구역 | U42: 4청년 | V42: 리알렉시나블라딜레노브나 | W42: Ли Алексина Владиленовна | X42: 여 | Y42: 33012 | Z42: =DATEDIF(Y42,TODAY(),"Y") -> 35 | AA42: 010-4244-3010 | AC42: 성도 | AD42: 입교 | AE42: 카자흐스탄 | AF42: 한국 | AJ42: 149-1기
C43: 23 | D43: 00360830-00346 | E43: =SUBTOTAL(103,$U$21:U43) -> 22 | F43: 국내성도 | G43: 국내_부녀 | H43: 00350330-00205 | I43: 박지민 | J43: 00261114-00053 | K43: 00360830-00346 | L43: 00350330-00153 | M43: x | P43: 2구역 | R43: 구역장 | S43: 구역장 | U43: 3부녀 | V43: 김예카테리나 | W43: Ким Екатерина | X43: 여 | Y43: 33312 | Z43: =DATEDIF(Y43,TODAY(),"Y") -> 34 | AA43: 010-5877-6557 | AB43: @Rina_Kim_1 | AC43: 집사 | AD43: 총회등록 | AE43: 우즈베키스탄 | AF43: 한국 | AG43: 서울특별시
C44: 24 | D44: 00350330-00153 | E44: =SUBTOTAL(103,$U$21:U44) -> 23 | F44: 국내성도 | G44: 국내_부녀 | H44: 00350330-00205 | I44: 박지민 | J44: 00261114-00053 | K44: 00360830-00346 | L44: 00350330-00153 | M44: x | P44: 2구역 | R44: 부구역장 | S44: 부구역장 | U44: 3부녀 | V44: 문발레리야 | W44: Мун Валерия | X44: 여 | Y44: 32771 | Z44: =DATEDIF(Y44,TODAY(),"Y") -> 36 | AA44: 010-7296-2009 | AB44: @leramun | AC44: 집사 | AD44: 총회등록 | AE44: 카자흐스탄 | AF44: 한국 | AG44: 서울특별시
C45: 25 | D45: 00371217-01047 | E45: =SUBTOTAL(103,$U$21:U45) -> 24 | F45: 국내성도 | G45: 국내_부녀 | H45: 00350330-00205 | I45: 박지민 | J45: 00261114-00053 | K45: 00360830-00346 | L45: 00350330-00153 | M45: x | P45: 2구역 | R45: 팀장 | S45: 새신자팀장 | T45: 구역장 | U45: 3부녀 | V45: 칸타코바안나일리니치나 | W45: Кантакова Анна | X45: 여 | Y45: 31722 | Z45: =DATEDIF(Y45,TODAY(),"Y") -> 39 | AA45: 010-2887-6167 | AB45: @annakantakova | AC45: 집사 | AD45: 총회등록 | AE45: 러시아 | AF45: 한국 | AG45: 경기도
C46: 26 | D46: 00270903-00002 | E46: =SUBTOTAL(103,$U$21:U46) -> 25 | F46: 국내성도 | G46: 국내_부녀 | H46: 00350330-00205 | I46: 박지민 | J46: 00261114-00053 | K46: 00360830-00346 | L46: 00350330-00153 | M46: x | P46: 2구역 | U46: 3부녀 | V46: 정류드밀라 | W46: Тен Людмила | X46: 여 | Y46: 30208 | Z46: =DATEDIF(Y46,TODAY(),"Y") -> 43 | AA46: 010-7624-7907 | AC46: 집사 | AD46: 총회등록 | AE46: 카자흐스탄 | AF46: 한국 | AG46: 서울특별시
C47: 27 | D47: 00261225-00087 | E47: =SUBTOTAL(103,$U$21:U47) -> 26 | F47: 국내성도 | G47: 국내_부녀 | H47: 00350330-00205 | I47: 박지민 | J47: 00261114-00053 | K47: 00360830-00346 | L47: 00350330-00153 | M47: x | P47: 2구역 | U47: 3부녀 | V47: 최승미 | W47: Цой Виктория(ЦойСынгМи) | X47: 여 | Y47: 31249 | Z47: =DATEDIF(Y47,TODAY(),"Y") -> 40 | AA47: 010-8921-3985 | AB47: @victoriachoi8 | AC47: 집사 | AD47: 총회등록 | AE47: 우즈베키스탄 | AF47: 한국 | AG47: 서울특별시
C48: 28 | D48: 00320813-00009 | E48: =SUBTOTAL(103,$U$21:U48) -> 27 | F48: 국내성도 | G48: 국내_부녀 | H48: 00350330-00205 | I48: 박지민 | J48: 00261114-00053 | K48: 00360830-00346 | L48: 00350330-00153 | M48: x | P48: 2구역 | U48: 3부녀 | V48: 이다리야B | W48: Ли Дарья | X48: 여 | Y48: 31736 | Z48: =DATEDIF(Y48,TODAY(),"Y") -> 39 | AA48: 010-4045-1523 | AC48: 문도 | AD48: 입교 | AE48: 우즈베키스탄 | AF48: 한국 | AG48: 서울특별시 | AI48: 출결제외해지(2025/3/1) | AK48: 신앙유약
C49: 29 | D49: 00300823-00110 | E49: =SUBTOTAL(103,$U$21:U49) -> 28 | F49: 국내성도 | G49: 국내_청년 | H49: 00350330-00205 | I49: 박지민 | J49: 00261114-00053 | K49: 00360830-00346 | L49: 00350330-00153 | M49: x | P49: 2구역 | U49: 4청년 | V49: 김올가 | W49: Ким Ольга | X49: 여 | Y49: 33222 | Z49: =DATEDIF(Y49,TODAY(),"Y") -> 35 | AA49: 010-2206-1590 | AC49: 문도 | AD49: 입교 | AE49: 우즈베키스탄 | AF49: 한국 | AG49: 서울특별시 | AI49: 출결제외해지(2023/03/14) | AK49: 신앙유약(24/03/27)
C50: 30 | D50: 00390826-00066 | E50: =SUBTOTAL(103,$U$21:U50) -> 29 | F50: 국내성도 | G50: 국내_부녀 | H50: 00350330-00205 | I50: 박지민 | J50: 00261114-00053 | K50: 00390826-00066 | L50: 00270104-00035 | M50: 00290520-00027 | P50: 3구역 | R50: 부구역장 | S50: 부구역장 | U50: 3부녀 | V50: 박이리나빅토로브나 | W50: Пак Ирина Викторовна | X50: 여 | Y50: 24988 | Z50: =DATEDIF(Y50,TODAY(),"Y") -> 57 | AA50: 010-5201-5526 | AB50: @ari2822 | AC50: 성도 | AD50: 총회등록 | AE50: 키르기스스탄 | AF50: 한국 | AG50: 충청북도 | AJ50: 147-1기
C51: 31 | D51: 00270104-00035 | E51: =SUBTOTAL(103,$U$21:U51) -> 30 | F51: 국내성도 | G51: 국내_부녀 | H51: 00350330-00205 | I51: 박지민 | J51: 00261114-00053 | K51: 00390826-00066 | L51: 00270104-00035 | M51: 00290520-00027 | P51: 3구역 | R51: 부구역장 | S51: 부구역장 | U51: 3부녀 | V51: 굴나라사드코바 | W51: Садыкова Гульнара | X51: 여 | Y51: 30935 | Z51: =DATEDIF(Y51,TODAY(),"Y") -> 41 | AA51: 010-6406-8815 | AB51: @Nara_Seoul | AC51: 집사 | AD51: 총회등록 | AE51: 키르기스스탄 | AF51: 한국 | AG51: 서울특별시
C52: 32 | D52: 00290520-00027 | E52: =SUBTOTAL(103,$U$21:U52) -> 31 | F52: 국내성도 | G52: 국내_부녀 | H52: 00350330-00205 | I52: 박지민 | J52: 00261114-00053 | K52: 00390826-00066 | L52: 00270104-00035 | M52: 00290520-00027 | P52: 3구역 | R52: 부구역장 | S52: 부구역장 | U52: 3부녀 | V52: 정갈리나 | W52: Тен Галина | X52: 여 | Y52: 29183 | Z52: =DATEDIF(Y52,TODAY(),"Y") -> 46 | AA52: 010-5329-6884 | AB52: @Galina10j | AC52: 집사 | AD52: 총회등록 | AE52: 카자흐스탄 | AF52: 한국 | AG52: 서울특별시
...

Sheet 42.3월(조직개편전) 취합마스터파일
A1: 7285
AF2: 국가별 지역 관할
AF3: 러시아 | AG3: 사할린
AG4: 사하공화국 (야쿠티야),야쿠츠크
AF7: 카자흐스탄 | AG7: 아스타나
AG8: 카라간다
AF11: 해외개척지역 | AG11: 벨라루스,폴란드,루마니아
C19: 642 | D19: 총인원 | E19: =SUBTOTAL(103,$F$21:F710) -> 642
C20: 번호 | D20: 고유번호 | E20: 인원수 | F20: 지역 | G20: 팀 | H20: 지역총괄팀장 | I20: 담당팀장 | J20: 팀장 | K20: 구역장 | L20: 부구역장(1) | M20: 부구역장(2) | N20: 부구역장(3) | O20: 부구역장(4) | P20: 구역 | Q20: 새신자 | R20: 행정직책 | S20: 직책 | T20: 겸직 | U20: 부서 | V20: 이름(KR) | W20: 이름(RU) | X20: 성별 | Y20: 생년월일 | Z20: (만)나이 | AA20: 전화번호 | AB20: 텔레사용자명 | AC20: 직분 | AD20: 등록상태 | AE20: 국적 | AF20: 국가 | AG20: 도시명 | AH20: 출결 여부 | AI20: 사유/기간 | AJ20: 센터기수 | AK20: 기타사항 | AL20: 체크 | AM20: 체크2
C21: 1 | D21: 00360527-00006 | E21: =SUBTOTAL(103,$U$21:U21) -> 1 | F21: 국내성도 | G21: 국내_장년 | H21: 00350330-00205 | I21: 김세진 | J21: 00360527-00006 | K21: 00360830-00345 | L21: x | M21: x | P21: 1구역 | R21: 팀장 | S21: 국내총괄팀장 | T21: 구역장 | U21: 2장년 | V21: 김세진 | W21: Ким Сергей | X21: 남 | Y21: 32431 | Z21: =DATEDIF(Y21,TODAY(),"Y") -> 37 | AA21: 010-6640-3437 | AB21: @execute25 | AC21: 집사 | AD21: 총회등록 | AE21: 우즈베키스탄/한국(국적취득) | AF21: 한국 | AG21: 서울특별시
C22: 2 | D22: 00360830-00345 | E22: =SUBTOTAL(103,$U$21:U22) -> 2 | F22: 국내성도 | G22: 국내_장년 | H22: 00350330-00205 | I22: 김세진 | J22: 00360527-00006 | K22: 00360830-00345 | L22: x | M22: x | P22: 1구역 | R22: 구역장 | S22: 구역장 | U22: 2장년 | V22: 허드미트리 | W22: Хе Дмитрий | X22: 남 | Y22: 32370 | Z22: =DATEDIF(Y22,TODAY(),"Y") -> 37 | AA22: 010-9575-8815 | AB22: @Dmitriyhe | AC22: 집사 | AD22: 총회등록 | AE22: 우즈베키스탄 | AF22: 한국 | AG22: 서울특별시
C23: 3 | D23: 00291129-00211 | E23: =SUBTOTAL(103,$U$21:U23) -> 3 | F23: 해외개척 | G23: 국내_장년 | H23: 00350330-00205 | I23: 김세진 | J23: 00360527-00006 | K23: 00360830-00345 | L23: x | M23: x | P23: 1구역 | U23: 2장년 | V23: 김에두아르드 | W23: Ким Эдуард | X23: 남 | Y23: 29900 | Z23: =DATEDIF(Y23,TODAY(),"Y") -> 44 | AA23: 010-2426-2496/(1(506)-898-3709) | AC23: 집사 | AD23: 총회등록 | AE23: 우크라이나 | AF23: 캐나다 | AG23: 프레더릭턴
C24: 4 | D24: 00360830-00344 | E24: =SUBTOTAL(103,$U$21:U24) -> 4 | F24: 국내성도 | G24: 국내_장년 | H24: 00350330-00205 | I24: 김세진 | J24: 00360527-00006 | K24: 00360830-00345 | L24: x | M24: x | P24: 1구역 | U24: 2장년 | V24: 이드미트리 | W24: Ли Дмитрий | X24: 남 | Y24: 32279 | Z24: =DATEDIF(Y24,TODAY(),"Y") -> 37 | AA24: 010-2351-0933 | AC24: 집사 | AD24: 총회등록 | AE24: 우즈베키스탄 | AF24: 한국 | AG24: 서울특별시
C25: 5 | D25: 00320813-00008 | E25: =SUBTOTAL(103,$U$21:U25) -> 5 | F25: 국내성도 | G25: 국내_장년 | H25: 00350330-00205 | I25: 김세진 | J25: 00360527-00006 | K25: 00360830-00345 | L25: x | M25: x | P25: 1구역 | U25: 2장년 | V25: 박뱌체슬라브 | W25: Пак Вячеслав | X25: 남 | Y25: 31456 | Z25: =DATEDIF(Y25,TODAY(),"Y") -> 39 | AA25: 010-4374-0713 | AC25: 집사 | AD25: 총회등록 | AE25: 우즈베키스탄 | AF25: 한국 | AG25: 서울특별시
C26: 6 | D26: 00371218-00469 | E26: =SUBTOTAL(103,$U$21:U26) -> 6 | F26: 국내성도 | G26: 국내_장년 | H26: 00350330-00205 | I26: 김세진 | J26: 00360527-00006 | K26: 00360830-00345 | L26: x | M26: x | P26: 1구역 | U26: 2장년 | V26: 한세묜세묘노비치 | W26: Хан Семён | X26: 남 | Y26: 33599 | Z26: =DATEDIF(Y26,TODAY(),"Y") -> 34 | AA26: 010-8433-2802 | AC26: 집사 | AD26: 총회등록 | AE26: 우즈베키스탄 | AF26: 한국 | AG26: 서울특별시
C27: 7 | D27: 00360810-00494 | E27: =SUBTOTAL(103,$U$21:U27) -> 7 | F27: 국내성도 | G27: 국내_장년 | H27: 00350330-00205 | I27: 김세진 | J27: 00360527-00006 | K27: 00360830-00345 | L27: x | M27: x | P27: 1구역 | U27: 2장년 | V27: 오가이디미트리 | W27: Огай Дмитрий | X27: 남 | Y27: 31780 | Z27: =DATEDIF(Y27,TODAY(),"Y") -> 39 | AA27: 010-4333-4896 | AC27: 집사 | AD27: 총회등록 | AE27: 우즈베키스탄 | AF27: 한국 | AG27: 전라남도
C28: 8 | D28: 00371217-01048 | E28: =SUBTOTAL(103,$U$21:U28) -> 8 | F28: 국내성도 | G28: 국내_장년 | H28: 00350330-00205 | I28: 김세진 | J28: 00360527-00006 | K28: 00360830-00345 | L28: x | M28: x | P28: 1구역 | R28: 팀장 | S28: 새신자팀장 | T28: 구역장 | U28: 2장년 | V28: 강블라디미르파블로비치 | W28: Кан Владимир | X28: 남 | Y28: 33031 | Z28: =DATEDIF(Y28,TODAY(),"Y") -> 35 | AA28: 010-5820-6557 | AC28: 집사 | AD28: 총회등록 | AE28: 러시아 | AF28: 한국 | AG28: 서울특별시
C29: 9 | D29: 00390826-00075 | E29: =SUBTOTAL(103,$U$21:U29) -> 9 | F29: 국내성도 | G29: 국내_청년 | H29: 00350330-00205 | I29: 김세진 | J29: 00360527-00006 | K29: 00390826-00075 | L29: x | M29: x | P29: 2구역 | R29: 구역장 | S29: 구역장 | U29: 4청년 | V29: 김세르게이발레리예비치 | W29: Ким Сергей Валерьевич | X29: 남 | Y29: 32305 | Z29: =DATEDIF(Y29,TODAY(),"Y") -> 37 | AA29: 010-8441-1728 | AB29: @k_i_m_sergey | AC29: 문도 | AD29: 총회등록 | AE29: 러시아 | AF29: 한국 | AG29: 경기도 | AJ29: 147-1기
C30: 10 | D30: 00311023-00027 | E30: =SUBTOTAL(103,$U$21:U30) -> 10 | F30: 국내성도 | G30: 국내_청년 | H30: 00350330-00205 | I30: 김세진 | J30: 00360527-00006 | K30: 00390826-00075 | L30: x | M30: x | P30: 2구역 | U30: 4청년 | V30: 주유리 | W30: Дю Юрий | X30: 남 | Y30: 32377 | Z30: =DATEDIF(Y30,TODAY(),"Y") -> 37 | AA30: 010-3141-8193 | AC30: 문도 | AD30: 총회등록 | AE30: 러시아 | AF30: 한국 | AG30: 서울특별시
C31: 11 | D31: 00390826-00117 | E31: =SUBTOTAL(103,$U$21:U31) -> 11 | F31: 국내성도 | G31: 국내_청년 | H31: 00350330-00205 | I31: 김세진 | J31: 00360527-00006 | K31: 00390826-00075 | L31: x | M31: x | P31: 2구역 | U31: 4청년 | V31: 손이고르아루투로비치 | W31: Сон Игорь Артурович | X31: 남 | Y31: 36739 | Z31: =DATEDIF(Y31,TODAY(),"Y") -> 25 | AA31: 010-97112243 | AC31: 성도 | AD31: 총회등록 | AE31: 우즈베키스탄 | AF31: 한국 | AG31: 서울특별시 | AJ31: 147-4기
C32: 12 | D32: 00360830-00347 | E32: =SUBTOTAL(103,$U$21:U32) -> 12 | F32: 국내성도 | G32: 국내_청년 | H32: 00350330-00205 | I32: 김세진 | J32: 00360527-00006 | K32: 00390826-00075 | L32: x | M32: x | P32: 2구역 | U32: 4청년 | V32: 강파벨 | W32: Кан Павел | X32: 남 | Y32: 33538 | Z32: =DATEDIF(Y32,TODAY(),"Y") -> 34 | AA32: 010-5552-2710 | AC32: 성도 | AD32: 교회등록 | AE32: 카자흐스탄 | AF32: 한국 | AG32: 경상북도 | AI32: 출결제외해지(2025/3/1) | AK32: 신앙유약
C33: 13 | D33: 00400227-01416 | E33: =SUBTOTAL(103,$U$21:U33) -> 13 | F33: 국내성도 | G33: 국내_청년 | H33: 00350330-00205 | I33: 김세진 | J33: 00360527-00006 | K33: 00390826-00075 | L33: x | M33: x | P33: 2구역 | U33: 4청년 | V33: 김예브게니알렉산드로비치 | W33: Ким Евгений Александрович | X33: 남 | Y33: 33400 | Z33: =DATEDIF(Y33,TODAY(),"Y") -> 34 | AA33: 7-747-455-6934 | AC33: 성도 | AD33: 입교 | AE33: 카자흐스탄 | AF33: 카자흐스탄 | AG33: 알마티 | AI33: 출결제외해지(2025/3/1) | AJ33: 149-1기 | AK33: 신앙유약
C34: 14 | D34: 00261225-00087 | E34: =SUBTOTAL(103,$U$21:U34) -> 14 | F34: 국내성도 | G34: 국내_부녀 | H34: 00350330-00205 | I34: 차소연 | J34: 00341026-00033 | K34: 00290520-00027 | L34: 00290520-00027 | M34: x | P34: 1구역 | U34: 3부녀 | V34: 최승미 | W34: Цой Виктория(ЦойСынгМи) | X34: 여 | Y34: 31249 | Z34: =DATEDIF(Y34,TODAY(),"Y") -> 40 | AA34: 010-8921-3985 | AB34: @victoriachoi8 | AC34: 집사 | AD34: 총회등록 | AE34: 우즈베키스탄 | AF34: 한국 | AG34: 서울특별시
C35: 15 | D35: 00290520-00027 | E35: =SUBTOTAL(103,$U$21:U35) -> 15 | F35: 국내성도 | G35: 국내_부녀 | H35: 00350330-00205 | I35: 차소연 | J35: 00341026-00033 | K35: 00290520-00027 | L35: 00290520-00027 | M35: x | P35: 1구역 | R35: 부구역장 | S35: 부구역장 | U35: 3부녀 | V35: 정갈리나 | W35: Тен Галина | X35: 여 | Y35: 29183 | Z35: =DATEDIF(Y35,TODAY(),"Y") -> 46 | AA35: 010-5329-6884 | AB35: @Galina10j | AC35: 집사 | AD35: 총회등록 | AE35: 카자흐스탄 | AF35: 한국 | AG35: 서울특별시
C36: 16 | D36: 00361031-00487 | E36: =SUBTOTAL(103,$U$21:U36) -> 16 | F36: 국내성도 | G36: 국내_부녀 | H36: 00350330-00205 | I36: 차소연 | J36: 00341026-00033 | K36: 00290520-00027 | L36: 00290520-00027 | M36: x | P36: 1구역 | U36: 3부녀 | V36: 최릴리야 | W36: Цой Лилия | X36: 여 | Y36: 33815 | Z36: =DATEDIF(Y36,TODAY(),"Y") -> 33 | AA36: 010-7550-5848 | AC36: 집사 | AD36: 총회등록 | AE36: 우즈베키스탄 | AF36: 한국 | AG36: 인천광역시
C37: 17 | D37: 00311023-00028 | E37: =SUBTOTAL(103,$U$21:U37) -> 17 | F37: 국내성도 | G37: 국내_부녀 | H37: 00350330-00205 | I37: 차소연 | J37: 00341026-00033 | K37: 00290520-00027 | L37: 00290520-00027 | M37: x | P37: 1구역 | U37: 3부녀 | V37: 박옐레나 | W37: Пак Елена | X37: 여 | Y37: 32547 | Z37: =DATEDIF(Y37,TODAY(),"Y") -> 36 | AA37: 010-5615-2266 | AC37: 집사 | AD37: 총회등록 | AE37: 우즈베키스탄 | AF37: 한국 | AG37: 경기도
C38: 18 | D38: 00280508-00022 | E38: =SUBTOTAL(103,$U$21:U38) -> 18 | F38: 국내성도 | G38: 국내_부녀 | H38: 00350330-00205 | I38: 차소연 | J38: 00341026-00033 | K38: 00290520-00027 | L38: 00290520-00027 | M38: x | P38: 1구역 | U38: 3부녀 | V38: 엘리나바투크흐티나 | W38: Батухтина Элина | X38: 여 | Y38: 31504 | Z38: =DATEDIF(Y38,TODAY(),"Y") -> 39 | AA38: 010-4593-5238 | AC38: 문도 | AD38: 총회등록 | AE38: 우크라이나 | AF38: 한국 | AG38: 서울특별시 | AI38: 출결제외해지(2025/3/1) | AK38: 신앙유약
C39: 19 | D39: 00360830-00346 | E39: =SUBTOTAL(103,$U$21:U39) -> 19 | F39: 국내성도 | G39: 국내_부녀 | H39: 00350330-00205 | I39: 차소연 | J39: 00341026-00033 | K39: 00360830-00346 | L39: 00350330-00153 | M39: x | P39: 2구역 | R39: 구역장 | S39: 구역장 | U39: 3부녀 | V39: 김예카테리나 | W39: Ким Екатерина | X39: 여 | Y39: 33312 | Z39: =DATEDIF(Y39,TODAY(),"Y") -> 34 | AA39: 010-5877-6557 | AB39: @Rina_Kim_1 | AC39: 집사 | AD39: 총회등록 | AE39: 우즈베키스탄 | AF39: 한국 | AG39: 서울특별시
C40: 20 | D40: 00350330-00153 | E40: =SUBTOTAL(103,$U$21:U40) -> 20 | F40: 국내성도 | G40: 국내_부녀 | H40: 00350330-00205 | I40: 차소연 | J40: 00341026-00033 | K40: 00360830-00346 | L40: 00350330-00153 | M40: x | P40: 2구역 | R40: 부구역장 | S40: 부구역장 | U40: 3부녀 | V40: 문발레리야 | W40: Мун Валерия | X40: 여 | Y40: 32771 | Z40: =DATEDIF(Y40,TODAY(),"Y") -> 36 | AA40: 010-7296-2009 | AC40: 집사 | AD40: 총회등록 | AE40: 카자흐스탄 | AF40: 한국 | AG40: 서울특별시
C41: 21 | D41: 00371217-01047 | E41: =SUBTOTAL(103,$U$21:U41) -> 21 | F41: 국내성도 | G41: 국내_부녀 | H41: 00350330-00205 | I41: 차소연 | J41: 00341026-00033 | K41: 00360830-00346 | L41: 00350330-00153 | M41: x | P41: 2구역 | R41: 팀장 | S41: 새신자팀장 | T41: 구역장 | U41: 3부녀 | V41: 칸타코바안나일리니치나 | W41: Кантакова Анна | X41: 여 | Y41: 31722 | Z41: =DATEDIF(Y41,TODAY(),"Y") -> 39 | AA41: 010-2887-6167 | AB41: @annakantakova | AC41: 집사 | AD41: 총회등록 | AE41: 러시아 | AF41: 한국 | AG41: 서울특별시
C42: 22 | D42: 00340624-00330 | E42: =SUBTOTAL(103,$U$21:U42) -> 22 | F42: 국내성도 | G42: 국내_부녀 | H42: 00350330-00205 | I42: 차소연 | J42: 00341026-00033 | K42: 00360830-00346 | L42: 00350330-00153 | M42: x | P42: 2구역 | U42: 3부녀 | V42: 최유나 | W42: Цой Ольга | X42: 여 | Y42: 31062 | Z42: =DATEDIF(Y42,TODAY(),"Y") -> 41 | AA42: 010-2570-6278 | AC42: 집사 | AD42: 총회등록 | AE42: 한국 | AF42: 한국 | AG42: 서울특별시
C43: 23 | D43: 00270903-00002 | E43: =SUBTOTAL(103,$U$21:U43) -> 23 | F43: 국내성도 | G43: 국내_부녀 | H43: 00350330-00205 | I43: 차소연 | J43: 00341026-00033 | K43: 00360830-00346 | L43: 00350330-00153 | M43: x | P43: 2구역 | U43: 3부녀 | V43: 정류드밀라 | W43: Тен Людмила | X43: 여 | Y43: 30208 | Z43: =DATEDIF(Y43,TODAY(),"Y") -> 43 | AA43: 010-7624-7907 | AC43: 집사 | AD43: 총회등록 | AE43: 카자흐스탄 | AF43: 한국 | AG43: 서울특별시
C44: 24 | D44: 00310314-00227 | E44: =SUBTOTAL(103,$U$21:U44) -> 24 | F44: 국내성도 | G44: 국내_부녀 | H44: 00350330-00205 | I44: 차소연 | J44: 00341026-00033 | K44: 00360830-00346 | L44: 00350330-00153 | M44: x | P44: 2구역 | U44: 3부녀 | V44: 한옐레나 | W44: Хан Елена | X44: 여 | Y44: 31075 | Z44: =DATEDIF(Y44,TODAY(),"Y") -> 41 | AA44: 010-8285-1011 | AC44: 집사 | AD44: 총회등록 | AE44: 러시아 | AF44: 한국 | AG44: 서울특별시 | AI44: 출결제외해지(2025/3/1) | AK44: 신앙유약
C45: 25 | D45: 00320813-00009 | E45: =SUBTOTAL(103,$U$21:U45) -> 25 | F45: 국내성도 | G45: 국내_부녀 | H45: 00350330-00205 | I45: 차소연 | J45: 00341026-00033 | K45: 00360830-00346 | L45: 00350330-00153 | M45: x | P45: 2구역 | U45: 3부녀 | V45: 이다리야B | W45: Ли Дарья | X45: 여 | Y45: 31736 | Z45: =DATEDIF(Y45,TODAY(),"Y") -> 39 | AA45: 010-4045-1523 | AC45: 문도 | AD45: 총회등록 | AE45: 우즈베키스탄 | AF45: 한국 | AG45: 서울특별시 | AI45: 출결제외해지(2025/3/1) | AK45: 신앙유약
C46: 26 | D46: 00341026-00033 | E46: =SUBTOTAL(103,$U$21:U46) -> 26 | F46: 국내성도 | G46: 국내_부녀 | H46: 00350330-00205 | I46: 차소연 | J46: 00341026-00033 | K46: 00341026-00033 | L46: 00270104-00035 | M46: 00371218-00466 | P46: 3구역 | R46: 구역장 | S46: 팀장 | T46: 구역장 | U46: 3부녀 | V46: 차소연 | W46: Ча Лариса | X46: 여 | Y46: 30625 | Z46: =DATEDIF(Y46,TODAY(),"Y") -> 42 | AA46: 010-2882-8927 | AB46: @soyeon_83 | AC46: 집사 | AD46: 총회등록 | AE46: 한국 | AF46: 한국 | AG46: 전라남도
C47: 27 | D47: 00270104-00035 | E47: =SUBTOTAL(103,$U$21:U47) -> 27 | F47: 국내성도 | G47: 국내_부녀 | H47: 00350330-00205 | I47: 차소연 | J47: 00341026-00033 | K47: 00341026-00033 | L47: 00270104-00035 | M47: 00371218-00466 | P47: 3구역 | R47: 부구역장 | S47: 부구역장 | U47: 3부녀 | V47: 굴나라사드코바 | W47: Садыкова Гульнара | X47: 여 | Y47: 30935 | Z47: =DATEDIF(Y47,TODAY(),"Y") -> 41 | AA47: 010-6406-8815 | AB47: @Nara_Seoul | AC47: 집사 | AD47: 총회등록 | AE47: 키르기스스탄 | AF47: 한국 | AG47: 서울특별시
